Workbook
Name 保有技能: '[1]技能或寶具'!$C$51:$C$250
Name 寶具: '[1]技能或寶具'!$C$351:$C$1002
Name 參戰者: #REF!
Name 參戰者: '战斗计算（新）'!$C$5:$C$68
Name 參戰者: #REF!
Name 技能類型: '[1]技能或寶具'!$B$2:$B$1002
Name 無: '[1]技能或寶具'!$C$2
Name 職階技能: '[1]技能或寶具'!$C$3:$C$50
Name 自創技能: '[1]技能或寶具'!$C$251:$C$350

Sheet 前言
A1: 如你所见，这是一个建立在旧战斗表基础上的战斗表。
A3: 更新日志
A4: 44160 | B4: 战斗表主体完成
A5: 追加内容： | B5: 五人战斗位
B6: 三方混战
B7: 战斗中胜率结算展示
A8: 44161 | B8: 修复了一定bug
B9: 调整了版面格式，现在版面更舒服了
A10: 45824 | B10: 增设战斗计算内容
B11: 增设战斗开始时的属性补正表

Sheet 說明
B1: 更新记录
A2: 2 | B2: 分开了心算版跟详细版，预计未来主要更新详细版。除非有规则上的大改动。
A3: 2.1 | B3: 加入了HP规则的数值计算
A4: 2.2 | B4: 将文字全转成简体
B5: 为初始工序也增加了计算属性的栏位
B6: 帮撒退率、暴击率等加上「%」号
A7: 2.21 | B7: 因应更新的单独行动,魔力不足扣减属性增加-5的选择
B8: 加入「星之开拓者」的等差处理
B9: 胜率补正多开一行,预计是用来填写DEBUFF。
A10: 2.22 | B10: 將不好看的格子修改了
A11: 2.3 | B11: 加入三方戰鬥的計算
B12: 屬性將不會因為debuff的因素降至0以下
B13: 加入對應三方戰鬥的勝率基準值與計算表
B14: 支援隱藏情報用的技能，為每工序、每角色都加了「隱藏」屬性的選擇
A15: 2.31 | B15: 試作性的採用了一套保有勝率分配。但已廢棄
A16: 2.32 | B16: 三方混戰，採用比例分配的方試分配保有勝率
A17: 2.33 | B17: 混戰的基準值原來可以自動..那麼自動了
B18: 隱藏情報的規則調了一下，任一項隱藏後會連總值也藏
B19: 保底的計算出包，改了新的
A20: 2.34 | B20: 耐力部份的魔力不足，原來出了很多年包…已搶救
A21: 2.35 | B21: 在頂部加了一片能拉申，能填文字的空白。有什麼怕忘記的可以用那裡當筆記。
A32: 开团前要准备的事
A34: 1 | B34: 在右则的角色属性处，将参与圣杯角色的属性、名字填上
A35: 2 | B35: 视情况，可以将一些常驻补正、必开的属性补正也预先填在右方，让开团后的计算减少
A36: 3 | B36: 将自己用不到的功能，用左方的+号摺起，营造最适合自己的环境(需要先解除工作表保护)
A40: 20/6/30:499已经完成的部分：神性类；透化初战类；魔放类；常驻加成类等 （总之，写在传统技能表内的技能，应该都可以运作了 | B40: 6/31：修正了复合效果的几个BUG；追加了军略与阵地的计算
B41: 7/1：除了有特殊标记的，所有表内技能都可使用；也可根据表追加新的数据；如果有BUG，联系499（1176720684）
A42: 填写角色的须知：在角色表的类型位置填写；从者需填写[从者]和职阶；御主需要填写[御主]；协力者也填[御主]；非玩家单位填[人偶]； 合体人请填写合体目标的名字，本计算表采用唯一姓名索引，所以不要写重复名字。 如果有合体单位的，请填入人物表，并注明[人偶]（一般都是人偶，你要合体从者也可以，但是不会有从者的技能) 如果你要合体还有技能的，请直接写成新单位，注明[合体] | B42: 7/6：又修复了好多bug。现在[透化][无冠的武艺]会正常计入初始工序了；无辜的怪物没有计入初始工序，而是计入主要工序（反正也看不到） 7/8:现在可以正常将宝具纳入计算了 7/23:修复了技能数值追加工序错误的问题； 【尚待修复的问题：神性/情报抹消/龙种等拓展性；宝具数值追加工序错误的问题；自我暗示类技能】 一键清空追加中……
A43: 照着例子填就行
A44: 特注：保菌请把宝具填在礼装栏里
A52: 一些图例
A116: 本计算表是为圣杯战争跑团准备的战斗计算表。 对该规则有兴趣,或想进行相关讨论可以加群424815329
A117: 该圣杯战争跑团规则大部分采用了日本现在较流行的男爵圣杯规则作为基底，进行魔改的TRPG规则，在游戏上简约了战斗部分，以实际扮演为主体的游戏方式。
A119: 另外若计算表发现错误联系我急救...2592616838

Sheet 战斗计算（新）
D3: 等级 | E3: 筋力 | F3: 耐力 | G3: 敏捷 | H3: 魔力 | I3: 幸运 | J3: 宝具 | K3: 等级补正 | L3: 筋力补正 | M3: 耐力补正 | N3: 敏捷补正 | O3: 魔力补正 | P3: 幸运补正 | Q3: 宝具补正 | R3: 基础等级 | S3: 基础筋力 | T3: 基础耐力 | U3: 基础敏捷 | V3: 基础魔力 | W3: 基础幸运 | X3: 基础宝具 | Y3: 常驻等级 | Z3: 常驻筋力 | AA3: 常驻耐力 | AB3: 常驻敏捷 | AC3: 常驻魔力 | AD3: 常驻幸运 | AE3: 常驻宝具 | AF3: 初始等级 | AG3: 初始筋力 | AH3: 初始耐力 | AI3: 初始敏捷 | AJ3: 初始魔力 | AK3: 初始幸运 | AL3: 初始宝具
B4: 编号 | C4: 角色名
C5: 无 | D5: =K5+R5 -> 0 | E5: =L5+S5 -> 0 | F5: =M5+T5 -> 0 | G5: =N5+U5 -> 0 | H5: =O5+V5 -> 0 | I5: =P5+W5 -> 0 | J5: =Q5+X5 -> 0 | R5: =Y5+AF5 -> 0 | S5: =Z5+AG5 -> 0 | T5: =AA5+AH5 -> 0 | U5: =AB5+AI5 -> 0 | V5: =AC5+AJ5 -> 0 | W5: =AD5+AK5 -> 0 | X5: =AE5+AL5 -> 0
D6: =K6+R6 -> 0 | E6: =L6+S6 -> 0 | F6: =M6+T6 -> 0 | G6: =N6+U6 -> 0 | H6: =O6+V6 -> 0 | I6: =P6+W6 -> 0 | J6: =Q6+X6 -> 0 | R6: =Y6+AF6 -> 0 | S6: =Z6+AG6 -> 0 | T6: =AA6+AH6 -> 0 | U6: =AB6+AI6 -> 0 | V6: =AC6+AJ6 -> 0 | W6: =AD6+AK6 -> 0 | X6: =AE6+AL6 -> 0
B7: 剑 | C7: 宝钟马琳 | D7: =K7+R7 -> 70 | E7: =L7+S7 -> 45 | F7: =M7+T7 -> 50 | G7: =N7+U7 -> 80 | H7: =O7+V7 -> 45 | I7: =P7+W7 -> 50 | J7: =Q7+X7 -> 55 | R7: =Y7+AF7 -> 70 | S7: =Z7+AG7 -> 45 | T7: =AA7+AH7 -> 50 | U7: =AB7+AI7 -> 80 | V7: =AC7+AJ7 -> 45 | W7: =AD7+AK7 -> 50 | X7: =AE7+AL7 -> 55 | Y7: 70 | Z7: 45 | AA7: 50 | AB7: 80 | AC7: 45 | AD7: 50 | AE7: 55
B8: 枪 | C8: 利维坦 | D8: =K8+R8 -> 70 | E8: =L8+S8 -> 30 | F8: =M8+T8 -> 70 | G8: =N8+U8 -> 90 | H8: =O8+V8 -> 20 | I8: =P8+W8 -> 50 | J8: =Q8+X8 -> 50 | R8: =Y8+AF8 -> 70 | S8: =Z8+AG8 -> 30 | T8: =AA8+AH8 -> 70 | U8: =AB8+AI8 -> 90 | V8: =AC8+AJ8 -> 20 | W8: =AD8+AK8 -> 50 | X8: =AE8+AL8 -> 50 | Y8: 70 | Z8: 30 | AA8: 70 | AB8: 90 | AC8: 20 | AD8: 50 | AE8: 50
B9: 弓 | C9: 尼奥尔德 | D9: =K9+R9 -> 70 | E9: =L9+S9 -> 30 | F9: =M9+T9 -> 60 | G9: =N9+U9 -> 90 | H9: =O9+V9 -> 20 | I9: =P9+W9 -> 80 | J9: =Q9+X9 -> 55 | R9: =Y9+AF9 -> 70 | S9: =Z9+AG9 -> 30 | T9: =AA9+AH9 -> 60 | U9: =AB9+AI9 -> 90 | V9: =AC9+AJ9 -> 20 | W9: =AD9+AK9 -> 80 | X9: =AE9+AL9 -> 55 | Y9: 70 | Z9: 30 | AA9: 60 | AB9: 90 | AC9: 20 | AD9: 80 | AE9: 55
B10: 骑 | C10: 醉枭赌徒 | D10: =K10+R10 -> 70 | E10: =L10+S10 -> 105 | F10: =M10+T10 -> 175 | G10: =N10+U10 -> 40 | H10: =O10+V10 -> 35 | I10: =P10+W10 -> 80 | J10: =Q10+X10 -> 55 | L10: 95 | M10: 95 | N10: -20 | O10: 15 | R10: =Y10+AF10 -> 70 | S10: =Z10+AG10 -> 10 | T10: =AA10+AH10 -> 80 | U10: =AB10+AI10 -> 60 | V10: =AC10+AJ10 -> 20 | W10: =AD10+AK10 -> 80 | X10: =AE10+AL10 -> 55 | Y10: 70 | Z10: 10 | AA10: 80 | AB10: 60 | AC10: 20 | AD10: 80 | AE10: 55
B11: 术 | C11: 周瑜 | D11: =K11+R11 -> 70 | E11: =L11+S11 -> 35 | F11: =M11+T11 -> 35 | G11: =N11+U11 -> 35 | H11: =O11+V11 -> 105 | I11: =P11+W11 -> 80 | J11: =Q11+X11 -> 50 | L11: 15 | M11: 15 | N11: 15 | O11: 15 | R11: =Y11+AF11 -> 70 | S11: =Z11+AG11 -> 20 | T11: =AA11+AH11 -> 20 | U11: =AB11+AI11 -> 20 | V11: =AC11+AJ11 -> 90 | W11: =AD11+AK11 -> 80 | X11: =AE11+AL11 -> 50 | Y11: 70 | Z11: 20 | AA11: 20 | AB11: 20 | AC11: 90 | AD11: 80 | AE11: 50
B12: 杀 | C12: 圣地亚哥 | D12: =K12+R12 -> 40 | E12: =L12+S12 -> 30 | F12: =M12+T12 -> 30 | G12: =N12+U12 -> 70 | H12: =O12+V12 -> 20 | I12: =P12+W12 -> 50 | J12: =Q12+X12 -> 45 | L12: 10 | M12: 10 | N12: 10 | O12: 10 | R12: =Y12+AF12 -> 40 | S12: =Z12+AG12 -> 20 | T12: =AA12+AH12 -> 20 | U12: =AB12+AI12 -> 60 | V12: =AC12+AJ12 -> 10 | W12: =AD12+AK12 -> 50 | X12: =AE12+AL12 -> 45 | Y12: 40 | Z12: 20 | AA12: 20 | AB12: 60 | AC12: 10 | AD12: 50 | AE12: 45
B13: 狂 | C13: 赛德娜 | D13: =K13+R13 -> 70 | E13: =L13+S13 -> 70 | F13: =M13+T13 -> 105 | G13: =N13+U13 -> 60 | H13: =O13+V13 -> 60 | I13: =P13+W13 -> 20 | J13: =Q13+X13 -> 60 | R13: =Y13+AF13 -> 70 | S13: =Z13+AG13 -> 70 | T13: =AA13+AH13 -> 105 | U13: =AB13+AI13 -> 60 | V13: =AC13+AJ13 -> 60 | W13: =AD13+AK13 -> 20 | X13: =AE13+AL13 -> 60 | Y13: 70 | Z13: 70 | AA13: 105 | AB13: 60 | AC13: 60 | AD13: 20 | AE13: 60
C14: 卢明 | D14: =K14+R14 -> 50 | E14: =L14+S14 -> 10 | F14: =M14+T14 -> 10 | G14: =N14+U14 -> 20 | H14: =O14+V14 -> 20 | I14: =P14+W14 -> 20 | J14: =Q14+X14 -> 0 | R14: =Y14+AF14 -> 50 | S14: =Z14+AG14 -> 10 | T14: =AA14+AH14 -> 10 | U14: =AB14+AI14 -> 20 | V14: =AC14+AJ14 -> 20 | W14: =AD14+AK14 -> 20 | X14: =AE14+AL14 -> 0 | Y14: 50 | Z14: 10 | AA14: 10 | AB14: 20 | AC14: 20 | AD14: 20 | AE14: 0
C15: 机甲少女 | D15: =K15+R15 -> 45 | E15: =L15+S15 -> 60 | F15: =M15+T15 -> 60 | G15: =N15+U15 -> 60 | H15: =O15+V15 -> 80 | I15: =P15+W15 -> 40 | J15: =Q15+X15 -> 0 | K15: 5 | O15: 10 | R15: =Y15+AF15 -> 40 | S15: =Z15+AG15 -> 60 | T15: =AA15+AH15 -> 60 | U15: =AB15+AI15 -> 60 | V15: =AC15+AJ15 -> 70 | W15: =AD15+AK15 -> 40 | X15: =AE15+AL15 -> 0 | Y15: 40 | Z15: 60 | AA15: 60 | AB15: 60 | AC15: 70 | AD15: 40 | AE15: 0
C16: 哈基米嗷 | D16: =K16+R16 -> 40 | E16: =L16+S16 -> 70 | F16: =M16+T16 -> 70 | G16: =N16+U16 -> 70 | H16: =O16+V16 -> 0 | I16: =P16+W16 -> 50 | J16: =Q16+X16 -> 0 | R16: =Y16+AF16 -> 40 | S16: =Z16+AG16 -> 70 | T16: =AA16+AH16 -> 70 | U16: =AB16+AI16 -> 70 | V16: =AC16+AJ16 -> 0 | W16: =AD16+AK16 -> 50 | X16: =AE16+AL16 -> 0 | Y16: 40 | Z16: 70 | AA16: 70 | AB16: 70 | AC16: 0 | AD16: 50 | AE16: 0
C17: 井上雪原 | D17: =K17+R17 -> 50 | E17: =L17+S17 -> 15 | F17: =M17+T17 -> 15 | G17: =N17+U17 -> 15 | H17: =O17+V17 -> 10 | I17: =P17+W17 -> 35 | J17: =Q17+X17 -> 0 | R17: =Y17+AF17 -> 50 | S17: =Z17+AG17 -> 15 | T17: =AA17+AH17 -> 15 | U17: =AB17+AI17 -> 15 | V17: =AC17+AJ17 -> 10 | W17: =AD17+AK17 -> 35 | X17: =AE17+AL17 -> 0 | Y17: 50 | Z17: 15 | AA17: 15 | AB17: 15 | AC17: 10 | AD17: 35 | AE17: 0
C18: 焰狼 | D18: =K18+R18 -> 70 | E18: =L18+S18 -> 15 | F18: =M18+T18 -> 20 | G18: =N18+U18 -> 40 | H18: =O18+V18 -> 15 | I18: =P18+W18 -> 40 | J18: =Q18+X18 -> 95 | Q18: 30 | R18: =Y18+AF18 -> 70 | S18: =Z18+AG18 -> 15 | T18: =AA18+AH18 -> 20 | U18: =AB18+AI18 -> 40 | V18: =AC18+AJ18 -> 15 | W18: =AD18+AK18 -> 40 | X18: =AE18+AL18 -> 65 | Y18: 70 | Z18: 15 | AA18: 20 | AB18: 40 | AC18: 15 | AD18: 40 | AE18: 65
C19: 岸优子 | D19: =K19+R19 -> 40 | E19: =L19+S19 -> 70 | F19: =M19+T19 -> 70 | G19: =N19+U19 -> 70 | H19: =O19+V19 -> 20 | I19: =P19+W19 -> 50 | J19: =Q19+X19 -> 50 | R19: =Y19+AF19 -> 40 | S19: =Z19+AG19 -> 70 | T19: =AA19+AH19 -> 70 | U19: =AB19+AI19 -> 70 | V19: =AC19+AJ19 -> 20 | W19: =AD19+AK19 -> 50 | X19: =AE19+AL19 -> 50 | Y19: 40 | Z19: 70 | AA19: 70 | AB19: 70 | AC19: 20 | AD19: 50 | AE19: 50
C20: 莫特 | D20: =K20+R20 -> 70 | E20: =L20+S20 -> 30 | F20: =M20+T20 -> 30 | G20: =N20+U20 -> 30 | H20: =O20+V20 -> 30 | I20: =P20+W20 -> 30 | J20: =Q20+X20 -> 0 | R20: =Y20+AF20 -> 70 | S20: =Z20+AG20 -> 30 | T20: =AA20+AH20 -> 30 | U20: =AB20+AI20 -> 30 | V20: =AC20+AJ20 -> 30 | W20: =AD20+AK20 -> 30 | X20: =AE20+AL20 -> 0 | Y20: 70 | Z20: 30 | AA20: 30 | AB20: 30 | AC20: 30 | AD20: 30 | AE20: 0
C21: 剑召唤物 | D21: =K21+R21 -> 60 | E21: =L21+S21 -> 20 | F21: =M21+T21 -> 20 | G21: =N21+U21 -> 60 | H21: =O21+V21 -> 20 | I21: =P21+W21 -> 20 | J21: =Q21+X21 -> 0 | R21: =Y21+AF21 -> 60 | S21: =Z21+AG21 -> 20 | T21: =AA21+AH21 -> 20 | U21: =AB21+AI21 -> 60 | V21: =AC21+AJ21 -> 20 | W21: =AD21+AK21 -> 20 | X21: =AE21+AL21 -> 0 | Y21: 60 | Z21: 20 | AA21: 20 | AB21: 60 | AC21: 20 | AD21: 20 | AE21: 0
B22: 弓召唤物 | C22: 高达采集者 | D22: =K22+R22 -> 40 | E22: =L22+S22 -> 20 | F22: =M22+T22 -> 20 | G22: =N22+U22 -> 20 | H22: =O22+V22 -> 20 | I22: =P22+W22 -> 20 | J22: =Q22+X22 -> 0 | R22: =Y22+AF22 -> 40 | S22: =Z22+AG22 -> 20 | T22: =AA22+AH22 -> 20 | U22: =AB22+AI22 -> 20 | V22: =AC22+AJ22 -> 20 | W22: =AD22+AK22 -> 20 | X22: =AE22+AL22 -> 0 | Y22: 40 | Z22: 20 | AA22: 20 | AB22: 20 | AC22: 20 | AD22: 20 | AE22: 0
C23: 术召唤物 | D23: =K23+R23 -> 40 | E23: =L23+S23 -> 10 | F23: =M23+T23 -> 10 | G23: =N23+U23 -> 10 | H23: =O23+V23 -> 10 | I23: =P23+W23 -> 10 | J23: =Q23+X23 -> 0 | R23: =Y23+AF23 -> 40 | S23: =Z23+AG23 -> 10 | T23: =AA23+AH23 -> 10 | U23: =AB23+AI23 -> 10 | V23: =AC23+AJ23 -> 10 | W23: =AD23+AK23 -> 10 | X23: =AE23+AL23 -> 0 | Y23: 40 | Z23: 10 | AA23: 10 | AB23: 10 | AC23: 10 | AD23: 10 | AE23: 0
C24: 狂召唤物 | D24: =K24+R24 -> 70 | E24: =L24+S24 -> 70 | F24: =M24+T24 -> 70 | G24: =N24+U24 -> 70 | H24: =O24+V24 -> 70 | I24: =P24+W24 -> 70 | J24: =Q24+X24 -> 0 | R24: =Y24+AF24 -> 70 | S24: =Z24+AG24 -> 70 | T24: =AA24+AH24 -> 70 | U24: =AB24+AI24 -> 70 | V24: =AC24+AJ24 -> 70 | W24: =AD24+AK24 -> 70 | X24: =AE24+AL24 -> 0 | Y24: 70 | Z24: 70 | AA24: 70 | AB24: 70 | AC24: 70 | AD24: 70 | AE24: 0
C25: 随船海员 | D25: =K25+R25 -> 20 | E25: =L25+S25 -> 10 | F25: =M25+T25 -> 10 | G25: =N25+U25 -> 10 | H25: =O25+V25 -> 10 | I25: =P25+W25 -> 10 | J25: =Q25+X25 -> 0 | R25: =Y25+AF25 -> 20 | S25: =Z25+AG25 -> 10 | T25: =AA25+AH25 -> 10 | U25: =AB25+AI25 -> 10 | V25: =AC25+AJ25 -> 10 | W25: =AD25+AK25 -> 10 | X25: =AE25+AL25 -> 0 | Y25: 20 | Z25: 10 | AA25: 10 | AB25: 10 | AC25: 10 | AD25: 10 | AE25: 0
C26: 多尔希爵士 | D26: =K26+R26 -> 70 | E26: =L26+S26 -> 70 | F26: =M26+T26 -> 70 | G26: =N26+U26 -> 90 | H26: =O26+V26 -> 20 | I26: =P26+W26 -> 10 | J26: =Q26+X26 -> 30 | R26: =Y26+AF26 -> 70 | S26: =Z26+AG26 -> 70 | T26: =AA26+AH26 -> 70 | U26: =AB26+AI26 -> 90 | V26: =AC26+AJ26 -> 20 | W26: =AD26+AK26 -> 10 | X26: =AE26+AL26 -> 30 | Y26: 70 | Z26: 70 | AA26: 70 | AB26: 90 | AC26: 20 | AD26: 10 | AE26: 30
D27: =K27+R27 -> 0 | E27: =L27+S27 -> 0 | F27: =M27+T27 -> 0 | G27: =N27+U27 -> 0 | H27: =O27+V27 -> 0 | I27: =P27+W27 -> 0 | J27: =Q27+X27 -> 0 | R27: =Y27+AF27 -> 0 | S27: =Z27+AG27 -> 0 | T27: =AA27+AH27 -> 0 | U27: =AB27+AI27 -> 0 | V27: =AC27+AJ27 -> 0 | W27: =AD27+AK27 -> 0 | X27: =AE27+AL27 -> 0
D28: =K28+R28 -> 0 | E28: =L28+S28 -> 0 | F28: =M28+T28 -> 0 | G28: =N28+U28 -> 0 | H28: =O28+V28 -> 0 | I28: =P28+W28 -> 0 | J28: =Q28+X28 -> 0 | R28: =Y28+AF28 -> 0 | S28: =Z28+AG28 -> 0 | T28: =AA28+AH28 -> 0 | U28: =AB28+AI28 -> 0 | V28: =AC28+AJ28 -> 0 | W28: =AD28+AK28 -> 0 | X28: =AE28+AL28 -> 0
D29: =K29+R29 -> 0 | E29: =L29+S29 -> 0 | F29: =M29+T29 -> 0 | G29: =N29+U29 -> 0 | H29: =O29+V29 -> 0 | I29: =P29+W29 -> 0 | J29: =Q29+X29 -> 0 | R29: =Y29+AF29 -> 0 | S29: =Z29+AG29 -> 0 | T29: =AA29+AH29 -> 0 | U29: =AB29+AI29 -> 0 | V29: =AC29+AJ29 -> 0 | W29: =AD29+AK29 -> 0 | X29: =AE29+AL29 -> 0
D30: =K30+R30 -> 0 | E30: =L30+S30 -> 0 | F30: =M30+T30 -> 0 | G30: =N30+U30 -> 0 | H30: =O30+V30 -> 0 | I30: =P30+W30 -> 0 | J30: =Q30+X30 -> 0 | R30: =Y30+AF30 -> 0 | S30: =Z30+AG30 -> 0 | T30: =AA30+AH30 -> 0 | U30: =AB30+AI30 -> 0 | V30: =AC30+AJ30 -> 0 | W30: =AD30+AK30 -> 0 | X30: =AE30+AL30 -> 0
D31: =K31+R31 -> 0 | E31: =L31+S31 -> 0 | F31: =M31+T31 -> 0 | G31: =N31+U31 -> 0 | H31: =O31+V31 -> 0 | I31: =P31+W31 -> 0 | J31: =Q31+X31 -> 0 | R31: =Y31+AF31 -> 0 | S31: =Z31+AG31 -> 0 | T31: =AA31+AH31 -> 0 | U31: =AB31+AI31 -> 0 | V31: =AC31+AJ31 -> 0 | W31: =AD31+AK31 -> 0 | X31: =AE31+AL31 -> 0
D32: =K32+R32 -> 0 | E32: =L32+S32 -> 0 | F32: =M32+T32 -> 0 | G32: =N32+U32 -> 0 | H32: =O32+V32 -> 0 | I32: =P32+W32 -> 0 | J32: =Q32+X32 -> 0 | R32: =Y32+AF32 -> 0 | S32: =Z32+AG32 -> 0 | T32: =AA32+AH32 -> 0 | U32: =AB32+AI32 -> 0 | V32: =AC32+AJ32 -> 0 | W32: =AD32+AK32 -> 0 | X32: =AE32+AL32 -> 0
D33: =K33+R33 -> 0 | E33: =L33+S33 -> 0 | F33: =M33+T33 -> 0 | G33: =N33+U33 -> 0 | H33: =O33+V33 -> 0 | I33: =P33+W33 -> 0 | J33: =Q33+X33 -> 0 | R33: =Y33+AF33 -> 0 | S33: =Z33+AG33 -> 0 | T33: =AA33+AH33 -> 0 | U33: =AB33+AI33 -> 0 | V33: =AC33+AJ33 -> 0 | W33: =AD33+AK33 -> 0 | X33: =AE33+AL33 -> 0
D34: =K34+R34 -> 0 | E34: =L34+S34 -> 0 | F34: =M34+T34 -> 0 | G34: =N34+U34 -> 0 | H34: =O34+V34 -> 0 | I34: =P34+W34 -> 0 | J34: =Q34+X34 -> 0 | R34: =Y34+AF34 -> 0 | S34: =Z34+AG34 -> 0 | T34: =AA34+AH34 -> 0 | U34: =AB34+AI34 -> 0 | V34: =AC34+AJ34 -> 0 | W34: =AD34+AK34 -> 0 | X34: =AE34+AL34 -> 0
D35: =K35+R35 -> 0 | E35: =L35+S35 -> 0 | F35: =M35+T35 -> 0 | G35: =N35+U35 -> 0 | H35: =O35+V35 -> 0 | I35: =P35+W35 -> 0 | J35: =Q35+X35 -> 0 | R35: =Y35+AF35 -> 0 | S35: =Z35+AG35 -> 0 | T35: =AA35+AH35 -> 0 | U35: =AB35+AI35 -> 0 | V35: =AC35+AJ35 -> 0 | W35: =AD35+AK35 -> 0 | X35: =AE35+AL35 -> 0
D36: =K36+R36 -> 0 | E36: =L36+S36 -> 0 | F36: =M36+T36 -> 0 | G36: =N36+U36 -> 0 | H36: =O36+V36 -> 0 | I36: =P36+W36 -> 0 | J36: =Q36+X36 -> 0 | R36: =Y36+AF36 -> 0 | S36: =Z36+AG36 -> 0 | T36: =AA36+AH36 -> 0 | U36: =AB36+AI36 -> 0 | V36: =AC36+AJ36 -> 0 | W36: =AD36+AK36 -> 0 | X36: =AE36+AL36 -> 0
D37: =K37+R37 -> 0 | E37: =L37+S37 -> 0 | F37: =M37+T37 -> 0 | G37: =N37+U37 -> 0 | H37: =O37+V37 -> 0 | I37: =P37+W37 -> 0 | J37: =Q37+X37 -> 0 | R37: =Y37+AF37 -> 0 | S37: =Z37+AG37 -> 0 | T37: =AA37+AH37 -> 0 | U37: =AB37+AI37 -> 0 | V37: =AC37+AJ37 -> 0 | W37: =AD37+AK37 -> 0 | X37: =AE37+AL37 -> 0
D38: =K38+R38 -> 0 | E38: =L38+S38 -> 0 | F38: =M38+T38 -> 0 | G38: =N38+U38 -> 0 | H38: =O38+V38 -> 0 | I38: =P38+W38 -> 0 | J38: =Q38+X38 -> 0 | R38: =Y38+AF38 -> 0 | S38: =Z38+AG38 -> 0 | T38: =AA38+AH38 -> 0 | U38: =AB38+AI38 -> 0 | V38: =AC38+AJ38 -> 0 | W38: =AD38+AK38 -> 0 | X38: =AE38+AL38 -> 0
... D47: =K47+R47 -> 0 | E47: =L47+S47 -> 0 | F47: =M47+T47 -> 0 | G47: =N47+U47 -> 0 | H47: =O47+V47 -> 0 | I47: =P47+W47 -> 0 | J47: =Q47+X47 -> 0 | R47: =Y47+AF47 -> 0 | S47: =Z47+AG47 -> 0 | T47: =AA47+AH47 -> 0 | U47: =AB47+AI47 -> 0 | V47: =AC47+AJ47 -> 0 | W47: =AD47+AK47 -> 0 | X47: =AE47+AL47 -> 0

Sheet 双方战斗表（新）
B3: 战斗开始时 | D3: 决定参战人选
T4: ↓本部分用于帮助GM计算魔力消耗
B5: 组别 | C5: 等级 | D5: 筋力 | E5: 耐力 | F5: 敏捷 | G5: 魔力 | H5: 幸运 | I5: 宝具 | J5: 宝外补惩 | K5: 全属补惩 | L5: 上三补惩 | T5: 当前魔力 | U5: 主力位 | V5: 辅助位 | W5: 辅助位 | X5: 辅助位 | Y5: 辅助位 | Z5: 主力位 | AA5: 辅助位 | AB5: 辅助位 | AC5: 辅助位 | AD5: 辅助位
B6: =C17 -> 醉枭赌徒 | Z6: 150
B7: =D17 -> 焰狼 | D7: -10 | J7: 5 | T7: 礼装补充
B8: =E17 -> 哈基米嗷 | E8: -5 | T8: 令咒补充
B9: =F17 -> 无 | T9: 消耗1 | Z9: 30
B10: =G17 -> 无 | T10: 消耗2 | Z10: 90
B11: =I17 -> 机甲少女 | D11: 10 | E11: 10 | F11: 10 | T11: 消耗3
B12: =J17 -> 无 | T12: 消耗4
B13: =K17 -> 无 | T13: 消耗5
B14: =L17 -> 无 | T14: 最终魔力 | U14: =U6-SUM(U7:U13) -> 0 | V14: =V6-SUM(V7:V13) -> 0 | W14: =W6-SUM(W7:W13) -> 0 | X14: =X6-SUM(X7:X13) -> 0 | Y14: =Y6-SUM(Y7:Y13) -> 0 | Z14: =Z6-SUM(Z7:Z13) -> 30 | AA14: =AA6-SUM(AA7:AA13) -> 0 | AB14: =AB6-SUM(AB7:AB13) -> 0 | ... AD14: =AD6-SUM(AD7:AD13) -> 0
B15: =M17 -> 无 | T15: 属性扣除 | U15: =IF(U6<0,INT(U6/-20)*10,0) -> 0 | V15: =IF(V6<0,INT(V6/-20)*10,0) -> 0 | W15: =IF(W6<0,INT(W6/-20)*10,0) -> 0 | X15: =IF(X6<0,INT(X6/-20)*10,0) -> 0 | Y15: =IF(Y6<0,INT(Y6/-20)*10,0) -> 0 | Z15: =IF(Z6<0,INT(Z6/-20)*10,0) -> 0 | AA15: =IF(AA6<0,INT(AA6/-20)*10,0) -> 0 | AB15: =IF(AB6<0,INT(AB6/-20)*10,0) -> 0 | ... AD15: =IF(AD6<0,INT(AD6/-20)*10,0) -> 0
C16: 主力位 | D16: 辅助位 | E16: 辅助位 | F16: 辅助位 | G16: 辅助位 | H16: 总值 | I16: 主力位 | J16: 辅助位 | K16: 辅助位 | L16: 辅助位 | M16: 辅助位 | N16: 总值 | O16: 魔力不足 | T16: 单独扣除 | U16: =U15/2 -> 0 | V16: =V15/2 -> 0 | W16: =W15/2 -> 0 | X16: =X15/2 -> 0 | Y16: =Y15/2 -> 0 | Z16: =Z15/2 -> 0 | AA16: =AA15/2 -> 0 | AB16: =AB15/2 -> 0 | ... AD16: =AD15/2 -> 0
C17: 醉枭赌徒 | D17: 焰狼 | E17: 哈基米嗷 | F17: 无 | G17: 无 | H17: 总值 | I17: 机甲少女 | J17: 无 | K17: 无 | L17: 无 | M17: 无 | N17: 总值 | O17: 高于-20 | P17: 0 | T17: 角色保底
B18: 魔力不足 | C18: 0 | D18: 0 | E18: 0 | F18: 0 | G18: 0 | H18: / | I18: 0 | J18: 0 | K18: 0 | L18: 0 | M18: 0 | N18: / | O18: 单独行动-20 | P18: -5 | T18: 角色保穿
B19: 等级 | C19: =INDEX('战斗计算（新）'!$B$1:$L$103,MATCH(C17,'战斗计算（新）'!$C$1:$C$103,0),3)+C6 -> 70 | D19: =INDEX('战斗计算（新）'!$B$1:$L$103,MATCH(D17,'战斗计算（新）'!$C$1:$C$103,0),3)+C7 -> 70 | E19: =INDEX('战斗计算（新）'!$B$1:$L$103,MATCH(E17,'战斗计算（新）'!$C$1:$C$103,0),3)+C8 -> 40 | F19: =INDEX('战斗计算（新）'!$B$1:$L$103,MATCH(F17,'战斗计算（新）'!$C$1:$C$103,0),3)+C9 -> 0 | G19: =INDEX('战斗计算（新）'!$B$1:$L$103,MATCH(G17,'战斗计算（新）'!$C$1:$C$103,0),3)+C10 -> 0 | H19: =C19 -> 70 | I19: =INDEX('战斗计算（新）'!$B$1:$L$103,MATCH(I17,'战斗计算（新）'!$C$1:$C$103,0),3)+C11 -> 45 | J19: =INDEX('战斗计算（新）'!$B$1:$L$103,MATCH(J17,'战斗计算（新）'!$C$1:$C$103,0),3)+C12 -> 0 | K19: =INDEX('战斗计算（新）'!$B$1:$L$103,MATCH(K17,'战斗计算（新）'!$C$1:$C$103,0),3)+C13 -> 0 | L19: =INDEX('战斗计算（新）'!$B$1:$L$103,MATCH(L17,'战斗计算（新）'!$C$1:$C$103,0),3)+C14 -> 0 | M19: =INDEX('战斗计算（新）'!$B$1:$L$103,MATCH(M17,'战斗计算（新）'!$C$1:$C$103,0),3)+C15 -> 0 | N19: =I19 -> 45 | O19: 低于-20 | P19: -10 | T19: 最终 | U19: =MAX(0,MAX(U17:Y17)-MAX(Z18:AD18)) -> 0 | Z19: =MAX(0,MAX(Z17:AD17)-MAX(U18:Y18)) -> 0
B20: 筋力 | C20: =INDEX('战斗计算（新）'!$B$1:$L$103,MATCH(C17,'战斗计算（新）'!$C$1:$C$103,0),4)+C18+D6+SUM(J6:L6) -> 105 | D20: =INDEX('战斗计算（新）'!$B$1:$L$103,MATCH(D17,'战斗计算（新）'!$C$1:$C$103,0),4)+D18+D7+SUM(J7:L7) -> 10 | E20: =INDEX('战斗计算（新）'!$B$1:$L$103,MATCH(E17,'战斗计算（新）'!$C$1:$C$103,0),4)+E18+D8+SUM(J8:L8) -> 70 | F20: =INDEX('战斗计算（新）'!$B$1:$L$103,MATCH(F17,'战斗计算（新）'!$C$1:$C$103,0),4)+F18+D9+SUM(J9:L9) -> 0 | G20: =INDEX('战斗计算（新）'!$B$1:$L$103,MATCH(G17,'战斗计算（新）'!$C$1:$C$103,0),4)+G18+D10+SUM(J10:L10) -> 0 | H20: =C20+(D20+E20+G20+F20)/2 -> 145 | I20: =INDEX('战斗计算（新）'!$B$1:$L$103,MATCH(I17,'战斗计算（新）'!$C$1:$C$103,0),4)+I18+D11+SUM(J11:L11) -> 70 | J20: =INDEX('战斗计算（新）'!$B$1:$L$103,MATCH(J17,'战斗计算（新）'!$C$1:$C$103,0),4)+J18+D12+SUM(J12:L12) -> 0 | K20: =INDEX('战斗计算（新）'!$B$1:$L$103,MATCH(K17,'战斗计算（新）'!$C$1:$C$103,0),4)+K18+D13+SUM(J13:L13) -> 0 | L20: =INDEX('战斗计算（新）'!$B$1:$L$103,MATCH(L17,'战斗计算（新）'!$C$1:$C$103,0),4)+L18+D14+SUM(J14:L14) -> 0 | M20: =INDEX('战斗计算（新）'!$B$1:$L$103,MATCH(M17,'战斗计算（新）'!$C$1:$C$103,0),4)+M18+D15+SUM(J15:L15) -> 0 | N20: =I20+(M20+L20+K20+J20)/2 -> 70 | O20: 单独行动-60 | P20: -15
B21: 耐力 | C21: =INDEX('战斗计算（新）'!$B$1:$L$103,MATCH(C17,'战斗计算（新）'!$C$1:$C$103,0),5)+C18+E6+SUM(J6:L6) -> 175 | D21: =INDEX('战斗计算（新）'!$B$1:$L$103,MATCH(D17,'战斗计算（新）'!$C$1:$C$103,0),5)+D18+E7+SUM(J7:L7) -> 25 | E21: =INDEX('战斗计算（新）'!$B$1:$L$103,MATCH(E17,'战斗计算（新）'!$C$1:$C$103,0),5)+E18+E8+SUM(J8:L8) -> 65 | F21: =INDEX('战斗计算（新）'!$B$1:$L$103,MATCH(F17,'战斗计算（新）'!$C$1:$C$103,0),5)+F18+E9+SUM(J9:L9) -> 0 | G21: =INDEX('战斗计算（新）'!$B$1:$L$103,MATCH(G17,'战斗计算（新）'!$C$1:$C$103,0),5)+G18+E10+SUM(J10:L10) -> 0 | H21: =C21+(D21+E21+G21+F21)/2 -> 220 | I21: =INDEX('战斗计算（新）'!$B$1:$L$103,MATCH(I17,'战斗计算（新）'!$C$1:$C$103,0),5)+I18+E11+SUM(J11:L11) -> 70 | J21: =INDEX('战斗计算（新）'!$B$1:$L$103,MATCH(J17,'战斗计算（新）'!$C$1:$C$103,0),5)+J18+E12+SUM(J12:L12) -> 0 | K21: =INDEX('战斗计算（新）'!$B$1:$L$103,MATCH(K17,'战斗计算（新）'!$C$1:$C$103,0),5)+K18+E13+SUM(J13:L13) -> 0 | L21: =INDEX('战斗计算（新）'!$B$1:$L$103,MATCH(L17,'战斗计算（新）'!$C$1:$C$103,0),5)+L18+E14+SUM(J14:L14) -> 0 | M21: =INDEX('战斗计算（新）'!$B$1:$L$103,MATCH(M17,'战斗计算（新）'!$C$1:$C$103,0),5)+M18+E15+SUM(J15:L15) -> 0 | N21: =I21+(M21+L21+K21+J21)/2 -> 70 | O21: 低于-40 | P21: -20
B22: 敏捷 | C22: =INDEX('战斗计算（新）'!$B$1:$L$103,MATCH(C17,'战斗计算（新）'!$C$1:$C$103,0),6)+C18+F6+SUM(J6:L6) -> 40 | D22: =INDEX('战斗计算（新）'!$B$1:$L$103,MATCH(D17,'战斗计算（新）'!$C$1:$C$103,0),6)+D18+F7 -> 40 | E22: =INDEX('战斗计算（新）'!$B$1:$L$103,MATCH(E17,'战斗计算（新）'!$C$1:$C$103,0),6)+E18+F8+SUM(J8:L8) -> 70 | F22: =INDEX('战斗计算（新）'!$B$1:$L$103,MATCH(F17,'战斗计算（新）'!$C$1:$C$103,0),6)+F18+F9+SUM(J9:L9) -> 0 | G22: =INDEX('战斗计算（新）'!$B$1:$L$103,MATCH(G17,'战斗计算（新）'!$C$1:$C$103,0),6)+G18+F10+SUM(J10:L10) -> 0 | H22: =C22+(D22+E22+G22+F22)/2 -> 95 | I22: =INDEX('战斗计算（新）'!$B$1:$L$103,MATCH(I17,'战斗计算（新）'!$C$1:$C$103,0),6)+I18+F11+SUM(J11:L11) -> 70 | J22: =INDEX('战斗计算（新）'!$B$1:$L$103,MATCH(J17,'战斗计算（新）'!$C$1:$C$103,0),6)+J18+F12+SUM(J12:L12) -> 0 | K22: =INDEX('战斗计算（新）'!$B$1:$L$103,MATCH(K17,'战斗计算（新）'!$C$1:$C$103,0),6)+K18+F13+SUM(J13:L13) -> 0 | L22: =INDEX('战斗计算（新）'!$B$1:$L$103,MATCH(L17,'战斗计算（新）'!$C$1:$C$103,0),6)+L18+F14+SUM(J14:L14) -> 0 | M22: =INDEX('战斗计算（新）'!$B$1:$L$103,MATCH(M17,'战斗计算（新）'!$C$1:$C$103,0),6)+M18+F15+SUM(J15:L15) -> 0 | N22: =I22+(M22+L22+K22+J22)/2 -> 70 | O22: 单独行动-100 | P22: -25 | T22: 技能、宝具提醒器
B23: 魔力 | C23: =INDEX('战斗计算（新）'!$B$1:$L$103,MATCH(C17,'战斗计算（新）'!$C$1:$C$103,0),7)+C18+G6 -> 35 | D23: =INDEX('战斗计算（新）'!$B$1:$L$103,MATCH(D17,'战斗计算（新）'!$C$1:$C$103,0),7)+D18+G7+SUM(J7:K7) -> 20 | E23: =INDEX('战斗计算（新）'!$B$1:$L$103,MATCH(E17,'战斗计算（新）'!$C$1:$C$103,0),7)+E18+G8+SUM(J8:K8) -> 0 | F23: =INDEX('战斗计算（新）'!$B$1:$L$103,MATCH(F17,'战斗计算（新）'!$C$1:$C$103,0),7)+F18+G9+SUM(J9:K9) -> 0 | G23: =INDEX('战斗计算（新）'!$B$1:$L$103,MATCH(G17,'战斗计算（新）'!$C$1:$C$103,0),7)+G18+G10+SUM(J10:K10) -> 0 | H23: =C23+(D23+E23+G23+F23)/2 -> 45 | I23: =INDEX('战斗计算（新）'!$B$1:$L$103,MATCH(I17,'战斗计算（新）'!$C$1:$C$103,0),7)+I18+G11+SUM(J11:K11) -> 80 | J23: =INDEX('战斗计算（新）'!$B$1:$L$103,MATCH(J17,'战斗计算（新）'!$C$1:$C$103,0),7)+J18+G12+SUM(J12:K12) -> 0 | K23: =INDEX('战斗计算（新）'!$B$1:$L$103,MATCH(K17,'战斗计算（新）'!$C$1:$C$103,0),7)+K18+G13+SUM(J13:K13) -> 0 | L23: =INDEX('战斗计算（新）'!$B$1:$L$103,MATCH(L17,'战斗计算（新）'!$C$1:$C$103,0),7)+L18+G14+SUM(J14:K14) -> 0 | M23: =INDEX('战斗计算（新）'!$B$1:$L$103,MATCH(M17,'战斗计算（新）'!$C$1:$C$103,0),7)+M18+G15+SUM(J15:K15) -> 0 | N23: =I23+(M23+L23+K23+J23)/2 -> 80 | O23: 低于-60 | P23: -30 | T23: 蓝色方 | X23: 黄色方 | AB23: 绿色方
B24: 幸运 | C24: =INDEX('战斗计算（新）'!$B$1:$L$103,MATCH(C17,'战斗计算（新）'!$C$1:$C$103,0),8)+C18+H6+SUM(J6:K6) -> 80 | D24: =INDEX('战斗计算（新）'!$B$1:$L$103,MATCH(D17,'战斗计算（新）'!$C$1:$C$103,0),8)+D18+H7+SUM(J7:K7) -> 45 | E24: =INDEX('战斗计算（新）'!$B$1:$L$103,MATCH(E17,'战斗计算（新）'!$C$1:$C$103,0),8)+E18+H8+SUM(J8:K8) -> 50 | F24: =INDEX('战斗计算（新）'!$B$1:$L$103,MATCH(F17,'战斗计算（新）'!$C$1:$C$103,0),8)+F18+H9+SUM(J9:K9) -> 0 | G24: =INDEX('战斗计算（新）'!$B$1:$L$103,MATCH(G17,'战斗计算（新）'!$C$1:$C$103,0),8)+G18+H10+SUM(J10:K10) -> 0 | H24: =C24+(D24+E24+G24+F24)/2 -> 127.5 | I24: =INDEX('战斗计算（新）'!$B$1:$L$103,MATCH(I17,'战斗计算（新）'!$C$1:$C$103,0),8)+I18+H11+SUM(J11:K11) -> 40 | J24: =INDEX('战斗计算（新）'!$B$1:$L$103,MATCH(J17,'战斗计算（新）'!$C$1:$C$103,0),8)+J18+H12+SUM(J12:K12) -> 0 | K24: =INDEX('战斗计算（新）'!$B$1:$L$103,MATCH(K17,'战斗计算（新）'!$C$1:$C$103,0),8)+K18+H13+SUM(J13:K13) -> 0 | L24: =INDEX('战斗计算（新）'!$B$1:$L$103,MATCH(L17,'战斗计算（新）'!$C$1:$C$103,0),8)+L18+H14+SUM(J14:K14) -> 0 | M24: =INDEX('战斗计算（新）'!$B$1:$L$103,MATCH(M17,'战斗计算（新）'!$C$1:$C$103,0),8)+M18+H15+SUM(J15:K15) -> 0 | N24: =I24+(M24+L24+K24+J24)/2 -> 40 | O24: 单独行动-140 | P24: -35
B25: 宝具 | C25: =INDEX('战斗计算（新）'!$B$1:$L$103,MATCH(C17,'战斗计算（新）'!$C$1:$C$103,0),9)+I6+K6 -> 55 | D25: =INDEX('战斗计算（新）'!$B$1:$L$103,MATCH(D17,'战斗计算（新）'!$C$1:$C$103,0),9)+I7+K7 -> 95 | E25: =INDEX('战斗计算（新）'!$B$1:$L$103,MATCH(E17,'战斗计算（新）'!$C$1:$C$103,0),9)+I8+K7 -> 0 | F25: =INDEX('战斗计算（新）'!$B$1:$L$103,MATCH(F17,'战斗计算（新）'!$C$1:$C$103,0),9)+I9+K9 -> 0 | G25: =INDEX('战斗计算（新）'!$B$1:$L$103,MATCH(G17,'战斗计算（新）'!$C$1:$C$103,0),9)+I10+K10 -> 0 | H25: =C25+(D25+E25+G25+F25)/2 -> 102.5 | I25: =INDEX('战斗计算（新）'!$B$1:$L$103,MATCH(I17,'战斗计算（新）'!$C$1:$C$103,0),9)+I11+K11 -> 0 | J25: =INDEX('战斗计算（新）'!$B$1:$L$103,MATCH(J17,'战斗计算（新）'!$C$1:$C$103,0),9)+I12+K12 -> 0 | K25: =INDEX('战斗计算（新）'!$B$1:$L$103,MATCH(K17,'战斗计算（新）'!$C$1:$C$103,0),9)+I13+K13 -> 0 | L25: =INDEX('战斗计算（新）'!$B$1:$L$103,MATCH(L17,'战斗计算（新）'!$C$1:$C$103,0),9)+I14+K14 -> 0 | M25: =INDEX('战斗计算（新）'!$B$1:$L$103,MATCH(M17,'战斗计算（新）'!$C$1:$C$103,0),9)+I15+K15 -> 0 | N25: =I25+(M25+L25+K25+J25)/2 -> 0 | O25: 低于-80 | P25: -40
B26: 战前胜补 | C26: 20 | H26: =IF($E$96="辅助胜率正常",SUM(C26:G26),C26+SUM(D26:G26)/2) -> 20 | N26: =IF($E$96="辅助胜率正常",SUM(I26:M26),I26+SUM(J26:M26)/2) -> 0
B27: 战前胜惩 | H27: =SUM(C27:G27) -> 0 | N27: =SUM(I27:M27) -> 0
B31: 组别 | C31: 等级 | D31: 筋力 | E31: 耐力 | F31: 敏捷 | G31: 魔力 | H31: 幸运 | I31: 宝具 | J31: 宝外补惩 | K31: 全属补惩 | L31: 上三补惩
B32: =C17 -> 醉枭赌徒
B33: =D17 -> 焰狼
B34: =E17 -> 哈基米嗷
B35: =F17 -> 无
B36: =G17 -> 无
B37: =I17 -> 机甲少女
B38: =J17 -> 无
B39: =K17 -> 无
B40: =L17 -> 无
B41: =M17 -> 无
B42: / | C42: 主力位 | D42: 辅助位 | E42: 辅助位 | F42: 辅助位 | G42: 辅助位 | H42: 总值 | I42: 主力位 | J42: 辅助位 | K42: 辅助位 | L42: 辅助位 | M42: 辅助位 | N42: 总值
B43: 单位 | C43: =C17 -> 醉枭赌徒 | D43: =D17 -> 焰狼 | E43: =E17 -> 哈基米嗷 | F43: =F17 -> 无 | G43: =G17 -> 无 | H43: / | I43: =I17 -> 机甲少女 | J43: =J17 -> 无 | K43: =K17 -> 无 | L43: =L17 -> 无 | M43: =M17 -> 无 | N43: /
B44: 等级 | C44: =MAX(0,C19+C32) -> 70 | D44: =D19+C33 -> 70 | E44: =E19+C34 -> 40 | F44: =F19+C35 -> 0 | G44: =G19+C36 -> 0 | H44: =C44 -> 70 | I44: =MAX(0,I19+C37) -> 45 | J44: =J19+C38 -> 0 | K44: =K19+C39 -> 0 | L44: =L19+C40 -> 0 | M44: =M19+C41 -> 0 | N44: =I44 -> 45
B45: 筋力 | C45: =MAX(0,C20+D32+J32+K32+L32) -> 105 | D45: =MAX(0,D20+D33+J33+K33+L33) -> 10 | E45: =MAX(0,E20+D34+J34+K34+L34) -> 70 | F45: =MAX(0,F20+D35+J35+K35+L35) -> 0 | G45: =MAX(0,G20+D36+J36+K36+L36) -> 0 | H45: =SUM(C45+((D45+E45+F45+G45)/2)) -> 145 | I45: =MAX(0,I20+D37+J37+K37+L37) -> 70 | J45: =MAX(0,J20+D38+J38+K38+L38) -> 0 | K45: =MAX(0,K20+D39+J39+K39+L39) -> 0 | L45: =MAX(0,L20+D40+J40+K40+L40) -> 0 | M45: =MAX(0,M20+D41+J41+K41+L41) -> 0 | N45: =SUM(I45+((J45+K45+L45+M45)/2)) -> 70
...

Sheet 三方混戰五人版
A1: 初始工序 | C1: 决定参战人选
B3: 主力 | C3: 辅助一(减半) | D3: 辅助二(减半) | E3: 辅助二(减半) | F3: 辅助二(减半) | G3: 总值 | H3: 主力 | I3: 辅助一(减半) | J3: 辅助二(减半) | K3: 辅助二(减半) | L3: 辅助二(减半) | M3: 总值 | N3: 主力 | O3: 辅助一(减半) | P3: 辅助二(减半) | Q3: 辅助一(减半) | R3: 辅助一(减半) | S3: 总值 | T3: 魔力不足
B4: 无 | C4: 无 | D4: 无 | E4: 无 | F4: 无 | G4: 总值 | H4: 无 | I4: 无 | J4: 无 | K4: 无 | L4: 无 | M4: 总值 | N4: 无 | O4: 无 | P4: 无 | Q4: 无 | R4: 无 | S4: 总值 | T4: 高于-80 | U4: 0
A5: 魔力不足扣减属性 | B5: 0 | C5: 0 | D5: 0 | E5: 0 | F5: 0 | G5: / | H5: 0 | I5: 0 | J5: 0 | K5: 0 | L5: 0 | M5: / | N5: 0 | O5: 0 | P5: 0 | Q5: 0 | R5: 0 | S5: / | T5: 单独行动-20 | U5: -5
A6: 等级 | B6: =INDEX(#REF!,MATCH(B4,#REF!,0),3) -> #REF! | C6: =INDEX(#REF!,MATCH(C4,#REF!,0),3) -> #REF! | D6: =INDEX(#REF!,MATCH(D4,#REF!,0),3) -> #REF! | E6: =INDEX(#REF!,MATCH(E4,#REF!,0),3) -> #REF! | F6: =INDEX(#REF!,MATCH(F4,#REF!,0),3) -> #REF! | G6: =B6 -> #REF! | H6: =INDEX(#REF!,MATCH(H4,#REF!,0),3) -> #REF! | I6: =INDEX(#REF!,MATCH(I4,#REF!,0),3) -> #REF! | J6: =INDEX(#REF!,MATCH(J4,#REF!,0),3) -> #REF! | K6: =INDEX(#REF!,MATCH(K4,#REF!,0),3) -> #REF! | L6: =INDEX(#REF!,MATCH(L4,#REF!,0),3) -> #REF! | M6: =H6 -> #REF! | N6: =INDEX(#REF!,MATCH(N4,#REF!,0),3) -> #REF! | O6: =INDEX(#REF!,MATCH(O4,#REF!,0),3) -> #REF! | P6: =INDEX(#REF!,MATCH(P4,#REF!,0),3) -> #REF! | Q6: =INDEX(#REF!,MATCH(Q4,#REF!,0),3) -> #REF! | R6: =INDEX(#REF!,MATCH(R4,#REF!,0),3) -> #REF! | S6: =N6 -> #REF! | T6: 低于-20 | U6: -10
A7: 筋力 | B7: =MAX(INDEX(#REF!,MATCH(B4,#REF!,0),4)+(B5),0) -> #REF! | C7: =MAX(INDEX(#REF!,MATCH(C4,#REF!,0),4)+(C5),0) -> #REF! | D7: =MAX(INDEX(#REF!,MATCH(D4,#REF!,0),4)+(D5),0) -> #REF! | E7: =MAX(INDEX(#REF!,MATCH(E4,#REF!,0),4)+(E5),0) -> #REF! | F7: =MAX(INDEX(#REF!,MATCH(F4,#REF!,0),4)+(F5),0) -> #REF! | G7: =SUM(B7+((C7+D7+E7+F7)/2)) -> #REF! | H7: =MAX(INDEX(#REF!,MATCH(H4,#REF!,0),4)+(H5),0) -> #REF! | I7: =MAX(INDEX(#REF!,MATCH(I4,#REF!,0),4)+(I5),0) -> #REF! | J7: =MAX(INDEX(#REF!,MATCH(J4,#REF!,0),4)+(J5),0) -> #REF! | K7: =MAX(INDEX(#REF!,MATCH(K4,#REF!,0),4)+(K5),0) -> #REF! | L7: =MAX(INDEX(#REF!,MATCH(L4,#REF!,0),4)+(L5),0) -> #REF! | M7: =SUM(H7+((I7+J7+K7+L7)/2)) -> #REF! | N7: =MAX(INDEX(#REF!,MATCH(N4,#REF!,0),4)+(N5),0) -> #REF! | O7: =MAX(INDEX(#REF!,MATCH(O4,#REF!,0),4)+(O5),0) -> #REF! | P7: =MAX(INDEX(#REF!,MATCH(P4,#REF!,0),4)+(P5),0) -> #REF! | Q7: =MAX(INDEX(#REF!,MATCH(Q4,#REF!,0),4)+(Q5),0) -> #REF! | R7: =MAX(INDEX(#REF!,MATCH(R4,#REF!,0),4)+(R5),0) -> #REF! | S7: =SUM(N7+((O7+P7+Q7+R7)/2)) -> #REF! | T7: 单独行动-60 | U7: -15
A8: 耐力 | B8: =MAX(INDEX(#REF!,MATCH(B4,#REF!,0),5)+(B5),0) -> #REF! | C8: =MAX(INDEX(#REF!,MATCH(C4,#REF!,0),5)+(C5),0) -> #REF! | D8: =MAX(INDEX(#REF!,MATCH(D4,#REF!,0),5)+(D5),0) -> #REF! | E8: =MAX(INDEX(#REF!,MATCH(E4,#REF!,0),5)+(E5),0) -> #REF! | F8: =MAX(INDEX(#REF!,MATCH(F4,#REF!,0),5)+(F5),0) -> #REF! | G8: =SUM(B8+((C8+D8+E8+F8)/2)) -> #REF! | H8: =MAX(INDEX(#REF!,MATCH(H4,#REF!,0),5)+(H5),0) -> #REF! | I8: =MAX(INDEX(#REF!,MATCH(I4,#REF!,0),5)+(I5),0) -> #REF! | J8: =MAX(INDEX(#REF!,MATCH(J4,#REF!,0),5)+(J5),0) -> #REF! | K8: =MAX(INDEX(#REF!,MATCH(K4,#REF!,0),5)+(K5),0) -> #REF! | L8: =MAX(INDEX(#REF!,MATCH(L4,#REF!,0),5)+(L5),0) -> #REF! | M8: =SUM(H8+((I8+J8+K8+L8)/2)) -> #REF! | N8: =MAX(INDEX(#REF!,MATCH(N4,#REF!,0),5)+(N5),0) -> #REF! | O8: =MAX(INDEX(#REF!,MATCH(O4,#REF!,0),5)+(O5),0) -> #REF! | P8: =MAX(INDEX(#REF!,MATCH(P4,#REF!,0),5)+(P5),0) -> #REF! | Q8: =MAX(INDEX(#REF!,MATCH(Q4,#REF!,0),5)+(Q5),0) -> #REF! | R8: =MAX(INDEX(#REF!,MATCH(R4,#REF!,0),5)+(R5),0) -> #REF! | S8: =SUM(N8+((O8+P8+Q8+R8)/2)) -> #REF! | T8: 低于-40 | U8: -20
A9: 敏捷 | B9: =MAX(INDEX(#REF!,MATCH(B4,#REF!,0),6)+(B5),0) -> #REF! | C9: =MAX(INDEX(#REF!,MATCH(C4,#REF!,0),6)+(C5),0) -> #REF! | D9: =MAX(INDEX(#REF!,MATCH(D4,#REF!,0),6)+(D5),0) -> #REF! | E9: =MAX(INDEX(#REF!,MATCH(E4,#REF!,0),6)+(E5),0) -> #REF! | F9: =MAX(INDEX(#REF!,MATCH(F4,#REF!,0),6)+(F5),0) -> #REF! | G9: =SUM(B9+((C9+D9+E9+F9)/2)) -> #REF! | H9: =MAX(INDEX(#REF!,MATCH(H4,#REF!,0),6)+(H5),0) -> #REF! | I9: =MAX(INDEX(#REF!,MATCH(I4,#REF!,0),6)+(I5),0) -> #REF! | J9: =MAX(INDEX(#REF!,MATCH(J4,#REF!,0),6)+(J5),0) -> #REF! | K9: =MAX(INDEX(#REF!,MATCH(K4,#REF!,0),6)+(K5),0) -> #REF! | L9: =MAX(INDEX(#REF!,MATCH(L4,#REF!,0),6)+(L5),0) -> #REF! | M9: =SUM(H9+((I9+J9+K9+L9)/2)) -> #REF! | N9: =MAX(INDEX(#REF!,MATCH(N4,#REF!,0),6)+(N5),0) -> #REF! | O9: =MAX(INDEX(#REF!,MATCH(O4,#REF!,0),6)+(O5),0) -> #REF! | P9: =MAX(INDEX(#REF!,MATCH(P4,#REF!,0),6)+(P5),0) -> #REF! | Q9: =MAX(INDEX(#REF!,MATCH(Q4,#REF!,0),6)+(Q5),0) -> #REF! | R9: =MAX(INDEX(#REF!,MATCH(R4,#REF!,0),6)+(R5),0) -> #REF! | S9: =SUM(N9+((O9+P9+Q9+R9)/2)) -> #REF! | T9: 单独行动-100 | U9: -25
A10: 魔力 | B10: =MAX(INDEX(#REF!,MATCH(B4,#REF!,0),7)+(B5),0) -> #REF! | C10: =MAX(INDEX(#REF!,MATCH(C4,#REF!,0),7)+(C5),0) -> #REF! | D10: =MAX(INDEX(#REF!,MATCH(D4,#REF!,0),7)+(D5),0) -> #REF! | E10: =MAX(INDEX(#REF!,MATCH(E4,#REF!,0),7)+(E5),0) -> #REF! | F10: =MAX(INDEX(#REF!,MATCH(F4,#REF!,0),7)+(F5),0) -> #REF! | G10: =SUM(B10+((C10+D10+E10+F10)/2)) -> #REF! | H10: =MAX(INDEX(#REF!,MATCH(H4,#REF!,0),7)+(H5),0) -> #REF! | I10: =MAX(INDEX(#REF!,MATCH(I4,#REF!,0),7)+(I5),0) -> #REF! | J10: =MAX(INDEX(#REF!,MATCH(J4,#REF!,0),7)+(J5),0) -> #REF! | K10: =MAX(INDEX(#REF!,MATCH(K4,#REF!,0),7)+(K5),0) -> #REF! | L10: =MAX(INDEX(#REF!,MATCH(L4,#REF!,0),7)+(L5),0) -> #REF! | M10: =SUM(H10+((I10+J10+K10+L10)/2)) -> #REF! | N10: =MAX(INDEX(#REF!,MATCH(N4,#REF!,0),7)+(N5),0) -> #REF! | O10: =MAX(INDEX(#REF!,MATCH(O4,#REF!,0),7)+(O5),0) -> #REF! | P10: =MAX(INDEX(#REF!,MATCH(P4,#REF!,0),7)+(P5),0) -> #REF! | Q10: =MAX(INDEX(#REF!,MATCH(Q4,#REF!,0),7)+(Q5),0) -> #REF! | R10: =MAX(INDEX(#REF!,MATCH(R4,#REF!,0),7)+(R5),0) -> #REF! | S10: =SUM(N10+((O10+P10+Q10+R10)/2)) -> #REF! | T10: 低于-60 | U10: -30
A11: 幸运 | B11: =MAX(INDEX(#REF!,MATCH(B4,#REF!,0),8)+(B5),0) -> #REF! | C11: =MAX(INDEX(#REF!,MATCH(C4,#REF!,0),8)+(C5),0) -> #REF! | D11: =MAX(INDEX(#REF!,MATCH(D4,#REF!,0),8)+(D5),0) -> #REF! | E11: =MAX(INDEX(#REF!,MATCH(E4,#REF!,0),8)+(E5),0) -> #REF! | F11: =MAX(INDEX(#REF!,MATCH(F4,#REF!,0),8)+(F5),0) -> #REF! | G11: =SUM(B11+((C11+D11+E11+F11)/2)) -> #REF! | H11: =MAX(INDEX(#REF!,MATCH(H4,#REF!,0),8)+(H5),0) -> #REF! | I11: =MAX(INDEX(#REF!,MATCH(I4,#REF!,0),8)+(I5),0) -> #REF! | J11: =MAX(INDEX(#REF!,MATCH(J4,#REF!,0),8)+(J5),0) -> #REF! | K11: =MAX(INDEX(#REF!,MATCH(K4,#REF!,0),8)+(K5),0) -> #REF! | L11: =MAX(INDEX(#REF!,MATCH(L4,#REF!,0),8)+(L5),0) -> #REF! | M11: =SUM(H11+((I11+J11+K11+L11)/2)) -> #REF! | N11: =MAX(INDEX(#REF!,MATCH(N4,#REF!,0),8)+(N5),0) -> #REF! | O11: =MAX(INDEX(#REF!,MATCH(O4,#REF!,0),8)+(O5),0) -> #REF! | P11: =MAX(INDEX(#REF!,MATCH(P4,#REF!,0),8)+(P5),0) -> #REF! | Q11: =MAX(INDEX(#REF!,MATCH(Q4,#REF!,0),8)+(Q5),0) -> #REF! | R11: =MAX(INDEX(#REF!,MATCH(R4,#REF!,0),8)+(R5),0) -> #REF! | S11: =SUM(N11+((O11+P11+Q11+R11)/2)) -> #REF! | T11: 单独行动-140 | U11: -35
A12: 宝具 | B12: =MAX(INDEX(#REF!,MATCH(B4,#REF!,0),9)+(B5),0) -> #REF! | C12: =MAX(INDEX(#REF!,MATCH(C4,#REF!,0),9)+(C5),0) -> #REF! | D12: =MAX(INDEX(#REF!,MATCH(D4,#REF!,0),9)+(D5),0) -> #REF! | E12: =MAX(INDEX(#REF!,MATCH(E4,#REF!,0),9)+(E5),0) -> #REF! | F12: =MAX(INDEX(#REF!,MATCH(F4,#REF!,0),9)+(F5),0) -> #REF! | G12: =SUM(B12+((C12+D12+E12+F12)/2)) -> #REF! | H12: =MAX(INDEX(#REF!,MATCH(H4,#REF!,0),9)+(H5),0) -> #REF! | I12: =MAX(INDEX(#REF!,MATCH(I4,#REF!,0),9)+(I5),0) -> #REF! | J12: =MAX(INDEX(#REF!,MATCH(J4,#REF!,0),9)+(J5),0) -> #REF! | K12: =MAX(INDEX(#REF!,MATCH(K4,#REF!,0),9)+(K5),0) -> #REF! | L12: =MAX(INDEX(#REF!,MATCH(L4,#REF!,0),9)+(L5),0) -> #REF! | M12: =SUM(H12+((I12+J12+K12+L12)/2)) -> #REF! | N12: =MAX(INDEX(#REF!,MATCH(N4,#REF!,0),9)+(N5),0) -> #REF! | O12: =MAX(INDEX(#REF!,MATCH(O4,#REF!,0),9)+(O5),0) -> #REF! | P12: =MAX(INDEX(#REF!,MATCH(P4,#REF!,0),9)+(P5),0) -> #REF! | Q12: =MAX(INDEX(#REF!,MATCH(Q4,#REF!,0),9)+(Q5),0) -> #REF! | R12: =MAX(INDEX(#REF!,MATCH(R4,#REF!,0),9)+(R5),0) -> #REF! | S12: =SUM(N12+((O12+P12+Q12+R12)/2)) -> #REF! | T12: 低于-80 | U12: -40
A13: 战前胜补 | G13: =IF($D$98="辅助胜率正常",SUM(B13:F13),B13+SUM(C13:F13)/2) -> 0 | M13: =IF($D$98="辅助胜率正常",SUM(H13:L13),H13+SUM(I13:L13)/2) -> 0 | S13: =IF($D$98="辅助胜率正常",SUM(N13:R13),N13+SUM(O13:R13)/2) -> 0
A14: 初始工序 | C14: 计算补正属性
E15: 不用这部份的话，自行摺起，别删
A16: 组别 | B16: 等级+/- | C16: 筋+/- | D16: 耐+/- | E16: 敏+/- | F16: 魔+/- | G16: 运+/- | H16: 宝+/- | I16: 胜率补正
A17: =B4 -> 无
A18: =C4 -> 无
A19: =D4 -> 无
A20: =E4 -> 无 | J20: =IF($D$98="辅助胜率正常",SUM(I17:I21),I17+SUM(I18:I21)/2) -> 0
A21: =F4 -> 无
A22: =H4 -> 无
A23: =I4 -> 无
A24: =J4 -> 无
A25: =K4 -> 无 | J25: =IF($D$98="辅助胜率正常",SUM(I22:I26),I22+SUM(I23:I26)/2) -> 0
A26: =L4 -> 无
A27: =N4 -> 无
A28: =O4 -> 无
A29: =P4 -> 无
A30: =Q4 -> 无 | J30: =IF($D$98="辅助胜率正常",SUM(I27:I31),I27+SUM(I28:I31)/2) -> 0
A31: =R4 -> 无
B32: 主力 | C32: 辅一(減半) | D32: 辅二(减半) | E32: 辅二(减半) | F32: 辅二(减半) | G32: 总值 | H32: 主力 | I32: 辅一(减半) | J32: 辅二(减半) | K32: 辅二(减半) | L32: 辅二(减半) | M32: 总值 | N32: 主力 | O32: 辅一(减半) | P32: 辅二(减半) | Q32: 辅二(减半) | R32: 辅二(减半) | S32: 总值
B33: =B4 -> 无 | C33: =C4 -> 无 | D33: =D4 -> 无 | E33: =E4 -> 无 | F33: =F4 -> 无 | H33: =H4 -> 无 | I33: =I4 -> 无 | J33: =J4 -> 无 | K33: =K4 -> 无 | L33: =L4 -> 无 | N33: =N4 -> 无 | O33: =O4 -> 无 | P33: =P4 -> 无 | Q33: =Q4 -> 无 | R33: =R4 -> 无
A34: 等级 | B34: =B6+B17 -> #REF! | C34: =C6+B18 -> #REF! | D34: =D6+B19 -> #REF! | E34: =E6+B20 -> #REF! | F34: =F6+B21 -> #REF! | G34: =B34 -> #REF! | H34: =H6+B22 -> #REF! | I34: =I6+B23 -> #REF! | J34: =J6+B24 -> #REF! | K34: =K6+B25 -> #REF! | L34: =L6+B26 -> #REF! | M34: =H34 -> #REF! | N34: =N6+B27 -> #REF! | O34: =O6+B28 -> #REF! | P34: =P6+B31 -> #REF! | Q34: =Q6+B30 -> #REF! | R34: =R6+B31 -> #REF! | S34: =N34 -> #REF!
A35: 筋力 | B35: =B7+C17 -> #REF! | C35: =C7+C18 -> #REF! | D35: =D7+C19 -> #REF! | E35: =E7+C20 -> #REF! | F35: =F7+C21 -> #REF! | G35: =SUM(B35+((C35+D35+E35+F35)/2)) -> #REF! | H35: =H7+C22 -> #REF! | I35: =I7+C23 -> #REF! | J35: =J7+C24 -> #REF! | K35: =K7+C25 -> #REF! | L35: =L7+C26 -> #REF! | M35: =SUM(H35+((I35+J35+K35+L35)/2)) -> #REF! | N35: =N7+C27 -> #REF! | O35: =O7+C28 -> #REF! | P35: =P7+C31 -> #REF! | Q35: =Q7+C30 -> #REF! | R35: =R7+C31 -> #REF! | S35: =SUM(N35+((O35+P35+Q35+R35)/2)) -> #REF!
A36: 耐力 | B36: =B8+D17 -> #REF! | C36: =C8+D18 -> #REF! | D36: =D8+D19 -> #REF! | E36: =E8+D20 -> #REF! | F36: =F8+D21 -> #REF! | G36: =SUM(B36+((C36+D36+E36+F36)/2)) -> #REF! | H36: =H8+D22 -> #REF! | I36: =I8+D23 -> #REF! | J36: =J8+D24 -> #REF! | K36: =K8+D25 -> #REF! | L36: =L8+D26 -> #REF! | M36: =SUM(H36+((I36+J36+K36+L36)/2)) -> #REF! | N36: =N8+D27 -> #REF! | O36: =O8+D28 -> #REF! | P36: =P8+D31 -> #REF! | Q36: =Q8+D30 -> #REF! | R36: =R8+D31 -> #REF! | S36: =SUM(N36+((O36+P36+Q36+R36)/2)) -> #REF!
A37: 敏捷 | B37: =B9+E17 -> #REF! | C37: =C9+E18 -> #REF! | D37: =D9+E19 -> #REF! | E37: =E9+E20 -> #REF! | F37: =F9+E21 -> #REF! | G37: =SUM(B37+((C37+D37+E37+F37)/2)) -> #REF! | H37: =H9+E22 -> #REF! | I37: =I9+E23 -> #REF! | J37: =J9+E24 -> #REF! | K37: =K9+E25 -> #REF! | L37: =L9+E26 -> #REF! | M37: =SUM(H37+((I37+J37+K37+L37)/2)) -> #REF! | N37: =N9+E27 -> #REF! | O37: =O9+E28 -> #REF! | P37: =P9+E31 -> #REF! | Q37: =Q9+E30 -> #REF! | R37: =R9+E31 -> #REF! | S37: =SUM(N37+((O37+P37+Q37+R37)/2)) -> #REF!
A38: 魔力 | B38: =B10+F17 -> #REF! | C38: =C10+F18 -> #REF! | D38: =D10+F19 -> #REF! | E38: =E10+F20 -> #REF! | F38: =F10+F21 -> #REF! | G38: =SUM(B38+((C38+D38+E38+F38)/2)) -> #REF! | H38: =H10+F22 -> #REF! | I38: =I10+F23 -> #REF! | J38: =J10+F24 -> #REF! | K38: =K10+F25 -> #REF! | L38: =L10+F26 -> #REF! | M38: =SUM(H38+((I38+J38+K38+L38)/2)) -> #REF! | N38: =N10+F27 -> #REF! | O38: =O10+F28 -> #REF! | P38: =P10+F31 -> #REF! | Q38: =Q10+F30 -> #REF! | R38: =R10+F31 -> #REF! | S38: =SUM(N38+((O38+P38+Q38+R38)/2)) -> #REF!
A39: 幸运 | B39: =B11+G17 -> #REF! | C39: =C11+G18 -> #REF! | D39: =D11+G19 -> #REF! | E39: =E11+G20 -> #REF! | F39: =F11+G21 -> #REF! | G39: =SUM(B39+((C39+D39+E39+F39)/2)) -> #REF! | H39: =H11+G22 -> #REF! | I39: =I11+G23 -> #REF! | J39: =J11+G24 -> #REF! | K39: =K11+G25 -> #REF! | L39: =L11+G26 -> #REF! | M39: =SUM(H39+((I39+J39+K39+L39)/2)) -> #REF! | N39: =N11+G27 -> #REF! | O39: =O11+G28 -> #REF! | P39: =P11+G31 -> #REF! | Q39: =Q11+G30 -> #REF! | R39: =R11+G31 -> #REF! | S39: =SUM(N39+((O39+P39+Q39+R39)/2)) -> #REF!
A40: 宝具 | B40: =B12+H17 -> #REF! | C40: =C12+H18 -> #REF! | D40: =D12+H19 -> #REF! | E40: =E12+H21 -> #REF! | F40: =F12+H21 -> #REF! | G40: =SUM(B40+((C40+D40+E40+F40)/2)) -> #REF! | H40: =H12+H22 -> #REF! | I40: =I12+H23 -> #REF! | J40: =J12+H24 -> #REF! | K40: =K12+H25 -> #REF! | L40: =L12+H26 -> #REF! | M40: =SUM(H40+((I40+J40+L40+K40)/2)) -> #REF! | N40: =N12+H27 -> #REF! | O40: =O12+H28 -> #REF! | P40: =P12+H31 -> #REF! | Q40: =Q12+H30 -> #REF! | R40: =R12+H31 -> #REF! | S40: =SUM(N40+((O40+P40+Q40+R40)/2)) -> #REF!
A43: 主要工序 | C43: 决定战斗属性，与补正属性
...

Sheet 测试
A1: 暂时停用 | B1: 蓝色保底 | C1: 橙色保底 | D1: 蓝色魔耗 | E1: 橙色魔耗 | F1: 统合胜率计算表：按顺序填入蓝色方胜率 | L1: 以下是计算部分 | R1: 蓝方必胜 | S1: 橙方必胜 | T1: 蓝胜平均 | U1: 橙胜平均 | V1: 标准偏差 | W1: 最终蓝胜 | X1: 最终橙胜 | Y1: 胜率比 | Z1: 魔耗比 | AA1: 偏差度
L2: =IF(F2>(100-$C2),(100-$C2),IF(F2<$B2,$B2,F2)) -> 0 | M2: =IF(G2>(100-$C2),(100-$C2),IF(G2<$B2,$B2,G2)) -> 0 | N2: =IF(H2>(100-$C2),(100-$C2),IF(H2<$B2,$B2,H2)) -> 0 | O2: =IF(I2>(100-$C2),(100-$C2),IF(I2<$B2,$B2,I2)) -> 0 | P2: =IF(J2>(100-$C2),(100-$C2),IF(J2<$B2,$B2,J2)) -> 0 | Q2: =IF(K2>(100-$C2),(100-$C2),IF(K2<$B2,$B2,K2)) -> 0 | T2: =AVERAGE(L2:Q2) -> 0 | U2: =100-T2 -> 100 | V2: =SQRT(VARP(L2:Q2)) -> 0 | W2: =IF(R2>0,R2+(100-R2)*T2/100,IF(AND(R2=0,S2=0),T2,100-X2)) -> 0 | X2: =IF(S2>0,S2+(100-S2)*U2/100,IF(AND(R2=0,S2=0),U2,100-W2)) -> 100 | Y2: =W2/(W2+X2) -> 0 | Z2: =D2/MAX(1,D2+E2) -> 0 | AA2: =IF(Z2<>0,ABS(Z2-Y2)/Z2,0) -> 0
L3: =IF(F3>(100-$C3),(100-$C3),IF(F3<$B3,$B3,F3)) -> 0 | M3: =IF(G3>(100-$C3),(100-$C3),IF(G3<$B3,$B3,G3)) -> 0 | N3: =IF(H3>(100-$C3),(100-$C3),IF(H3<$B3,$B3,H3)) -> 0 | O3: =IF(I3>(100-$C3),(100-$C3),IF(I3<$B3,$B3,I3)) -> 0 | P3: =IF(J3>(100-$C3),(100-$C3),IF(J3<$B3,$B3,J3)) -> 0 | Q3: =IF(K3>(100-$C3),(100-$C3),IF(K3<$B3,$B3,K3)) -> 0 | T3: =AVERAGE(L3:Q3) -> 0 | U3: =100-T3 -> 100 | V3: =SQRT(VARP(L3:Q3)) -> 0 | W3: =IF(R3>0,R3+(100-R3)*T3/100,IF(AND(R3=0,S3=0),T3,100-X3)) -> 0 | X3: =IF(S3>0,S3+(100-S3)*U3/100,IF(AND(R3=0,S3=0),U3,100-W3)) -> 100 | Y3: =W3/(W3+X3) -> 0 | Z3: =D3/MAX(1,D3+E3) -> 0 | AA3: =IF(Z3<>0,ABS(Z3-Y3)/Z3,0) -> 0
L4: =IF(F4>(100-$C4),(100-$C4),IF(F4<$B4,$B4,F4)) -> 0 | M4: =IF(G4>(100-$C4),(100-$C4),IF(G4<$B4,$B4,G4)) -> 0 | N4: =IF(H4>(100-$C4),(100-$C4),IF(H4<$B4,$B4,H4)) -> 0 | O4: =IF(I4>(100-$C4),(100-$C4),IF(I4<$B4,$B4,I4)) -> 0 | P4: =IF(J4>(100-$C4),(100-$C4),IF(J4<$B4,$B4,J4)) -> 0 | Q4: =IF(K4>(100-$C4),(100-$C4),IF(K4<$B4,$B4,K4)) -> 0 | T4: =AVERAGE(L4:Q4) -> 0 | U4: =100-T4 -> 100 | V4: =SQRT(VARP(L4:Q4)) -> 0 | W4: =IF(R4>0,R4+(100-R4)*T4/100,IF(AND(R4=0,S4=0),T4,100-X4)) -> 0 | X4: =IF(S4>0,S4+(100-S4)*U4/100,IF(AND(R4=0,S4=0),U4,100-W4)) -> 100 | Y4: =W4/(W4+X4) -> 0 | Z4: =D4/MAX(1,D4+E4) -> 0 | AA4: =IF(Z4<>0,ABS(Z4-Y4)/Z4,0) -> 0
L5: =IF(F5>(100-$C5),(100-$C5),IF(F5<$B5,$B5,F5)) -> 0 | M5: =IF(G5>(100-$C5),(100-$C5),IF(G5<$B5,$B5,G5)) -> 0 | N5: =IF(H5>(100-$C5),(100-$C5),IF(H5<$B5,$B5,H5)) -> 0 | O5: =IF(I5>(100-$C5),(100-$C5),IF(I5<$B5,$B5,I5)) -> 0 | P5: =IF(J5>(100-$C5),(100-$C5),IF(J5<$B5,$B5,J5)) -> 0 | Q5: =IF(K5>(100-$C5),(100-$C5),IF(K5<$B5,$B5,K5)) -> 0 | T5: =AVERAGE(L5:Q5) -> 0 | U5: =100-T5 -> 100 | V5: =SQRT(VARP(L5:Q5)) -> 0 | W5: =IF(R5>0,R5+(100-R5)*T5/100,IF(AND(R5=0,S5=0),T5,100-X5)) -> 0 | X5: =IF(S5>0,S5+(100-S5)*U5/100,IF(AND(R5=0,S5=0),U5,100-W5)) -> 100 | Y5: =W5/(W5+X5) -> 0 | Z5: =D5/MAX(1,D5+E5) -> 0 | AA5: =IF(Z5<>0,ABS(Z5-Y5)/Z5,0) -> 0
L6: =IF(F6>(100-$C6),(100-$C6),IF(F6<$B6,$B6,F6)) -> 0 | M6: =IF(G6>(100-$C6),(100-$C6),IF(G6<$B6,$B6,G6)) -> 0 | N6: =IF(H6>(100-$C6),(100-$C6),IF(H6<$B6,$B6,H6)) -> 0 | O6: =IF(I6>(100-$C6),(100-$C6),IF(I6<$B6,$B6,I6)) -> 0 | P6: =IF(J6>(100-$C6),(100-$C6),IF(J6<$B6,$B6,J6)) -> 0 | Q6: =IF(K6>(100-$C6),(100-$C6),IF(K6<$B6,$B6,K6)) -> 0 | T6: =AVERAGE(L6:Q6) -> 0 | U6: =100-T6 -> 100 | V6: =SQRT(VARP(L6:Q6)) -> 0 | W6: =IF(R6>0,R6+(100-R6)*T6/100,IF(AND(R6=0,S6=0),T6,100-X6)) -> 0 | X6: =IF(S6>0,S6+(100-S6)*U6/100,IF(AND(R6=0,S6=0),U6,100-W6)) -> 100 | Y6: =W6/(W6+X6) -> 0 | Z6: =D6/MAX(1,D6+E6) -> 0 | AA6: =IF(Z6<>0,ABS(Z6-Y6)/Z6,0) -> 0
L7: =IF(F7>(100-$C7),(100-$C7),IF(F7<$B7,$B7,F7)) -> 0 | M7: =IF(G7>(100-$C7),(100-$C7),IF(G7<$B7,$B7,G7)) -> 0 | N7: =IF(H7>(100-$C7),(100-$C7),IF(H7<$B7,$B7,H7)) -> 0 | O7: =IF(I7>(100-$C7),(100-$C7),IF(I7<$B7,$B7,I7)) -> 0 | P7: =IF(J7>(100-$C7),(100-$C7),IF(J7<$B7,$B7,J7)) -> 0 | Q7: =IF(K7>(100-$C7),(100-$C7),IF(K7<$B7,$B7,K7)) -> 0 | T7: =AVERAGE(L7:Q7) -> 0 | U7: =100-T7 -> 100 | V7: =SQRT(VARP(L7:Q7)) -> 0 | W7: =IF(R7>0,R7+(100-R7)*T7/100,IF(AND(R7=0,S7=0),T7,100-X7)) -> 0 | X7: =IF(S7>0,S7+(100-S7)*U7/100,IF(AND(R7=0,S7=0),U7,100-W7)) -> 100 | Y7: =W7/(W7+X7) -> 0 | Z7: =D7/MAX(1,D7+E7) -> 0 | AA7: =IF(Z7<>0,ABS(Z7-Y7)/Z7,0) -> 0
L8: =IF(F8>(100-$C8),(100-$C8),IF(F8<$B8,$B8,F8)) -> 0 | M8: =IF(G8>(100-$C8),(100-$C8),IF(G8<$B8,$B8,G8)) -> 0 | N8: =IF(H8>(100-$C8),(100-$C8),IF(H8<$B8,$B8,H8)) -> 0 | O8: =IF(I8>(100-$C8),(100-$C8),IF(I8<$B8,$B8,I8)) -> 0 | P8: =IF(J8>(100-$C8),(100-$C8),IF(J8<$B8,$B8,J8)) -> 0 | Q8: =IF(K8>(100-$C8),(100-$C8),IF(K8<$B8,$B8,K8)) -> 0 | T8: =AVERAGE(L8:Q8) -> 0 | U8: =100-T8 -> 100 | V8: =SQRT(VARP(L8:Q8)) -> 0 | W8: =IF(R8>0,R8+(100-R8)*T8/100,IF(AND(R8=0,S8=0),T8,100-X8)) -> 0 | X8: =IF(S8>0,S8+(100-S8)*U8/100,IF(AND(R8=0,S8=0),U8,100-W8)) -> 100 | Y8: =W8/(W8+X8) -> 0 | Z8: =D8/MAX(1,D8+E8) -> 0 | AA8: =IF(Z8<>0,ABS(Z8-Y8)/Z8,0) -> 0
L9: =IF(F9>(100-$C9),(100-$C9),IF(F9<$B9,$B9,F9)) -> 0 | M9: =IF(G9>(100-$C9),(100-$C9),IF(G9<$B9,$B9,G9)) -> 0 | N9: =IF(H9>(100-$C9),(100-$C9),IF(H9<$B9,$B9,H9)) -> 0 | O9: =IF(I9>(100-$C9),(100-$C9),IF(I9<$B9,$B9,I9)) -> 0 | P9: =IF(J9>(100-$C9),(100-$C9),IF(J9<$B9,$B9,J9)) -> 0 | Q9: =IF(K9>(100-$C9),(100-$C9),IF(K9<$B9,$B9,K9)) -> 0 | T9: =AVERAGE(L9:Q9) -> 0 | U9: =100-T9 -> 100 | V9: =SQRT(VARP(L9:Q9)) -> 0 | W9: =IF(R9>0,R9+(100-R9)*T9/100,IF(AND(R9=0,S9=0),T9,100-X9)) -> 0 | X9: =IF(S9>0,S9+(100-S9)*U9/100,IF(AND(R9=0,S9=0),U9,100-W9)) -> 100 | Y9: =W9/(W9+X9) -> 0 | Z9: =D10/MAX(1,D10+E9) -> 0 | AA9: =IF(Z9<>0,ABS(Z9-Y9)/Z9,0) -> 0
L10: =IF(F10>(100-$C10),(100-$C10),IF(F10<$B10,$B10,F10)) -> 0 | M10: =IF(G10>(100-$C10),(100-$C10),IF(G10<$B10,$B10,G10)) -> 0 | N10: =IF(H10>(100-$C10),(100-$C10),IF(H10<$B10,$B10,H10)) -> 0 | O10: =IF(I10>(100-$C10),(100-$C10),IF(I10<$B10,$B10,I10)) -> 0 | P10: =IF(J10>(100-$C10),(100-$C10),IF(J10<$B10,$B10,J10)) -> 0 | Q10: =IF(K10>(100-$C10),(100-$C10),IF(K10<$B10,$B10,K10)) -> 0 | T10: =AVERAGE(L10:Q10) -> 0 | U10: =100-T10 -> 100 | V10: =SQRT(VARP(L10:Q10)) -> 0 | W10: =IF(R10>0,R10+(100-R10)*T10/100,IF(AND(R10=0,S10=0),T10,100-X10)) -> 0 | X10: =IF(S10>0,S10+(100-S10)*U10/100,IF(AND(R10=0,S10=0),U10,100-W10)) -> 100 | Y10: =W10/(W10+X10) -> 0 | Z10: =D10/MAX(1,D10+E10) -> 0 | AA10: =IF(Z10<>0,ABS(Z10-Y10)/Z10,0) -> 0
L11: =IF(F11>(100-$C11),(100-$C11),IF(F11<$B11,$B11,F11)) -> 0 | M11: =IF(G11>(100-$C11),(100-$C11),IF(G11<$B11,$B11,G11)) -> 0 | N11: =IF(H11>(100-$C11),(100-$C11),IF(H11<$B11,$B11,H11)) -> 0 | O11: =IF(I11>(100-$C11),(100-$C11),IF(I11<$B11,$B11,I11)) -> 0 | P11: =IF(J11>(100-$C11),(100-$C11),IF(J11<$B11,$B11,J11)) -> 0 | Q11: =IF(K11>(100-$C11),(100-$C11),IF(K11<$B11,$B11,K11)) -> 0 | T11: =AVERAGE(L11:Q11) -> 0 | U11: =100-T11 -> 100 | V11: =SQRT(VARP(L11:Q11)) -> 0 | W11: =IF(R11>0,R11+(100-R11)*T11/100,IF(AND(R11=0,S11=0),T11,100-X11)) -> 0 | X11: =IF(S11>0,S11+(100-S11)*U11/100,IF(AND(R11=0,S11=0),U11,100-W11)) -> 100 | Y11: =W11/(W11+X11) -> 0 | Z11: =D12/MAX(1,D12+E11) -> 0 | AA11: =IF(Z11<>0,ABS(Z11-Y11)/Z11,0) -> 0
L12: =IF(F12>(100-$C12),(100-$C12),IF(F12<$B12,$B12,F12)) -> 0 | M12: =IF(G12>(100-$C12),(100-$C12),IF(G12<$B12,$B12,G12)) -> 0 | N12: =IF(H12>(100-$C12),(100-$C12),IF(H12<$B12,$B12,H12)) -> 0 | O12: =IF(I12>(100-$C12),(100-$C12),IF(I12<$B12,$B12,I12)) -> 0 | P12: =IF(J12>(100-$C12),(100-$C12),IF(J12<$B12,$B12,J12)) -> 0 | Q12: =IF(K12>(100-$C12),(100-$C12),IF(K12<$B12,$B12,K12)) -> 0 | T12: =AVERAGE(L12:Q12) -> 0 | U12: =100-T12 -> 100 | V12: =SQRT(VARP(L12:Q12)) -> 0 | W12: =IF(R12>0,R12+(100-R12)*T12/100,IF(AND(R12=0,S12=0),T12,100-X12)) -> 0 | X12: =IF(S12>0,S12+(100-S12)*U12/100,IF(AND(R12=0,S12=0),U12,100-W12)) -> 100 | Y12: =W12/(W12+X12) -> 0 | Z12: =D12/MAX(1,D12+E12) -> 0 | AA12: =IF(Z12<>0,ABS(Z12-Y12)/Z12,0) -> 0
L13: =IF(F13>(100-$C13),(100-$C13),IF(F13<$B13,$B13,F13)) -> 0 | M13: =IF(G13>(100-$C13),(100-$C13),IF(G13<$B13,$B13,G13)) -> 0 | N13: =IF(H13>(100-$C13),(100-$C13),IF(H13<$B13,$B13,H13)) -> 0 | O13: =IF(I13>(100-$C13),(100-$C13),IF(I13<$B13,$B13,I13)) -> 0 | P13: =IF(J13>(100-$C13),(100-$C13),IF(J13<$B13,$B13,J13)) -> 0 | Q13: =IF(K13>(100-$C13),(100-$C13),IF(K13<$B13,$B13,K13)) -> 0 | T13: =AVERAGE(L13:Q13) -> 0 | U13: =100-T13 -> 100 | V13: =SQRT(VARP(L13:Q13)) -> 0 | W13: =IF(R13>0,R13+(100-R13)*T13/100,IF(AND(R13=0,S13=0),T13,100-X13)) -> 0 | X13: =IF(S13>0,S13+(100-S13)*U13/100,IF(AND(R13=0,S13=0),U13,100-W13)) -> 100 | Y13: =W13/(W13+X13) -> 0 | Z13: =D14/MAX(1,D14+E13) -> 0 | AA13: =IF(Z13<>0,ABS(Z13-Y13)/Z13,0) -> 0
L14: =IF(F14>(100-$C14),(100-$C14),IF(F14<$B14,$B14,F14)) -> 0 | M14: =IF(G14>(100-$C14),(100-$C14),IF(G14<$B14,$B14,G14)) -> 0 | N14: =IF(H14>(100-$C14),(100-$C14),IF(H14<$B14,$B14,H14)) -> 0 | O14: =IF(I14>(100-$C14),(100-$C14),IF(I14<$B14,$B14,I14)) -> 0 | P14: =IF(J14>(100-$C14),(100-$C14),IF(J14<$B14,$B14,J14)) -> 0 | Q14: =IF(K14>(100-$C14),(100-$C14),IF(K14<$B14,$B14,K14)) -> 0 | T14: =AVERAGE(L14:Q14) -> 0 | U14: =100-T14 -> 100 | V14: =SQRT(VARP(L14:Q14)) -> 0 | W14: =IF(R14>0,R14+(100-R14)*T14/100,IF(AND(R14=0,S14=0),T14,100-X14)) -> 0 | X14: =IF(S14>0,S14+(100-S14)*U14/100,IF(AND(R14=0,S14=0),U14,100-W14)) -> 100 | Y14: =W14/(W14+X14) -> 0 | Z14: =D14/MAX(1,D14+E14) -> 0 | AA14: =IF(Z14<>0,ABS(Z14-Y14)/Z14,0) -> 0
L15: =IF(F15>(100-$C15),(100-$C15),IF(F15<$B15,$B15,F15)) -> 0 | M15: =IF(G15>(100-$C15),(100-$C15),IF(G15<$B15,$B15,G15)) -> 0 | N15: =IF(H15>(100-$C15),(100-$C15),IF(H15<$B15,$B15,H15)) -> 0 | O15: =IF(I15>(100-$C15),(100-$C15),IF(I15<$B15,$B15,I15)) -> 0 | P15: =IF(J15>(100-$C15),(100-$C15),IF(J15<$B15,$B15,J15)) -> 0 | Q15: =IF(K15>(100-$C15),(100-$C15),IF(K15<$B15,$B15,K15)) -> 0 | T15: =AVERAGE(L15:Q15) -> 0 | U15: =100-T15 -> 100 | V15: =SQRT(VARP(L15:Q15)) -> 0 | W15: =IF(R15>0,R15+(100-R15)*T15/100,IF(AND(R15=0,S15=0),T15,100-X15)) -> 0 | X15: =IF(S15>0,S15+(100-S15)*U15/100,IF(AND(R15=0,S15=0),U15,100-W15)) -> 100 | Y15: =W15/(W15+X15) -> 0 | Z15: =D15/MAX(1,D15+E15) -> 0 | AA15: =IF(Z15<>0,ABS(Z15-Y15)/Z15,0) -> 0
L16: =IF(F16>(100-$C16),(100-$C16),IF(F16<$B16,$B16,F16)) -> 0 | M16: =IF(G16>(100-$C16),(100-$C16),IF(G16<$B16,$B16,G16)) -> 0 | N16: =IF(H16>(100-$C16),(100-$C16),IF(H16<$B16,$B16,H16)) -> 0 | O16: =IF(I16>(100-$C16),(100-$C16),IF(I16<$B16,$B16,I16)) -> 0 | P16: =IF(J16>(100-$C16),(100-$C16),IF(J16<$B16,$B16,J16)) -> 0 | Q16: =IF(K16>(100-$C16),(100-$C16),IF(K16<$B16,$B16,K16)) -> 0 | T16: =AVERAGE(L16:Q16) -> 0 | U16: =100-T16 -> 100 | V16: =SQRT(VARP(L16:Q16)) -> 0 | W16: =IF(R16>0,R16+(100-R16)*T16/100,IF(AND(R16=0,S16=0),T16,100-X16)) -> 0 | X16: =IF(S16>0,S16+(100-S16)*U16/100,IF(AND(R16=0,S16=0),U16,100-W16)) -> 100 | Y16: =W16/(W16+X16) -> 0 | Z16: =D16/MAX(1,D16+E16) -> 0 | AA16: =IF(Z16<>0,ABS(Z16-Y16)/Z16,0) -> 0
L17: =IF(F17>(100-$C17),(100-$C17),IF(F17<$B17,$B17,F17)) -> 0 | M17: =IF(G17>(100-$C17),(100-$C17),IF(G17<$B17,$B17,G17)) -> 0 | N17: =IF(H17>(100-$C17),(100-$C17),IF(H17<$B17,$B17,H17)) -> 0 | O17: =IF(I17>(100-$C17),(100-$C17),IF(I17<$B17,$B17,I17)) -> 0 | P17: =IF(J17>(100-$C17),(100-$C17),IF(J17<$B17,$B17,J17)) -> 0 | Q17: =IF(K17>(100-$C17),(100-$C17),IF(K17<$B17,$B17,K17)) -> 0 | T17: =AVERAGE(L17:Q17) -> 0 | U17: =100-T17 -> 100 | V17: =SQRT(VARP(L17:Q17)) -> 0 | W17: =IF(R17>0,R17+(100-R17)*T17/100,IF(AND(R17=0,S17=0),T17,100-X17)) -> 0 | X17: =IF(S17>0,S17+(100-S17)*U17/100,IF(AND(R17=0,S17=0),U17,100-W17)) -> 100 | Y17: =W17/(W17+X17) -> 0 | Z17: =D17/MAX(1,D17+E17) -> 0 | AA17: =IF(Z17<>0,ABS(Z17-Y17)/Z17,0) -> 0
L18: =IF(F18>(100-$C18),(100-$C18),IF(F18<$B18,$B18,F18)) -> 0 | M18: =IF(G18>(100-$C18),(100-$C18),IF(G18<$B18,$B18,G18)) -> 0 | N18: =IF(H18>(100-$C18),(100-$C18),IF(H18<$B18,$B18,H18)) -> 0 | O18: =IF(I18>(100-$C18),(100-$C18),IF(I18<$B18,$B18,I18)) -> 0 | P18: =IF(J18>(100-$C18),(100-$C18),IF(J18<$B18,$B18,J18)) -> 0 | Q18: =IF(K18>(100-$C18),(100-$C18),IF(K18<$B18,$B18,K18)) -> 0 | T18: =AVERAGE(L18:Q18) -> 0 | U18: =100-T18 -> 100 | V18: =SQRT(VARP(L18:Q18)) -> 0 | W18: =IF(R18>0,R18+(100-R18)*T18/100,IF(AND(R18=0,S18=0),T18,100-X18)) -> 0 | X18: =IF(S18>0,S18+(100-S18)*U18/100,IF(AND(R18=0,S18=0),U18,100-W18)) -> 100 | Y18: =W18/(W18+X18) -> 0 | Z18: =D18/MAX(1,D18+E18) -> 0 | AA18: =IF(Z18<>0,ABS(Z18-Y18)/Z18,0) -> 0
L19: =IF(F19>(100-$C19),(100-$C19),IF(F19<$B19,$B19,F19)) -> 0 | M19: =IF(G19>(100-$C19),(100-$C19),IF(G19<$B19,$B19,G19)) -> 0 | N19: =IF(H19>(100-$C19),(100-$C19),IF(H19<$B19,$B19,H19)) -> 0 | O19: =IF(I19>(100-$C19),(100-$C19),IF(I19<$B19,$B19,I19)) -> 0 | P19: =IF(J19>(100-$C19),(100-$C19),IF(J19<$B19,$B19,J19)) -> 0 | Q19: =IF(K19>(100-$C19),(100-$C19),IF(K19<$B19,$B19,K19)) -> 0 | T19: =AVERAGE(L19:Q19) -> 0 | U19: =100-T19 -> 100 | V19: =SQRT(VARP(L19:Q19)) -> 0 | W19: =IF(R19>0,R19+(100-R19)*T19/100,IF(AND(R19=0,S19=0),T19,100-X19)) -> 0 | X19: =IF(S19>0,S19+(100-S19)*U19/100,IF(AND(R19=0,S19=0),U19,100-W19)) -> 100 | Y19: =W19/(W19+X19) -> 0 | Z19: =D19/MAX(1,D19+E19) -> 0 | AA19: =IF(Z19<>0,ABS(Z19-Y19)/Z19,0) -> 0
L20: =IF(F20>(100-$C20),(100-$C20),IF(F20<$B20,$B20,F20)) -> 0 | M20: =IF(G20>(100-$C20),(100-$C20),IF(G20<$B20,$B20,G20)) -> 0 | N20: =IF(H20>(100-$C20),(100-$C20),IF(H20<$B20,$B20,H20)) -> 0 | O20: =IF(I20>(100-$C20),(100-$C20),IF(I20<$B20,$B20,I20)) -> 0 | P20: =IF(J20>(100-$C20),(100-$C20),IF(J20<$B20,$B20,J20)) -> 0 | Q20: =IF(K20>(100-$C20),(100-$C20),IF(K20<$B20,$B20,K20)) -> 0 | T20: =AVERAGE(L20:Q20) -> 0 | U20: =100-T20 -> 100 | V20: =SQRT(VARP(L20:Q20)) -> 0 | W20: =IF(R20>0,R20+(100-R20)*T20/100,IF(AND(R20=0,S20=0),T20,100-X20)) -> 0 | X20: =IF(S20>0,S20+(100-S20)*U20/100,IF(AND(R20=0,S20=0),U20,100-W20)) -> 100 | Y20: =W20/(W20+X20) -> 0 | Z20: =D20/MAX(1,D20+E20) -> 0 | AA20: =IF(Z20<>0,ABS(Z20-Y20)/Z20,0) -> 0
L21: =IF(F21>(100-$C21),(100-$C21),IF(F21<$B21,$B21,F21)) -> 0 | M21: =IF(G21>(100-$C21),(100-$C21),IF(G21<$B21,$B21,G21)) -> 0 | N21: =IF(H21>(100-$C21),(100-$C21),IF(H21<$B21,$B21,H21)) -> 0 | O21: =IF(I21>(100-$C21),(100-$C21),IF(I21<$B21,$B21,I21)) -> 0 | P21: =IF(J21>(100-$C21),(100-$C21),IF(J21<$B21,$B21,J21)) -> 0 | Q21: =IF(K21>(100-$C21),(100-$C21),IF(K21<$B21,$B21,K21)) -> 0 | T21: =AVERAGE(L21:Q21) -> 0 | U21: =100-T21 -> 100 | V21: =SQRT(VARP(L21:Q21)) -> 0 | W21: =IF(R21>0,R21+(100-R21)*T21/100,IF(AND(R21=0,S21=0),T21,100-X21)) -> 0 | X21: =IF(S21>0,S21+(100-S21)*U21/100,IF(AND(R21=0,S21=0),U21,100-W21)) -> 100 | Y21: =W21/(W21+X21) -> 0 | Z21: =D21/MAX(1,D21+E21) -> 0 | AA21: =IF(Z21<>0,ABS(Z21-Y21)/Z21,0) -> 0
L22: =IF(F22>(100-$C22),(100-$C22),IF(F22<$B22,$B22,F22)) -> 0 | M22: =IF(G22>(100-$C22),(100-$C22),IF(G22<$B22,$B22,G22)) -> 0 | N22: =IF(H22>(100-$C22),(100-$C22),IF(H22<$B22,$B22,H22)) -> 0 | O22: =IF(I22>(100-$C22),(100-$C22),IF(I22<$B22,$B22,I22)) -> 0 | P22: =IF(J22>(100-$C22),(100-$C22),IF(J22<$B22,$B22,J22)) -> 0 | Q22: =IF(K22>(100-$C22),(100-$C22),IF(K22<$B22,$B22,K22)) -> 0 | T22: =AVERAGE(L22:Q22) -> 0 | U22: =100-T22 -> 100 | V22: =SQRT(VARP(L22:Q22)) -> 0 | W22: =IF(R22>0,R22+(100-R22)*T22/100,IF(AND(R22=0,S22=0),T22,100-X22)) -> 0 | X22: =IF(S22>0,S22+(100-S22)*U22/100,IF(AND(R22=0,S22=0),U22,100-W22)) -> 100 | Y22: =W22/(W22+X22) -> 0 | Z22: =D22/MAX(1,D22+E22) -> 0 | AA22: =IF(Z22<>0,ABS(Z22-Y22)/Z22,0) -> 0
L23: =IF(F23>(100-$C23),(100-$C23),IF(F23<$B23,$B23,F23)) -> 0 | M23: =IF(G23>(100-$C23),(100-$C23),IF(G23<$B23,$B23,G23)) -> 0 | N23: =IF(H23>(100-$C23),(100-$C23),IF(H23<$B23,$B23,H23)) -> 0 | O23: =IF(I23>(100-$C23),(100-$C23),IF(I23<$B23,$B23,I23)) -> 0 | P23: =IF(J23>(100-$C23),(100-$C23),IF(J23<$B23,$B23,J23)) -> 0 | Q23: =IF(K23>(100-$C23),(100-$C23),IF(K23<$B23,$B23,K23)) -> 0 | T23: =AVERAGE(L23:Q23) -> 0 | U23: =100-T23 -> 100 | V23: =SQRT(VARP(L23:Q23)) -> 0 | W23: =IF(R23>0,R23+(100-R23)*T23/100,IF(AND(R23=0,S23=0),T23,100-X23)) -> 0 | X23: =IF(S23>0,S23+(100-S23)*U23/100,IF(AND(R23=0,S23=0),U23,100-W23)) -> 100 | Y23: =W23/(W23+X23) -> 0 | Z23: =D23/MAX(1,D23+E23) -> 0 | AA23: =IF(Z23<>0,ABS(Z23-Y23)/Z23,0) -> 0
L24: =IF(F24>(100-$C24),(100-$C24),IF(F24<$B24,$B24,F24)) -> 0 | M24: =IF(G24>(100-$C24),(100-$C24),IF(G24<$B24,$B24,G24)) -> 0 | N24: =IF(H24>(100-$C24),(100-$C24),IF(H24<$B24,$B24,H24)) -> 0 | O24: =IF(I24>(100-$C24),(100-$C24),IF(I24<$B24,$B24,I24)) -> 0 | P24: =IF(J24>(100-$C24),(100-$C24),IF(J24<$B24,$B24,J24)) -> 0 | Q24: =IF(K24>(100-$C24),(100-$C24),IF(K24<$B24,$B24,K24)) -> 0 | T24: =AVERAGE(L24:Q24) -> 0 | U24: =100-T24 -> 100 | V24: =SQRT(VARP(L24:Q24)) -> 0 | W24: =IF(R24>0,R24+(100-R24)*T24/100,IF(AND(R24=0,S24=0),T24,100-X24)) -> 0 | X24: =IF(S24>0,S24+(100-S24)*U24/100,IF(AND(R24=0,S24=0),U24,100-W24)) -> 100 | Y24: =W24/(W24+X24) -> 0 | Z24: =D24/MAX(1,D24+E24) -> 0 | AA24: =IF(Z24<>0,ABS(Z24-Y24)/Z24,0) -> 0
L25: =IF(F25>(100-$C25),(100-$C25),IF(F25<$B25,$B25,F25)) -> 0 | M25: =IF(G25>(100-$C25),(100-$C25),IF(G25<$B25,$B25,G25)) -> 0 | N25: =IF(H25>(100-$C25),(100-$C25),IF(H25<$B25,$B25,H25)) -> 0 | O25: =IF(I25>(100-$C25),(100-$C25),IF(I25<$B25,$B25,I25)) -> 0 | P25: =IF(J25>(100-$C25),(100-$C25),IF(J25<$B25,$B25,J25)) -> 0 | Q25: =IF(K25>(100-$C25),(100-$C25),IF(K25<$B25,$B25,K25)) -> 0 | T25: =AVERAGE(L25:Q25) -> 0 | U25: =100-T25 -> 100 | V25: =SQRT(VARP(L25:Q25)) -> 0 | W25: =IF(R25>0,R25+(100-R25)*T25/100,IF(AND(R25=0,S25=0),T25,100-X25)) -> 0 | X25: =IF(S25>0,S25+(100-S25)*U25/100,IF(AND(R25=0,S25=0),U25,100-W25)) -> 100 | Y25: =W25/(W25+X25) -> 0 | Z25: =D25/MAX(1,D25+E25) -> 0 | AA25: =IF(Z25<>0,ABS(Z25-Y25)/Z25,0) -> 0
... L76: =IF(F76>(100-$C76),(100-$C76),IF(F76<$B76,$B76,F76)) -> 0 | M76: =IF(G76>(100-$C76),(100-$C76),IF(G76<$B76,$B76,G76)) -> 0 | N76: =IF(H76>(100-$C76),(100-$C76),IF(H76<$B76,$B76,H76)) -> 0 | O76: =IF(I76>(100-$C76),(100-$C76),IF(I76<$B76,$B76,I76)) -> 0 | P76: =IF(J76>(100-$C76),(100-$C76),IF(J76<$B76,$B76,J76)) -> 0 | Q76: =IF(K76>(100-$C76),(100-$C76),IF(K76<$B76,$B76,K76)) -> 0 | T76: =AVERAGE(L76:Q76) -> 0 | U76: =100-T76 -> 100 | V76: =SQRT(VARP(L76:Q76)) -> 0 | W76: =IF(R76>0,R76+(100-R76)*T76/100,IF(AND(R76=0,S76=0),T76,100-X76)) -> 0 | X76: =IF(S76>0,S76+(100-S76)*U76/100,IF(AND(R76=0,S76=0),U76,100-W76)) -> 100 | Y76: =W76/(W76+X76) -> 0 | Z76: =D76/MAX(1,D76+E76) -> 0 | AA76: =IF(Z76<>0,ABS(Z76-Y76)/Z76,0) -> 0
