Workbook
Name 阵营: 数值参考!$C$3:$C$35

Sheet 说明
A1: 對應規則書︰2.05
A6: 更新记录
A7: 5 | B7: 自动化一部份的属性分配
B8: 加入看上去很酷的属性图
B9: 加入详细的圣遗物介绍
A10: 5.1 | B10: 加入特性(可选规则)用的格子
A11: 5.11 | B11: 只是加了一個職階技能的格子，方便特殊職階車卡。拜託普通職階不要填
A12: 5.2 | B12: 將特性這不會暴露，暴露後易被針對的效果移至角色卡下方，以便GM處理情報
B13: 為特性提供了實驗性質的效果槽，是否啟用自行向GM查詢
A14: 5.22 | B14: Berserker的基礎屬性調整，1.79以下的版本的參加者請注意
A15: 5.31 | B15: 六維圖修了修
B16: 技能效果多加了一行，讓說明有點複雜的技能不用整天拉長行數。但是說明超長的依然要拉長行數
A17: 5.4 | B17: 其實什麼都沒動，但為了對稱所以再發一版~
A18: 5.5 | B18: 這回真的有更動!寶具/技能的名稱格子長了!
B19: 遺物介紹的格子微調了
B20: 特性由原來的範例，改成一些針對性的問題，寫特性時請將這些問題納入考慮
B21: Avenger的基礎屬性確立，2.03以下的版本注意
B22: 雖然很丟人，但之前一直將貼圖鎖了....現在不解除保護也能貼圖了
B23: Lancer的基础属性调整，2.05以下的版本注意
A24: 6.0 | B24: 角色的屬性改成橫的，方便填表時右鍵
B25: 角色頭像可以放更大的了
B26: 陣營的位置改放到「角色經歷」
B27: 調整了一下排版，如無意外角卡可以用A4size印出來了
A28: 6.01 | B28: 有些排版出包了，調整完成。
A29: GM开团前「可」准备的事
A34: 在数值参考页面按自己特有的村规进行基础属性、点数的调整。或加入新职阶
A48: 本角色卡是为圣杯战争跑团准备的战斗计算表。
A49: 该圣杯战争跑团规则大部分采用了日本现在较流行的男爵圣杯规则作为基底，进行魔改的TRPG规则，在游戏上简约了战斗部分，以实际扮演为主体的游戏方式。
A51: 若有疑问可加群424815329查询

Sheet 角色卡 
C1: =C16+C17 -> 40 | D1: =D16+D17 -> 30 | E1: =E16+E17 -> 30 | F1: =F16+F17 -> 20 | G1: =G16+G17 -> 30 | H1: =H16+H17 -> 80 | I1: =I16+I17 -> 50
B2: 阵营 | E2: 外貌描述 | H2: 肖像 | K2: 资源上限 | L2: 特攻列表
B3: =角色经历!B15 -> 秩序-善 | H3: =_xlfn.DISPIMG("ID_BC849194706D4E2C8A2F9EFFA2DC9407",1) -> =DISPIMG("ID_BC849194706D4E2C8A2F9EFFA2DC9407",1) | K3: =24+K15 -> 29 | L3: 职阶 | N3: =F9 -> Shielder
L4: 灵基 | N4: =F10 -> 幻灵
B5: 令咒 | K5: 剩余资源 | L5: 阵营 | N5: =角色经历!B15 -> 秩序-善
K6: =K3-IF(J18>0,K9,K9-J18/20) -> 0 | L6: 特性 | N6: =F11 -> 人型 | O6: =G11 -> 0
N7: =F12 -> 0 | O7: =G12 -> 0
K8: 花费资源 | L8: 时代 | N8: 过去
E9: 职阶 | F9: Shielder | K9: =J20+J29+J38+J48+J57+J66+T20+T29+T38+T48+T57+T66+K12 -> 29 | L9: 隐属 | N9: 地属性
E10: 灵基 | F10: 幻灵 | L10: 性别 | N10: =角色经历!C27 -> 女
E11: 特性 | F11: 人型 | K11: 扩容 | L11: 体型 | N11: =F13 -> 通常
K12: =H20+H29+H38+H48+H57+H66+R20+R29+R38+R48+R57+R66 -> 2 | L12: 注释
E13: 体型 | F13: 通常 | L13: 特攻列表不会也不能为其他角色所获取。
C14: 等级 | D14: 筋力 | E14: 耐久 | F14: 敏捷 | G14: 魔力 | H14: 幸运 | I14: 宝具 | J14: 属性点数 | K14: RP补正
B15: 合计 | C15: =C16+C17+C18 -> 40 | D15: =D16+D17+D18 -> 30 | E15: =E16+E17+E18 -> 30 | F15: =F16+F17+F18 -> 20 | G15: =G16+G17+G18 -> 30 | H15: =H16+H17+H18 -> 80 | I15: =I16+I17+I18 -> 50 | J15: =40+C17*2 -> 120 | K15: 5
B16: 职阶 | D16: =VLOOKUP(F9,调卡用表!$B$4:$G$13,2,0) -> 20 | E16: =VLOOKUP(F9,调卡用表!$B$4:$G$13,3,0) -> 20 | F16: =VLOOKUP(F9,调卡用表!$B$4:$G$13,4,0) -> 0 | G16: =VLOOKUP(F9,调卡用表!$B$4:$G$13,5,0) -> 10 | H16: =VLOOKUP(F9,调卡用表!$B$4:$G$13,6,0) -> 20 | I16: 0 | J16: =SUM(C16:I16) -> 70
B17: 分配 | C17: 40 | D17: 10 | E17: 10 | F17: 20 | G17: 20 | H17: 60 | I17: 50 | J17: 剩余点数 | K17: 基础上限
B18: 补正 | J18: =J15-D17-E17-F17-G17-H17 -> 0 | K18: 60
B19: 职阶技能 | L19: 宝具
B20: 模板 | C20: 己阵防御 | E20: 等级 | F20: E级(本职) | G20: 扩容 | I20: 资源 | J20: =_xlfn.IFNA(VLOOKUP(F20,数值参考!$J$23:$K$38,2,FALSE),0) -> 0 | L20: 模板 | M20: 吾将远征，鹦鹉螺的大冲角 | O20: 等级 | P20: B级 | Q20: 扩容 | S20: 资源 | T20: =_xlfn.IFNA(VLOOKUP(P20,调卡用表!$M$4:$N$33,2,0),0) -> 4
B21: 名称 | C21: 溟海引航 | E21: 类型 | F21: 职阶 | H21: 回转 | I21: 6点 | J21: 6点 | L21: 名称 | M21: 沉默于远海，诺第留斯号的守望 | O21: 类型 | P21: 对人宝具 | R21: 回转 | S21: 0点 | T21: 0点
E22: 发动时机 | F22: 战斗开始时 | H22: 魔力消耗 | I22: 0点 | J22: =IF(F22="常驻","每日","每次") -> 每次 | O22: 发动时机 | P22: 常驻 | R22: 魔力消耗 | S22: 20点 | T22: =IF(P22="常驻","每日","每次") -> 每日
B23: 效果 | C23: 赋予己方战斗位中除自身外的至多[1]名单位单位[保护]，记录通过[保护]的效果转移到自身的惩罚，根据记录的的惩罚值减少至多[10]点的自身受到的惩罚，此效果仅会影响受到记录的惩罚。 | L23: 效果 | M23: [主力位][骑乘] 自身获得[抗性无效：恐惧]，仅能对敌方[主力位]进行[冲锋] 此宝具根据自身在本场战斗中进行的最后1次[冲锋]结果产生效果： 1.自身[冲锋]失败时，移除双方[主力位]等级带来的胜率，并赋予敌方[主力位][-等同于其等级%]的胜率惩罚，此胜率惩罚至多=[-40%]。 2.自身[冲锋]成功时，若目标等级高于自身则赋予目标[-20%]的胜率惩罚，在主要工序开始时，[战斗属性]中每存在1项[劣势]则使此胜率惩罚的数值提升[20%]。 注.若[冲锋目标[筋力][耐久][敏捷]3项属性的总值≥270]或具有[巨大]特性则本场战斗中自身额外获得[无敌贯通]。
B26: 背景 | C26: |海, 黑洞般幽邃，诺第留斯号正向更深处行驶着。-驶向深海、驶向绝望。 恐惧、谵妄、死......将被这片死寂吞没。 |领航旗帜残破鲜红， 她立于船头:「我必会将船只， 引领向正确的航向。」一驶向深海、 驶向希望。 崭新的航向!伟大神国绝非幻梦！ | L26: 背景 | M26: 这是本该是一场充满欢笑的航行， 豪华的游轮横渡大西洋，载着战利品，载着人们征服海洋的野望。但海洋有自己的脾气，在远超理解的恐怖与未知面前，人类，终究渺小如蝼蚁！ 诺第留斯号 ，她的第一艘船，也是最后一艘船 12岁上船，16岁开始学习引航知识，22岁正式接手诺第留斯号 在绝望的黑暗中 诺第留斯号最终会沉默，所有人都将葬身于无光的海底，这是结局 但，只要她还在这艘船上，他就还是领航员 哪怕诺第留斯号成为幽灵船，哪怕自身也早已沉没于海底，自身依旧守望着这艘船，直至永远
B29: 模板 | E29: 等级 | G29: 扩容 | I29: 资源 | J29: =_xlfn.IFNA(VLOOKUP(F29,数值参考!$J$23:$K$38,2,FALSE),0) -> 0 | L29: 模板 | M29: 恶龙之血凯 | O29: 等级 | P29: A级 | Q29: 扩容 | R29: 2 | S29: 资源 | T29: =_xlfn.IFNA(VLOOKUP(P29,调卡用表!$M$4:$N$33,2,0),0) -> 5
B30: 名称 | E30: 类型 | H30: 回转 | L30: 名称 | M30: 钥令—不灭的雷光 | O30: 类型 | P30: 对人宝具 | R30: 回转 | S30: 0点 | T30: 0点
E31: 发动时机 | H31: 魔力消耗 | J31: =IF(F31="常驻","每日","每次") -> 每次 | O31: 发动时机 | P31: 常驻 | R31: 魔力消耗 | S31: 25点 | T31: =IF(P31="常驻","每日","每次") -> 每日
B32: 效果 | L32: 效果 | M32: 自身常驻获得[特性赋予：龙种] 建卡时，破除自身保有的[对魔力]，因此效果破除技能时自身额外获得[1]点RP； 当自身被选作敌方单位的技能或宝具的效果目标或受到其效果影响时，令此技能或宝具的效果对自身下降[4]级，若因此宝具导致其效果等级降低，但其效果未存在相应模板时使用最低等级生效，若其效果等级降低至不足[E]级则令其无效化，且不会返还发动消耗。 注.若敌方战斗位中的单位知悉自身的[真名]或曾对自身发起成功的[资料分析]，则此宝具对其自阵营单位的技能和宝具产生的效果下降[1]级。 注.若敌方战斗位中的任意单位保有[屠龙]技能，则此宝具暂时失效。
B35: 背景 | L35: 背景 | M35: 燃烧，燃烧，燃烧。 哪怕骨血已沸腾，哪怕皮肉已焦糊，也要榨干身体里的最后一滴血夜，绽放光明。 因为这黑暗中，我是唯一的指引。
B38: 模板 | E38: 等级 | G38: 扩容 | I38: 资源 | J38: =_xlfn.IFNA(VLOOKUP(F38,数值参考!$J$23:$K$38,2,FALSE),0) -> 0 | L38: 模板 | O38: 等级 | Q38: 扩容 | S38: 资源 | T38: =_xlfn.IFNA(VLOOKUP(P38,调卡用表!$M$4:$N$33,2,0),0) -> 0
B39: 名称 | E39: 类型 | H39: 回转 | L39: 名称 | O39: 类型 | R39: 回转
E40: 发动时机 | H40: 魔力消耗 | O40: 发动时机 | R40: 魔力消耗 | T40: =IF(P40="常驻","每日","每次") -> 每次
B41: 效果 | L41: 效果
B44: 背景 | L44: 背景
B47: 保有技能 | L47: 礼装
B48: 模板 | C48: 王途踏破 | E48: 等级 | F48: EX级 | G48: 扩容 | I48: 资源 | J48: =_xlfn.IFNA(VLOOKUP(F48,调卡用表!$J$4:$K$33,2,0),0) -> 7 | L48: 模板 | O48: 等级 | P48: / | Q48: 扩容 | S48: 资源
B49: 名称 | C49: 圣火的引航 | E49: 类型 | F49: 荣冠 | H49: 回转 | I49: 0点 | J49: 0点 | L49: 名称 | O49: 类型 | R49: 回转
E50: 发动时机 | F50: 常驻 | H50: 魔力消耗 | I50: 0点 | J50: =IF(F50="常驻","每日","每次") -> 每日 | O50: 发动时机 | R50: 魔力消耗
B51: 效果 | C51: 建卡时选择[6]项特质记录： 1.无法进行[魂食]，在发生[魂食暴露]时必须[介入]并[袭击]魂食单位，且与[混沌恶]单位发生[交流]时会立刻知悉并对敌方宣言[袭击]； 2.全部战斗工序中必须解放符合时机且不处于回转的自身宝具，且无法在敌方解放宝具的工序内宣言撤退； 3.无法对[女性]单位宣言袭击，且无法介入袭击方参与到与敌方的战斗中； 4.无法破弃任何契约，进行语言类角色扮演时全部发言必须从在角色视角为真； 5.无法对未参战单位宣言[冲锋]，若敌方[主力位]首次与自身战斗则无法宣言[死斗]； 6.仅能宣言[破袭]或[强击]作为战术，且在最终胜率未=[0%]时无法在最终工序内撤退； 自身处于主力位时获得[+记录特质数*15%]的胜率补正，若自身未违背任意特质则额外获得[+15%]的胜率补正。 注.自身违背生效特质时，移除对应记录。 | L51: 效果 | M51: （建卡时，从者无法持有礼装）
B54: 背景 | C54: 「 我们用凡俗的铜与铁，丈量星辰的轨迹，但无尽的深渊有自己的算法，阴晴不定。 逐渐沉没的游轮里，克珀珊特吟诵起《领航员挽歌》 她早已知晓自己的命运，也早已选择自己的命运，因此对面死亡，她没有恐惧，只有平静 平静地燃烧，平静地完成最后一次的领航。 但焚烧的火光太过炽热，她看不见前路，发不出声音，也无法挥舞旗帜，这样残缺的指引下，船只是否能够正确航行? 她不知道，并因此产生出恐惧与忧虑。 这时《领航员挽歌》给出了指引:「年轻的领航员啊，你终将被咸水拥入怀中，化为引路的磷火。 引路的磷火?克珀珊特沉默。姚确实听闻过在水手间流传的圣艾尔摩之火的故事，然而区区凡人之躯，如何化为照亮人世的圣火? 但即便希望渺茫，克珀珊特也在内心中不断祈求:祈求自己能够履行职责，完成最后的指引工作。 除了克珀珊特自己，没有人能够听到这祈求，但这已经足够了 黑暗中，银芯以融蚀浆为养料，迸发出强烈的光芒，实现了她最后的心愿。 「潮汐黑册将记载你的名讳，令咆哮的怒涛为你奏响永恒的安魂曲。 她最终如《领航员挽歌》所言，死亡于大海 但她又超越了《领航员挽歌》。那是人类领航员面对大海时的狂妄与劝诚，而如今，她已成为圣艾尔摩之火，永恒指引船只。 | L54: 背景
...

Sheet 角色经历
B2: 最能代表角色的一句话: | L2: 角色之核心人設
B3: “海员们，跟随我的指引，我们一定会安全到达海港！″ | L3: 船长啊，虽然是引航员 但是一般玩家都叫船长，人设就是人机，外带职责所内我必须得干... 就有一种很人机的感觉，就是只要是自己的职责 无论权利与义务都会在自己的职责之内必须得完成 因此在角色上我选择了王途踏破，用以体现遵守规则这一点，然后本身是引航员，但是根据目前的剧情完全不知道他左手和胸前是怎么个回事儿 想解释也解释不了... 然后这个角色的船只设计是以海底两万里的鹦鹉螺号为原型，但是由于翻译问题翻译成了诺弟留斯号。
B6: 职阶 | C6: 灵基 | D6: 等级 | E6: 筋力 | F6: 耐力 | G6: 敏捷 | H6: 魔力 | I6: 幸运 | J6: 宝具
B7: ='角色卡 '!F9 -> Shielder | C7: 英灵 | D7: ='角色卡 '!C15 -> 40 | E7: =_xlfn.IFS('角色卡 '!$D$15<21,"E",'角色卡 '!$D$15<41,"D",'角色卡 '!$D$15<61,"C",'角色卡 '!$D$15<81,"B",'角色卡 '!$D$15<101,"A",'角色卡 '!$D$15<121,"A+",'角色卡 '!$D$15>120,"EX") -> D | F7: =_xlfn.IFS('角色卡 '!$E$15<21,"E",'角色卡 '!$E$15<41,"D",'角色卡 '!$E$15<61,"C",'角色卡 '!$E$15<81,"B",'角色卡 '!$E$15<101,"A",'角色卡 '!$E$15<121,"A+",'角色卡 '!$E$15>120,"EX") -> D | G7: =_xlfn.IFS('角色卡 '!$F$15<21,"E",'角色卡 '!$F$15<41,"D",'角色卡 '!$F$15<61,"C",'角色卡 '!$F$15<81,"B",'角色卡 '!$F$15<101,"A",'角色卡 '!$F$15<121,"A+",'角色卡 '!$F$15>120,"EX") -> E | H7: =_xlfn.IFS('角色卡 '!$G$15<21,"E",'角色卡 '!$G$15<41,"D",'角色卡 '!$G$15<61,"C",'角色卡 '!$G$15<81,"B",'角色卡 '!$G$15<101,"A",'角色卡 '!$G$15<121,"A+",'角色卡 '!$G$15>120,"EX") -> D | I7: =_xlfn.IFS('角色卡 '!$H$15<21,"E",'角色卡 '!$H$15<41,"D",'角色卡 '!$H$15<61,"C",'角色卡 '!$H$15<81,"B",'角色卡 '!$H$15<101,"A",'角色卡 '!$H$15<121,"A+",'角色卡 '!$H$15>120,"EX") -> B | J7: =_xlfn.IFS('角色卡 '!$I$15<11,"E",'角色卡 '!$I$15<21,"D",'角色卡 '!$I$15<31,"C",'角色卡 '!$I$15<41,"B",'角色卡 '!$I$15<51,"A",'角色卡 '!$I$15<56,"A+",'角色卡 '!$I$15>55,"EX") -> A
B8: 性别 | C8: =C27 -> 女 | E8: 样貌特点
B9: 身高 | C9: 175.26㎝ | E9: 蓝发，过膝长袜，左手化为雷光，胸前有一部分血肉被雷光所覆盖，头顶船长帽。
B10: 体重 | C10: 65.77㎏
B11: 玩家 | E11: 喜好事物
B12: 神奇的天海 | E12: 比起喜欢，更喜欢用皈依这个词，当直视那不可名状的神明时，大脑失去理智陷入狂喜，是的，该恐惧，但是无法控制自己。
B14: 阵营 | E14: 厌恶事物
B15: 秩序-善 | E15: 混乱与混乱
E17: 圣遗物评级
E18: Euclid
E19: 名称
E21: 地域
E22: 年代
E23: 外观
E24: 出产地点
B25: 真名 | C25: 克珀珊特 | E25: 英灵愿望 | L25: 你希望拥有怎样的御主？在什么情况下你可能会违背御主的命令？
B26: 职业 | C26: 引航员 | E26: 只要神国降临，世间一切都将变为乐土 | L26: 对于御主只有尊重，并且会誓死完成所下达的所有命令，不会违背意愿。
B27: 性别 | C27: 女
B28: 国家 | C28: 英国
B29: 信仰 | C29: 图鲁 | L29: 你在战斗中会以怎样的姿态面对你的对手？
B30: 典出 | C30: 《忘却前夜》 | L30: 不会主动袭击，因为这不在自己的职责所在之内，但倘若对方主动袭击或伤害自己的“水手″那么自己也只能被迫应战 。
B31: 角色资料
B32: 诺第留斯号唯一幸存者/沉沦者 他生前将以自身之性命将整艘船运送归岸，但就此之后他与整艘诺地留斯号便成为幽灵船驻守在大西洋的海底。
L33: 你认为友谊是什么？你愿意把后背托付给怎么样的战友？
L34: 她的眼中只有命令与职责，做好自己该做的事情
L37: 此空白留给GM为了更好理解你扮演的角色而给出询问
B40: 职阶适性
B41: 防御型唤醒体，且角色背景为引航员，守护着整个船员的安全。 | L41: 此空白留给GM为了更好理解你扮演的角色而给出询问
B44: 英灵原则
B45: 她的责任，她的义务，她的生命都与船只绑定，除此之外，别无他物 因此，指引航向，就是它存在的意义 | L45: 此空白留给GM为了更好理解你扮演的角色而给出询问
B49: 下方的效果将严重影响角色方针，请自行填写描述，由GM决定具体效果
B50: 特性: | C50: 职责所在
B51: 效果︰ | C51: 当自身未违背特质时，额外获得[抗性上升：+15%]； 当技能[王途踏破]记录的特质产生矛盾时，自身可消耗[30]点魔力令本场战斗中不会违背记录的特质。
B52: 描述︰ | C52: 不畏惧暴力，不畏惧霸权，自然也不会畏惧职责所在 是在职责所在之内的事情自己就会完成，不是职责所在之事自身便不会过多干涉。

Sheet 调卡用表
B3: 职阶名称 | C3: 筋力 | D3: 耐久 | E3: 敏捷 | F3: 魔力 | G3: 幸运 | J3: 技能等级 | K3: 对应RP | M3: 宝具等级 | N3: 对应RP
B4: Saber | C4: 20 | D4: 20 | E4: 20 | F4: 10 | G4: 20 | J4: E级 | K4: 1 | M4: E级 | N4: 1
B5: Saber(骑乘) | C5: 20 | D5: 30 | E5: 20 | F5: 10 | G5: 20 | J5: D级 | K5: 2 | M5: D级 | N5: 2
B6: Lancer | C6: 10 | D6: 10 | E6: 30 | F6: 10 | G6: 10 | J6: C级 | K6: 3 | M6: C级 | N6: 3
B7: Rider | C7: 0 | D7: 30 | E7: 0 | F7: 0 | G7: 20 | J7: B级 | K7: 4 | M7: B级 | N7: 4
B8: Archer | C8: 10 | D8: 10 | E8: 10 | F8: 0 | G8: 20 | J8: A级 | K8: 5 | M8: A级 | N8: 5
B9: Caster | C9: 0 | D9: 0 | E9: 0 | F9: 30 | G9: 0 | J9: EX级 | K9: 7 | M9: EX级 | N9: 9
B10: Assassin | C10: 0 | D10: 0 | E10: 20 | F10: 0 | G10: 20 | J10: - [视为E级] | K10: 1 | M10: - [视为E级] | N10: 1
B11: Berserker | C11: 20 | D11: 20 | E11: 20 | F11: 0 | G11: 0 | J11: - [视为D级] | K11: 2 | M11: - [视为D级] | N11: 2
B12: Shielder | C12: 20 | D12: 20 | E12: 0 | F12: 10 | G12: 20 | J12: - [视为C级] | K12: 3 | M12: - [视为C级] | N12: 3
C13: 0 | D13: 0 | E13: 0 | F13: 0 | G13: 0 | J13: - [视为B级] | K13: 4 | M13: - [视为B级] | N13: 4
J14: - [视为A级] | K14: 5 | M14: - [视为A级] | N14: 5
J15: - [视为EX级] | K15: 7 | M15: - [视为EX级] | N15: 9
J16: E+级 | K16: 3 | M16: E+级 | N16: 3
J17: D+级 | K17: 4 | M17: D+级 | N17: 4
J18: C+级 | K18: 5 | M18: C+级 | N18: 5
J19: B+级 | K19: 6 | M19: B+级 | N19: 6
J20: A+级 | K20: 7 | M20: A+级 | N20: 7
J21: E++级 | K21: 5 | M21: E++级 | N21: 5
J22: D++级 | K22: 6 | M22: D++级 | N22: 6
J23: C++级 | K23: 7 | M23: C++级 | N23: 7
J24: B++级 | K24: 8 | M24: B++级 | N24: 8
J25: A++级 | K25: 9 | M25: A++级 | N25: 9
... J30: A+++级 | K30: 11 | M30: A+++级 | N30: 11

Sheet 数值参考
A2: 从者等级 | B2: 分配点数 | C2: 特性
A3: 40 | B3: 100 | C3: 秩序·善
A4: 50 | B4: 120 | C4: 中立·善
A5: 60 | B5: 140 | C5: 混沌·善
A6: 70 | B6: 160 | C6: 秩序·中立
A7: 空 | B7: 0 | C7: 中立·中庸
A8: 空 | B8: 0 | C8: 混沌·中立
A9: 空 | B9: 0 | C9: 秩序·恶
C10: 中立·恶
C11: 混沌·恶
C12: 秩序·狂
C13: 中立·狂
C14: 混沌·狂
C15: 空
C16: 空
C17: 空
C18: 空
C19: 空
C20: 空
C21: 空
C22: 空 | F22: 技能等级 | H22: 宝具等级 | J22: 职阶技能等级
C23: 空 | F23: EX | G23: 7 | H23: EX | I23: 9 | J23: A+级(本职) | K23: 6
C24: 空 | F24: A++++ | G24: 5 | J24: A级(本职) | K24: 4
C25: 空 | F25: A+ | G25: 7 | H25: A+ | I25: 7 | J25: A+级 | K25: 7
C26: 空 | F26: A | G26: 5 | H26: A | I26: 5 | J26: A级 | K26: 5
C27: 空 | F27: - [视为A级] | G27: 5 | H27: - [视为A级] | I27: 5 | J27: B级(本职) | K27: 3
C28: 空 | F28: B+ | G28: 6 | H28: B+ | I28: 6 | J28: B+级 | K28: 6
C29: 空 | F29: B | G29: 4 | H29: B | I29: 4 | J29: B级 | K29: 4
C30: 空 | F30: - [视为B级] | G30: 4 | H30: - [视为B级] | I30: 4 | J30: C级(本职) | K30: 2
C31: 空 | F31: C+ | G31: 5 | H31: C+ | I31: 5 | J31: C+级 | K31: 5
C32: 空 | F32: C | G32: 3 | H32: C | I32: 3 | J32: C级 | K32: 3
C33: 空 | F33: - [视为C级] | G33: 3 | H33: - [视为C级] | I33: 3 | J33: D级(本职) | K33: 1
C34: 空 | F34: D+ | G34: 4 | H34: D+ | I34: 4 | J34: D+级 | K34: 4
C35: 空 | F35: D | G35: 2 | H35: D | I35: 2 | J35: D级 | K35: 2
J36: E级(本职) | K36: 0
F37: E+ | G37: 3 | H37: E+ | I37: 3 | J37: E+级 | K37: 3
F38: E | G38: 1 | H38: E | I38: 1 | J38: E级 | K38: 1
