Workbook
Name 阵营: 數值參考!$C$3:$C$35

Sheet 说明
A1: 對應規則書︰2.05
A6: 更新记录
A7: 5 | B7: 自动化一部份的属性分配
B8: 加入看上去很酷的属性图
B9: 加入详细的圣遗物介绍
A10: 5.1 | B10: 加入特性(可选规则)用的格子
A11: 5.11 | B11: 只是加了一個職階技能的格子，方便特殊職階車卡。拜託普通職階不要填
A12: 5.2 | B12: 將特性這不會暴露，暴露後易被針對的效果移至角色卡下方，以便GM處理情報
B13: 為特性提供了實驗性質的效果槽，是否啟用自行向GM查詢
A14: 5.22 | B14: Berserker的基礎屬性調整，1.79以下的版本的參加者請注意
A15: 5.31 | B15: 六維圖修了修
B16: 技能效果多加了一行，讓說明有點複雜的技能不用整天拉長行數。但是說明超長的依然要拉長行數
A17: 5.4 | B17: 其實什麼都沒動，但為了對稱所以再發一版~
A18: 5.5 | B18: 這回真的有更動!寶具/技能的名稱格子長了!
B19: 遺物介紹的格子微調了
B20: 特性由原來的範例，改成一些針對性的問題，寫特性時請將這些問題納入考慮
B21: Avenger的基礎屬性確立，2.03以下的版本注意
B22: 雖然很丟人，但之前一直將貼圖鎖了....現在不解除保護也能貼圖了
B23: Lancer的基础属性调整，2.05以下的版本注意
A24: 6.0 | B24: 角色的屬性改成橫的，方便填表時右鍵
B25: 角色頭像可以放更大的了
B26: 陣營的位置改放到「角色經歷」
B27: 調整了一下排版，如無意外角卡可以用A4size印出來了
A28: 6.01 | B28: 有些排版出包了，調整完成。
A29: GM开团前「可」准备的事
A34: 在数值参考页面按自己特有的村规进行基础属性、点数的调整。或加入新职阶
A48: 本角色卡是为圣杯战争跑团准备的战斗计算表。
A49: 该圣杯战争跑团规则大部分采用了日本现在较流行的男爵圣杯规则作为基底，进行魔改的TRPG规则，在游戏上简约了战斗部分，以实际扮演为主体的游戏方式。
A51: 若有疑问可加群424815329查询

Sheet 角色卡 
C1: =C16+C17 -> 70 | D1: =D16+D17 -> 55 | E1: =E16+E17 -> 45 | F1: =F16+F17 -> 80 | G1: =G16+G17 -> 40 | H1: =H16+H17 -> 50 | I1: =I16+I17 -> 40
B2: 阵营 | E2: 外貌描述 | H2: 肖像 | K2: 资源上限 | L2: 特攻列表 | Q2: 职阶特性
B3: =角色經歷!B15 -> 秩序-善 | E3: （简单的外貌描述） | H3: （立绘） | K3: =24+K15 -> 27 | L3: 职阶 | N3: =F9 -> Saber（职阶2） | Q3: =VLOOKUP(F9,调卡用表!P3:Q19,2,0) -> 建卡时，放弃职阶技能[骑乘]和[10]点[耐久]职阶属性，获得额外的[+2]RP点。
L4: 灵基 | N4: =F10 -> 英灵
B5: 令咒 | K5: 剩余资源 | L5: 阵营 | N5: =角色經歷!B15 -> 秩序-善
B6: （此区域从者通常不需要使用） | K6: =K3-IF(J18>0,K9,K9-J18/20) -> 0 | L6: 特性 | N6: =F11 -> 人型 | O6: =G11 -> 0
N7: =F12 -> 0 | O7: =G12 -> 0
K8: 花费资源 | L8: 时代 | N8: 过去
E9: 职阶 | F9: Saber（职阶2） | K9: =J20+J29+J38+J48+J57+J66+T20+T29+T38+T48+T57+T66+K12 -> 27 | L9: 隐属 | N9: 地 | Q9: 职阶特性
E10: 灵基 | F10: 英灵 | L10: 性别 | N10: =角色經歷!C27 -> 男
E11: 特性 | F11: 人型 | K11: 扩容 | L11: 体型 | N11: =F13 -> 通常
K12: =H20+H29+H38+H48+H57+H66+R20+R29+R38+R48+R57+R66 -> 2 | L12: 注释
E13: 体型 | F13: 通常 | L13: 特攻列表不会也不能为其他角色所获取。
C14: 等级 | D14: 筋力 | E14: 耐久 | F14: 敏捷 | G14: 魔力 | H14: 幸运 | I14: 宝具 | J14: 属性点数 | K14: RP补正
B15: 合计 | C15: =C16+C17+C18 -> 70 | D15: =D16+D17+D18 -> 55 | E15: =E16+E17+E18 -> 45 | F15: =F16+F17+F18 -> 80 | G15: =G16+G17+G18 -> 40 | H15: =H16+H17+H18 -> 40 | I15: =I16+I17+I18 -> 60 | J15: =40+C17*2 -> 180 | K15: 3
B16: 职阶 | D16: =VLOOKUP(F9,调卡用表!B3:H19,2,0) -> 20 | E16: =VLOOKUP(F9,调卡用表!B3:H19,3,0) -> 10 | F16: =VLOOKUP(F9,调卡用表!B3:H19,4,0) -> 20 | G16: =VLOOKUP(F9,调卡用表!B3:G19,5,0) -> 20 | H16: =VLOOKUP(F9,调卡用表!B3:H19,6,0) -> 20 | J16: =SUM(C16:I16) -> 90
B17: 分配 | C17: 70 | D17: 35 | E17: 35 | F17: 60 | G17: 20 | H17: 30 | I17: 40 | J17: 剩余点数 | K17: 基础上限
B18: 补正 | H18: -10 | I18: 20 | J18: =J15-D17-E17-F17-G17-H17 -> 0 | K18: 60
B19: 职阶技能 | L19: 宝具
B20: 模板 | C20: 对魔力 | E20: 等级 | F20: E(本职) | G20: 扩容 | I20: 资源 | J20: =_xlfn.IFNA(VLOOKUP(F20,數值參考!$J$23:$K$38,2,FALSE),0) -> 0 | L20: 模板 | M20: 无明三段突 | O20: 等级 | P20: A | Q20: 扩容 | S20: 资源 | T20: =_xlfn.IFNA(VLOOKUP(P20,调卡用表!$M$4:$N$33,2,0),0) -> 5
B21: 名称 | C21: 对 魔力 | E21: 类型 | F21: 职阶 | H21: 回转 | I21: 0 | L21: 名称 | M21: 答辨三连 | O21: 类型 | P21: 对人魔剑 | R21: 回转 | S21: 3
E22: 发动时机 | F22: 常柱 | H22: 魔力消耗 | I22: 0 | J22: =IF(F22="常驻","每日","每次") -> 每次 | O22: 发动时机 | P22: 随时 | R22: 魔力消耗 | S22: 10 | T22: =IF(P22="常驻","每日","每次") -> 每次
B23: 效果 | C23: 令自身受到的，来源于技能和宝具的负面判定受到[-10%]的基础成功率惩罚。 若受到此技能效果影响的[类型：魔术]技能未能对自身造成效果，给予自身[+10%]胜率补正。 当自身成为不来源自身的[类型：魔术]技能的效果对象时，允许宣言令其对自身的效果下降 [-]级。 若因此技能而导致其效果等级降低，但其效果不存在相应模板时，将以其效果最低等级生效； 若其效果等级降低至低于E级，则使之无效化，且不会返还发动消耗。 | L23: 效果 | M23: [主力位] 令敌方主力位受到三次成功率=[80%]的负面判定（视为[即死]判定），若目标[敏捷]属性不小于 [40]，则这个判定的成功率减半。 每个成功的判定，都将令目标[筋力][耐久][敏捷]三项属性中一项属性受到[-20]的属性惩罚，若 目标对应属性存在补正，则这个属性惩罚减半； 若本次解放中，此宝具判定成功数达到[3]，则额外对目标造成一次[即死]效果，若不消耗一枚令 咒抵消，则立即退场。每场战斗中，此效果仅会在此宝具首次生效时生效。 解放此宝具后，给予自身[迟滞 1]。
B26: 背景 | C26: 作为职阶而获得 | L26: 背景 | M26: 连续三道的踏足反击
B29: 模板 | E29: 等级 | G29: 扩容 | I29: 资源 | J29: =_xlfn.IFNA(VLOOKUP(F29,數值參考!$J$23:$K$38,2,FALSE),0) -> 0 | L29: 模板 | M29: 源流斗争 | O29: 等级 | P29: B | Q29: 扩容 | R29: 2 | S29: 资源 | T29: =_xlfn.IFNA(VLOOKUP(P29,调卡用表!$M$4:$N$33,2,0),0) -> 4
B30: 名称 | E30: 类型 | H30: 回转 | I30: 0 | L30: 名称 | M30: 一斩，足矣 | O30: 类型 | P30: 对人 | R30: 回转 | S30: 12
E31: 发动时机 | H31: 魔力消耗 | I31: 0 | J31: =IF(F31="常驻","每日","每次") -> 每次 | O31: 发动时机 | P31: 最终工序 | R31: 魔力消耗 | S31: 50 | T31: =IF(P31="常驻","每日","每次") -> 每次
B32: 效果 | L32: 效果 | M32: [主力位][必中][无敌贯通] 宣言一项属性，给予敌方主力位[-宣言属性差%]的胜率惩罚；若双方战斗位上仅主力位存在单 位，则令此宝具带来的胜率惩罚翻倍；此宝具带来的胜率惩罚至多为[-100%]。
B35: 背景 | L35: 背景 | M35: 将手中的力气用于最后一段 ，凭借这最后一斩就够了
B38: 模板 | E38: 等级 | G38: 扩容 | I38: 资源 | J38: =_xlfn.IFNA(VLOOKUP(F38,數值參考!$J$23:$K$38,2,FALSE),0) -> 0 | L38: 模板 | O38: 等级 | Q38: 扩容 | S38: 资源 | T38: =_xlfn.IFNA(VLOOKUP(P38,调卡用表!$M$4:$N$33,2,0),0) -> 0
B39: 名称 | E39: 类型 | H39: 回转 | L39: 名称 | O39: 类型 | R39: 回转
E40: 发动时机 | H40: 魔力消耗 | O40: 发动时机 | R40: 魔力消耗 | T40: =IF(P40="常驻","每日","每次") -> 每次
B41: 效果 | L41: 效果
B44: 背景 | L44: 背景
B47: 保有技能 | L47: 额外栏位
B48: 模板 | C48: 无辜的怪物 | E48: 等级 | F48: EX | G48: 扩容 | I48: 资源 | J48: =_xlfn.IFNA(VLOOKUP(F48,调卡用表!$J$4:$K$33,2,0),0) -> 7 | L48: 模板 | M48: 绝招 | O48: 等级 | P48: A | Q48: 扩容 | S48: 资源
B49: 名称 | C49: 无辜的他 | E49: 类型 | F49: 祝福 | H49: 回转 | I49: 0 | L49: 名称 | O49: 类型 | P49: 技艺 | R49: 回转 | S49: 12
E50: 发动时机 | F50: 常柱 | H50: 魔力消耗 | I50: 0 | J50: =IF(F50="常驻","每日","每次") -> 每次 | O50: 发动时机 | P50: 随时 | R50: 魔力消耗 | S50: 0
B51: 效果 | C51: 2、始终给予自身[幸运]属性[-10]的常驻惩罚、除[幸运]外任一属性[+20]的常驻补正； 3、自身发起的所有判定、以及自身受到的负面判定获得[+20%]的基础成功率补正； 6、以与此技能等级相同的模板获取自身未持有面向的任一从者保有技能置于此技能下，始终给 予自身[抗性破除]以及[抗性下降：-40%]，自身持有的具有[抗性上升][抗性无效] 的技能和宝具无效化。特别的，此效果无法获取仅有等级 A 的技能，若那个技能可以以其他等 级的模板获取，则不在此列。 此技能等级达到EX时，效果6仅能获取A级的技能，并遵守原本规则 | L51: 效果 | M51: [主力位] 建卡时，此技能允许无视面向获取。 发动时，此技能默认优先结算。 本场战斗中，自身下一个发动的技能或解放的宝具获得[无敌贯通]。 这之后，从以下效果选择一项生效： 1、令那个技能或宝具在首次生效时，其发起的判定获得[+40%]判定成功率。 2、令那个技能或宝具在首次生效时，给予目标[-40%]胜率惩罚以及[底限穿透：-10%]。 3、令那个技能或宝具在首次生效时，给予目标[耐久]属性[-40]属性惩罚。
B54: 背景 | C54: 改朝换代并非他所之愿，只是被迫而行 | L54: 背景 | M54: 这是最后的绝招，这是在乱世之中苟活下来的秘籍
...

Sheet 角色經歷
B2: 最能代表角色的一句话: | L2: 角色之核心人設
L3: (玩家对扮演角色的再解读，以英雄的事迹、史料作参考，构建出有血有肉独属于玩家自己的英灵。）
B6: 职阶 | C6: 灵基 | D6: 等级 | E6: 筋力 | F6: 耐力 | G6: 敏捷 | H6: 魔力 | I6: 幸运 | J6: 宝具
B7: ='角色卡 '!F9 -> Saber（职阶2） | C7: 英灵 | D7: ='角色卡 '!C15 -> 70 | E7: =_xlfn.IFS('角色卡 '!$D$15<21,"E",'角色卡 '!$D$15<41,"D",'角色卡 '!$D$15<61,"C",'角色卡 '!$D$15<81,"B",'角色卡 '!$D$15<101,"A",'角色卡 '!$D$15<121,"A+",'角色卡 '!$D$15>120,"EX") -> C | F7: =_xlfn.IFS('角色卡 '!$E$15<21,"E",'角色卡 '!$E$15<41,"D",'角色卡 '!$E$15<61,"C",'角色卡 '!$E$15<81,"B",'角色卡 '!$E$15<101,"A",'角色卡 '!$E$15<121,"A+",'角色卡 '!$E$15>120,"EX") -> C | G7: =_xlfn.IFS('角色卡 '!$F$15<21,"E",'角色卡 '!$F$15<41,"D",'角色卡 '!$F$15<61,"C",'角色卡 '!$F$15<81,"B",'角色卡 '!$F$15<101,"A",'角色卡 '!$F$15<121,"A+",'角色卡 '!$F$15>120,"EX") -> B | H7: =_xlfn.IFS('角色卡 '!$G$15<21,"E",'角色卡 '!$G$15<41,"D",'角色卡 '!$G$15<61,"C",'角色卡 '!$G$15<81,"B",'角色卡 '!$G$15<101,"A",'角色卡 '!$G$15<121,"A+",'角色卡 '!$G$15>120,"EX") -> D | I7: =_xlfn.IFS('角色卡 '!$H$15<21,"E",'角色卡 '!$H$15<41,"D",'角色卡 '!$H$15<61,"C",'角色卡 '!$H$15<81,"B",'角色卡 '!$H$15<101,"A",'角色卡 '!$H$15<121,"A+",'角色卡 '!$H$15>120,"EX") -> D | J7: =_xlfn.IFS('角色卡 '!$I$15<11,"E",'角色卡 '!$I$15<21,"D",'角色卡 '!$I$15<31,"C",'角色卡 '!$I$15<41,"B",'角色卡 '!$I$15<51,"A",'角色卡 '!$I$15<56,"A+",'角色卡 '!$I$15>55,"EX") -> EX
B8: 性别 | C8: =C27 -> 男 | E8: 样貌特点
B9: 身高 | C9: 182
B10: 体重 | C10: 42
B11: 玩家 | E11: 喜好事物
B12: 天海
B14: 阵营 | E14: 厌恶事物
B15: 秩序-善
B17: 图片 | E17: 圣遗物评级 | H17: （圣遗物背景，在梦境召唤的圣杯中无需填写）
E18: Euclid
E19: 名称
E21: 地域
E22: 年代
E23: 外观
E24: 出产地点
B25: 真名 | C25: 仇远 | E25: 英灵愿望 | L25: 你希望拥有怎样的御主？在什么情况下你可能会违背御主的命令？
B26: 职业 | C26: 任官 | E26: （你扮演的角色为了什么回应圣杯？这个愿望可以被放弃吗？在绝对无法做到的情况下你的角色会做什么？）
B27: 性别 | C27: 男
B28: 国家 | C28: cn
B29: 信仰 | L29: 你在战斗中会以怎样的姿态面对你的对手？
B30: 典出
B31: 角色资料
B32: （此处可以书写百科中对你扮演的角色的介绍，请优先截取侧重点进行复制）
L33: 你认为友谊是什么？你愿意把后背托付给怎么样的战友？
L37: 此空白留给GM为了更好理解你扮演的角色而给出询问
B40: 职阶适性
B41: （为什么你扮演的角色作为这个职阶现界？） | L41: 角色梦境:
L42: （在梦境召唤的圣杯中，从者需要写梦境） （梦境的内容可以是生前的经历，对于过去、某个遭遇的感想等，适合角色就行） （梦境的目的，主要是寻找一名相性较为匹配的御主）
B44: 英灵原则
B45: （在圣杯战争中，你扮演的角色会遵循哪些世俗的道德原则？又或者他存在自己的原则？）
B49: 下方的效果将严重影响角色方针，请自行填写描述，由GM决定具体效果
B50: 特性: | C50: （例：无尽的强制）（此内容是否启用请咨询GM）
B51: 效果︰ | C51: （例：执行[机动]的回合内作为袭击方参与战斗时将额外获得[+5%]的胜率补正）
B52: 描述︰ | C52: （例：你的角色无论如何都不会放弃圣杯，将会用尽一切手段攻击其他可能的阻碍者或在战斗中胜出）

Sheet 调卡用表
B3: 职阶名称 | C3: 筋力 | D3: 耐久 | E3: 敏捷 | F3: 魔力 | G3: 幸运 | J3: 技能等级 | K3: 对应RP | M3: 宝具等级 | N3: 对应RP | P3: 职阶特性
B4: Saber（职阶1） | C4: 20 | D4: 20 | E4: 20 | F4: 20 | G4: 20 | J4: E | K4: 1 | M4: E | N4: 1 | P4: Saber（职阶1） | Q4: 你的面板就是你的特性。
B5: Saber（职阶2） | C5: 20 | D5: 10 | E5: 20 | F5: 20 | G5: 20 | J5: D | K5: 2 | M5: D | N5: 2 | P5: Saber（职阶2） | Q5: 建卡时，放弃职阶技能[骑乘]和[10]点[耐久]职阶属性，获得额外的[+2]RP点。
B6: Lancer（职阶1） | C6: 10 | D6: 10 | E6: 30 | F6: 20 | G6: 10 | J6: C | K6: 3 | M6: C | N6: 3 | P6: Lancer（职阶1） | Q6: 建卡时，使自身等级最高的[类型：对人]宝具魔力消耗[-20]，若那个宝具为[发动时机：常驻]则此效果数值减半；若敌方战斗位单位数高于己方战斗位单位数则主要工序内撤退消耗FP-1；允许宣言指令[冲锋]。
B7: Lancer（职阶2） | C7: 10 | D7: 10 | E7: 30 | F7: 20 | G7: 10 | J7: B | K7: 4 | M7: B | N7: 4 | P7: Lancer（职阶2） | Q7: 建卡时，令自身任一宝具获得[骑乘]特性并将[骑乘]作为自身的[职阶技能]。自身宣言[冲锋]时，给予目标[-10%]胜率惩罚，若本次[冲锋]进行了成功的判定，此胜率惩罚翻倍。
B8: Archer（职阶1） | C8: 30 | D8: 20 | E8: 30 | F8: 0 | G8: 20 | J8: A | K8: 5 | M8: A | N8: 5 | P8: Archer（职阶1） | Q8: 使作为职阶属性的[筋力][耐久][敏捷]三项[+10]；建卡时允许指定自身持有的任一宝具，消耗[2]RP点（计为扩容）令其获得[爆发]。
B9: Archer（职阶2） | C9: 20 | D9: 10 | E9: 20 | F9: 0 | G9: 20 | J9: EX | K9: 7 | M9: EX | N9: 9 | P9: Archer（职阶2） | Q9: 指定自身持有的任一宝具，若其具有[主力位]且不为[类型：结界]，使其失去[主力位]；若其不具有[主力位]且不为[类型：结界]则使其获得[支援]。
B10: Rider（职阶1） | C10: 10 | D10: 20 | E10: 20 | F10: 0 | G10: 20 | J10: -(E) | K10: 1 | M10: -(E) | N10: 1 | P10: Rider（职阶1） | Q10: 建卡时，令自身任一宝具获得[骑乘]特性且自身具有[骑乘]特性的宝具不需要扩容。
B11: Rider（职阶2） | C11: 10 | D11: 20 | E11: 20 | F11: 0 | G11: 20 | J11: -(D) | K11: 2 | M11: -(D) | N11: 2 | P11: Rider（职阶2） | Q11: 建卡时，令自身任一宝具获得[骑乘]特性；自身具有至多6个宝具栏位，但仍然需要支付扩容所需的RP点。
B12: Caster（职阶1） | C12: 0 | D12: 0 | E12: 0 | F12: 30 | G12: 20 | J12: -(C) | K12: 3 | M12: -(C) | N12: 3 | P12: Caster（职阶1） | Q12: 建卡时允许令自身保有的[类型：魔术]技能获得[爆发]特性；始终允许自身在签订任意契约或进行[休整]时视为[御主]单位。
B13: Caster（职阶2） | C13: 0 | D13: 0 | E13: 0 | F13: 30 | G13: 20 | J13: -(B) | K13: 4 | M13: -(B) | N13: 4 | P13: Caster（职阶2） | Q13: 建卡时额外具有一个仅可用于购入[类型：魔术]技能的技能栏位，并令[魔力]属性低于自身的单位以自身为效果对象的[类型：魔术]技能，效果等级下降[[魔力]属性差/20]]级；始终允许自身在签订任意契约或进行[休整]时视为[御主]单位。
B14: Assassin（职阶1） | C14: 0 | D14: 0 | E14: 20 | F14: 0 | G14: 20 | J14: -(A) | K14: 5 | M14: -(A) | N14: 5 | P14: Assassin（职阶1） | Q14: 自身发起的负面判定获得[+25%]的最终成功率补正。
B15: Assassin（职阶2） | C15: 0 | D15: 0 | E15: 20 | F15: 0 | G15: 20 | J15: -(EX) | K15: 7 | M15: -(EX) | N15: 9 | P15: Assassin（职阶2） | Q15: 始终给予自身[+10%]胜率补正，在自身宣言[袭击]产生的战斗中，此胜率补正数值翻倍；若敌方[主力位]不为[从者]或初次处于同一场战斗，则此胜率补正再次翻倍。
... B17: Berserker（职阶2） | C17: 20 | D17: 20 | E17: 20 | F17: 0 | G17: 0 | J17: D+ | K17: 4 | M17: D+ | N17: 4 | P17: Berserker（职阶2） | Q17: 建卡时，令自身[筋力][耐久][敏捷]的分配属性上限上升[+10]；自身宣言死斗时，获得[+20%]胜率补正。
J18: C+ | K18: 5 | M18: C+ | N18: 5
J19: B+ | K19: 6 | M19: B+ | N19: 6
J20: A+ | K20: 7 | M20: A+ | N20: 7
J21: E++ | K21: 5 | M21: E++ | N21: 5
J22: D++ | K22: 6 | M22: D++ | N22: 6
J23: C++ | K23: 7 | M23: C++ | N23: 7
J24: B++ | K24: 8 | M24: B++ | N24: 8
J25: A++ | K25: 9 | M25: A++ | N25: 9
J26: E+++ | K26: 7 | M26: E+++ | N26: 7
J27: D+++ | K27: 8 | M27: D+++ | N27: 8
J28: C+++ | K28: 9 | M28: C+++ | N28: 9
J29: B+++ | K29: 10 | M29: B+++ | N29: 10
J30: A+++ | K30: 11 | M30: A+++ | N30: 11

Sheet 建卡用参考资源
B1: *仅包含常用资源
B2: 职阶 | D2: 基础属性 | J2: 职阶奖励与特性
B3: Saber | D3: 属性 | E3: 筋力 | F3: 耐久 | G3: 敏捷 | H3: 魔力 | I3: 幸运 | J3: [对魔力]上升一级。
D4: 点数 | E4: 20 | F4: 20 | G4: 20 | H4: 10 | I4: 0
B5: Lancer | D5: 属性 | E5: 筋力 | F5: 耐久 | G5: 敏捷 | H5: 魔力 | I5: 幸运 | J5: [对魔力]上升一级。
D6: 点数 | E6: 15 | F6: 15 | G6: 30 | H6: 0 | I6: 0 | J6: 需要主动释放且[类型：对人宝具]的宝具所消耗的魔力降低10点。
B7: Archer | D7: 属性 | E7: 筋力 | F7: 耐久 | G7: 敏捷 | H7: 魔力 | I7: 幸运 | J7: 从[对魔力]或[单独行动]中，择一项上升一级。
D8: 点数 | E8: 15 | F8: 15 | G8: 20 | H8: 0 | I8: 0
B9: Rider | D9: 属性 | E9: 筋力 | F9: 耐久 | G9: 敏捷 | H9: 魔力 | I9: 幸运 | J9: 从[对魔力]或[骑乘]中，择一项上升一级。
D10: 点数 | E10: 10 | F10: 10 | G10: 10 | H10: 0 | I10: 0
B11: Caster | D11: 属性 | E11: 筋力 | F11: 耐久 | G11: 敏捷 | H11: 魔力 | I11: 幸运 | J11: 从[阵地制作]或[道具制作]中，择一项上升一级。
D12: 点数 | E12: 0 | F12: 0 | G12: 0 | H12: 30 | I12: 0
B13: Assassin | D13: 属性 | E13: 筋力 | F13: 耐久 | G13: 敏捷 | H13: 魔力 | I13: 幸运 | J13: [气息遮蔽]上升一级。
D14: 点数 | E14: 0 | F14: 0 | G14: 30 | H14: 0 | I14: 0
B15: Berserker | D15: 属性 | E15: 筋力 | F15: 耐久 | G15: 敏捷 | H15: 魔力 | I15: 幸运 | J15: [狂化]可选择是否上升或下降一级。
D16: 点数 | E16: 15 | F16: 15 | G16: 0 | H16: 0 | I16: 0 | J16: 除了 EX 级别的狂化外，B 等级以上的狂化解放宝具时，
J17: 需额外消耗一枚令咒才能解放。(该枚令咒将视为胜率补正消耗)。
B19: 技能资源库
B20: 基础技能
B21: 一般 | K21: 一般
B22: 名称： | C22: 枪械精通 A B C | E22: 类别： | F22: 一般 | H22: 使用时机： | I22: 初始工序 | K22: 名称： | L22: 八极拳 B | N22: 类别： | O22: 一般 | Q22: 使用时机： | R22: 初始工序
B23: 效果︰ | C23: 在[袭击]或[介入行动]的时候，无条件获得[+20/15/10]的胜率补正。 | K23: 效果︰ | L23: 选择对方战斗位上的一名御主发动，令其进行一次成功率=[自身上三维总和-目标上三维总和]的判定 在判定成功后，将会使目标强制退出战斗位，这个判定受[非精神系弱体耐性]的影响。
B25: 备注： | C25: 御主等级[30/20/10]可分别获得[A/B/C]等级。
B26: 名称： | C26: 情报优势 A B C | E26: 类别： | F26: 一般 | H26: 使用时机： | I26: 游戏第一天开始时
B27: 效果︰ | C27: 随机获得除自己以外最多[3/2/1]名[御主]的[详细侦查资料]以及[所在根据地]。 | K27: 名称： | L27: 投毒 B | N27: 类别： | O27: 一般 | Q27: 使用时机： | R27: 行动阶段
K28: 效果︰ | L28: 该技能在本次圣杯战争中只能使用一次，发动后选择以下其一发动。 ①消耗一个行动阶段，令一个灵脉上的全部[御主]受到一次成功率=[50]的[中毒]判定。 ②回合结束时发动，令自身所在灵脉除自身以外的全部[御主]直接[中毒]。
B29: 备注： | C29: 御主等级[35/25/15]可分别获得[A/B/C]等级。
B30: 名称： | C30: 武术（剑术） A B C | E30: 类别： | F30: 一般 | H30: 使用时机： | I30: 主要工序
B31: 效果︰ | C31: 给予自身[筋力 [耐久]、[敏捷]其中一项获得[+15/+10/+5]的属性补正。
K32: 魔术
B33: 备注： | C33: 御主上三维属性的总和[70/50/30]可分别获得[A/B/C]等级。 | K33: 名称： | L33: 宝石魔术 B | N33: 类别： | O33: 魔术 | Q33: 使用时机： | R33: 最终工序
B34: 魔术 | K34: 效果︰ | L34: 消耗任意一个礼装后发动，给予对方[-20]的胜率惩罚。
B35: 名称： | C35: 魔术 A B C | E35: 类别： | F35: 魔术 | H35: 使用时机： | I35: 主要工序
B36: 效果︰ | C36: 有使用[魔力]作为战斗属性的场合，给予敌方[-20/15/10]的胜率惩罚。 | K36: 名称： | L36: 死灵魔术 B | N36: 类别： | O36: 魔术 | Q36: 使用时机： | R36: 常驻
K37: 效果︰ | L37: 自身[人偶]的制作方式改变为[杀死一名御主]或[进行一次成功的魂食]，但自身的[人偶]将可以复数存在， 且自身的人偶无论数量多少，都将会在战斗时将所有人偶的属性叠加在一起并视为一个单位。
B38: 备注： | C38: 御主的[魔]达到[35/25/15]可分别获得[A/B/C]等级。
B39: 名称： | C39: 炼金魔术 A B C | E39: 类别： | F39: 魔术 | H39: 使用时机： | I39: 常驻
B40: 效果︰ | C40: 自身在制作礼装时，将会获得[+25/20/15]的[成功率补正]。 并且在制作礼装时，若出目数在[5]以下时，则这一次制作成功的礼装视为[2]份。
K41: 备注： | L41: 利用[魂食]进行[人偶制作]时，在成功时将无法获取相对应的魔力。
B42: 备注： | C42: 御主的[魔]达到[35/25/15]可分别获得[A/B/C]等级。 | K42: 名称： | L42: 妨碍傀儡 A | N42: 类别： | O42: 魔术 | Q42: 使用时机： | R42: 战斗前
...

Sheet 技能&宝具资源库
A1: 技能资源列表 | I1: 宝具资源列表
A2: 模板 | B2: 类型 | C2: 时机 | D2: 等级 | E2: 资源 | F2: 回转 | G2: 魔耗 | H2: 效果 | I2: 模板 | J2: 类型 | K2: 时机 | L2: 等级 | M2: 资源 | N2: 回转 | O2: 魔耗 | P2: 效果
A3: 对魔力 | B3: 职介 | C3: 技能发动时 | D3: E | E3: 1 | F3: 1 | G3: 1 | H3: [反击][支援] 当自身成为此技能等级相同或以下的[类型：魔术]技能的效果对象，或受到其效果影响时可以发动，令那个技能对自身可能生效的效果无效，且不会返还发动消耗。
A4: 对魔力 | B4: 职介 | C4: 技能发动时 | D4: D | E4: 2 | F4: 1 | G4: 1 | H4: [反击][支援] 当自身成为此技能等级相同或以下的[类型：魔术]技能的效果对象，或受到其效果影响时可以发动，令那个技能对自身可能生效的效果无效，且不会返还发动消耗。
A5: 对魔力 | B5: 职介 | C5: 技能发动时 | D5: C | E5: 3 | F5: 1 | G5: 1 | H5: [反击][支援] 当自身成为此技能等级相同或以下的[类型：魔术]技能的效果对象，或受到其效果影响时可以发动，令那个技能对自身可能生效的效果无效，且不会返还发动消耗。
A6: 对魔力 | B6: 职介 | C6: 技能发动时 | D6: B | E6: 4 | F6: 1 | G6: 1 | H6: [反击][支援] 当自身成为此技能等级相同或以下的[类型：魔术]技能的效果对象，或受到其效果影响时可以发动，令那个技能对自身可能生效的效果无效，且不会返还发动消耗。
A7: 对魔力 | B7: 职介 | C7: 技能发动时 | D7: A | E7: 5 | F7: 1 | G7: 1 | H7: [反击][支援] 当自身成为此技能等级相同或以下的[类型：魔术]技能的效果对象，或受到其效果影响时可以发动，令那个技能对自身可能生效的效果无效，且不会返还发动消耗。
A8: 骑乘 | B8: 职介 | C8: 常驻 | D8: E | E8: 1 | F8: 0 | G8: 0 | H8: 自身具有[骑乘]的技能或宝具生效时，给予自身[+10%]的胜率补正。
A9: 骑乘 | B9: 职介 | C9: 常驻 | D9: D | E9: 2 | F9: 0 | G9: 0 | H9: 自身具有[骑乘]的技能或宝具生效时，给予自身[+20%]的胜率补正。
A10: 骑乘 | B10: 职介 | C10: 常驻 | D10: C | E10: 3 | F10: 0 | G10: 0 | H10: 自身具有[骑乘]的技能或宝具生效时，给予自身[+30%]的胜率补正。
A11: 骑乘 | B11: 职介 | C11: 常驻 | D11: B | E11: 4 | F11: 0 | G11: 0 | H11: 自身具有[骑乘]的技能或宝具生效时，给予自身[+40%]的胜率补正。
A12: 骑乘 | B12: 职介 | C12: 常驻 | D12: A | E12: 5 | F12: 0 | G12: 0 | H12: 自身具有[骑乘]的技能或宝具生效时，给予自身[+50%]的胜率补正。
A13: 单独行动 | B13: 职介 | C13: 常驻 | D13: E | E13: 1 | F13: 0 | G13: 0 | H13: 自身进行广泛侦查时，额外获得[+10%]的最终成功率补正。 自身魔力下限改为[-200]，魔力不足惩罚改为每达到[-20]，全属性将受到[-5]的惩罚。 御主死亡或与御主解除[圣杯契约]后仍可以存活[1]天，在此期间将不结算待机耗魔，但亦无法获得来自[灵脉]或[圣杯]的供魔。 魔力不足达到下限或剩余回合数不足时将会消灭。
A14: 单独行动 | B14: 职介 | C14: 常驻 | D14: D | E14: 2 | F14: 0 | G14: 0 | H14: 自身进行广泛侦查时，额外获得[+20%]的最终成功率补正。 自身魔力下限改为[-200]，魔力不足惩罚改为每达到[-20]，全属性将受到[-5]的惩罚。 御主死亡或与御主解除[圣杯契约]后仍可以存活[2]天，在此期间将不结算待机耗魔，但亦无法获得来自[灵脉]或[圣杯]的供魔。 魔力不足达到下限或剩余回合数不足时将会消灭。
... A68: 魔力放出 | B68: 技艺 | C68: 随时 | D68: C | E68: 3 | F68: 1 | G68: 5 | H68: 给予自身的[筋力][耐久][敏捷]当中的任一项属性[+5]的常驻补正与[+10%]的胜率补正。 这个技能带来的常驻补正将会在回合结束时失去。
D69: B | E69: 4 | F69: 1 | G69: 10 | H69: 给予自身的[筋力][耐久][敏捷]当中的任一项属性[+10]的常驻补正与[+10%]的胜率补正。 这个技能带来的常驻补正将会在回合结束时失去。
D70: A | E70: 5 | F70: 1 | G70: 15 | H70: 给予自身的[筋力][耐久][敏捷]当中的任一项属性[+15]的常驻补正与[+10%]的胜率补正。 这个技能带来的常驻补正将会在回合结束时失去。
A71: 军略 | B71: 技艺 | C71: 常驻 | D71: E | E71: 1 | F71: 0 | G71: 0 | H71: [主力位] 自身[战术]未被克制时才能生效。 我方发动[对军宝具]时，给予自身[+5%]的胜率补正。 自身[战术]克制敌方，且在敌方发动[对军宝具]时，给予自身[+5%]的胜率补正。
C72: 常驻 | D72: D | E72: 2 | F72: 0 | G72: 0 | H72: [主力位] 自身[战术]未被克制时才能生效。 我方发动[对军宝具]时，给予自身[+10%]的胜率补正。 自身[战术]克制敌方，且在敌方发动[对军宝具]时，给予自身[+10%]的胜率补正。
C73: 常驻 | D73: C | E73: 3 | F73: 0 | G73: 0 | H73: [主力位] 自身[战术]未被克制时才能生效。 我方发动[对军宝具]时，给予自身[+15%]的胜率补正。 自身[战术]克制敌方，且在敌方发动[对军宝具]时，给予自身[+15%]的胜率补正。
C74: 常驻 | D74: B | E74: 4 | F74: 0 | G74: 0 | H74: [主力位] 自身[战术]未被克制时才能生效。 我方发动[对军宝具]时，给予自身[+20%]的胜率补正。 自身[战术]克制敌方，且在敌方发动[对军宝具]时，给予自身[+20%]的胜率补正。
C75: 常驻 | D75: A | E75: 5 | F75: 0 | G75: 0 | H75: [主力位] 自身[战术]未被克制时才能生效。 我方发动[对军宝具]时，给予自身[+25%]的胜率补正。 自身[战术]克制敌方，且在敌方发动[对军宝具]时，给予自身[+25%]的胜率补正。

Sheet 數值參考
A2: 从者等级 | B2: 分配点数 | C2: 特性 | G2: 筋力： | H2: 耐力： | I2: 敏捷： | J2: 魔力： | K2: 幸运： | L2: 宝具： | M2: 职阶特性
A3: 40 | B3: 100 | C3: 秩序·善 | F3: Saber | G3: 20 | H3: 20 | I3: 20 | J3: 10 | K3: 20 | L3: 0 | M3: 宝具栏数量最大为2，建卡时可以通过放弃【骑乘】来额外获得2的RP用于资源兑换。
A4: 50 | B4: 120 | C4: 中立·善 | F4: Lancer | G4: 10 | H4: 10 | I4: 30 | J4: 10 | K4: 10 | L4: 0 | M4: 自身的其中一项等级最高宝具的魔耗【-20】（最低为0），允许宣言指令【冲锋】。
A5: 60 | B5: 140 | C5: 混沌·善 | F5: Archer | G5: 10 | H5: 10 | I5: 10 | J5: 0 | K5: 20 | L5: 0 | M5: 自身的其中一项等级最高宝具获得【爆发】特性，且建卡时额外拥有2的RP用于在宝具资源上的兑换。
A6: 70 | B6: 160 | C6: 秩序·中立 | F6: Rider | G6: 0 | H6: 30 | I6: 0 | J6: 0 | K6: 20 | L6: 0 | M6: 初始宝具栏数量为2，且自身其中一项宝具获得【骑乘】特性。
A7: 空 | B7: 0 | C7: 中立·中庸 | F7: Caster | G7: 0 | H7: 0 | I7: 0 | J7: 30 | K7: 0 | L7: 0 | M7: 自身的【魔力】属性视为等值的【回路】属性，魔力池额外获得50上限，且自身持有的魔术技能获得【双发】特性。
A8: 空 | B8: 0 | C8: 混沌·中立 | F8: Assassin | G8: 0 | H8: 0 | I8: 20 | J8: 0 | K8: 20 | L8: 0 | M8: 自身发起的负面判定成功率[+20%]调整值。
A9: 空 | B9: 0 | C9: 秩序·恶 | F9: Berserker | G9: 0 | H9: 0 | I9: 0 | J9: 0 | K9: 0 | L9: 0 | M9: 【筋力】【耐久】【敏捷】的分配属性上限修改为80，【魔力】【幸运】的分配属性上限修改为40。
C10: 中立·恶 | F10: Saber(骑乘) | G10: 20 | H10: 30 | I10: 20 | J10: 10 | K10: 20 | L10: 0
C11: 混沌·恶 | F11: Ruler | G11: 0 | H11: 0 | I11: 0 | J11: 0 | K11: 0 | L11: 0
C12: 秩序·狂 | F12: Shielder | G12: 0 | H12: 0 | I12: 0 | J12: 0 | K12: 0 | L12: 0
C13: 中立·狂 | F13: Foreigner | G13: 0 | H13: 0 | I13: 0 | J13: 0 | K13: 0 | L13: 0
C14: 混沌·狂 | F14: Alterego | G14: 0 | H14: 0 | I14: 0 | J14: 0 | K14: 0 | L14: 0
C15: 空 | F15: Moon Cancer | G15: 0 | H15: 0 | I15: 0 | J15: 0 | K15: 0 | L15: 0
C16: 空 | F16: Beast | G16: 0 | H16: 0 | I16: 0 | J16: 0 | K16: 0 | L16: 0
C17: 空 | F17: Avenger | G17: 20 | H17: 0 | I17: 0 | J17: 0 | K17: 0 | L17: 0
C18: 空 | G18: 0 | H18: 0 | I18: 0 | J18: 0 | K18: 0 | L18: 0
C19: 空 | G19: 0 | H19: 0 | I19: 0 | J19: 0 | K19: 0 | L19: 0
C20: 空 | G20: 0 | H20: 0 | I20: 0 | J20: 0 | K20: 0 | L20: 0
C21: 空
C22: 空 | F22: 技能等级转化资源 | H22: 宝具等级转化资源 | J22: 职阶技能等级转化资源
C23: 空 | F23: EX | G23: 7 | H23: EX | I23: 9 | J23: A+(本职) | K23: 6
C24: 空 | F24: A++++ | G24: 5 | J24: A(本职) | K24: 4
C25: 空 | F25: A+ | G25: 7 | H25: A+ | I25: 7 | J25: A+ | K25: 7
C26: 空 | F26: A | G26: 5 | H26: A | I26: 5 | J26: A | K26: 5
C27: 空 | F27: - [视为A级] | G27: 5 | H27: - [视为A级] | I27: 5 | J27: B(本职) | K27: 3
C28: 空 | F28: B+ | G28: 6 | H28: B+ | I28: 6 | J28: B+ | K28: 6
C29: 空 | F29: B | G29: 4 | H29: B | I29: 4 | J29: B | K29: 4
C30: 空 | F30: - [视为B级] | G30: 4 | H30: - [视为B级] | I30: 4 | J30: C(本职) | K30: 2
C31: 空 | F31: C+ | G31: 5 | H31: C+ | I31: 5 | J31: C+ | K31: 5
C32: 空 | F32: C | G32: 3 | H32: C | I32: 3 | J32: C | K32: 3
C33: 空 | F33: - [视为C级] | G33: 3 | H33: - [视为C级] | I33: 3 | J33: D(本职) | K33: 1
C34: 空 | F34: D+ | G34: 4 | H34: D+ | I34: 4 | J34: D+ | K34: 4
C35: 空 | F35: D | G35: 2 | H35: D | I35: 2 | J35: D | K35: 2
J36: E(本职) | K36: 0
F37: E+ | G37: 3 | H37: E+ | I37: 3 | J37: E+ | K37: 3
F38: E | G38: 1 | H38: E | I38: 1 | J38: E | K38: 1
