Workbook
Name 表: 数值参考!#REF!
Name 科技: 数值参考!#REF!
Name 魔术: 数值参考!#REF!
Name 特殊: 数值参考!#REF!
Name 天赋类型: 数值参考!#REF!
Name 武术: 数值参考!#REF!

Sheet 說明
A1: 對應規則書︰2.05
A7: 更新記錄
A8: 5 | B8: 自動化一部份的屬性分配
B9: 加入看上去很酷的屬性圖
B10: 加入簡單背景介紹在第一頁
A11: 5.1 | B11: 加入特性(可選規則)用的格子
A12: 5.2 | B12: 將特性這不會暴露，暴露後易被針對的效果移至角色卡下方，以便GM處理情報
B13: 為特性提供了實驗性質的效果槽，是否啟用自行向GM查詢
A14: 5.3 | B14: 本版本因應2.0規則將魔屬性分配更改了，舊版千萬不要使用此規則
B15: 並且于本版卡的起源覺醒者已正式移出，和加入了結界使、人偶使
A16: 5.31 | B16: 六維圖修了修
B17: 技能效果多加了一行，讓說明有點複雜的技能不用整天拉長行數。但是說明超長的依然要拉長行數
A18: 5.4 | B18: 禦主屬性回檔，魔力分配重新改為/2
B19: 處理了不太好看的格子
A20: 5.5 | B20: 加了倫理規則下，關係用的格子
B21: 特性由原來的範例，改成一些針對性的問題，寫特性時請將這些問題納入考慮
B22: 雖然很丟人，但之前一直將貼圖鎖了....現在不解除保護也能貼圖了
A23: 5.51 | B23: 異能者的特性也改了
B24: 代行者的九鍵數值調成15
A25: 6 | B25: 倫理關係的格子細分了關係背景、對指定關係人的態度
B26: 角色的屬性改成橫的，方便填表時右鍵
B27: 角色頭像可以放更大的了
B28: 禦主名字、陣營的位置改放到「角色經歷」，第一頁改為放代稱
B29: 為了排版美觀，職業特性自己去查規則書。
B30: 另外調整了排版，如無意外角色卡可以用A4size印出來了。不過我還沒嘗試。
A31: 6.01 | B31: 有些排版出包了，調整完成。
B32: 御主可选职业新增了巫术使
A34: GM開團前「可」準備的事
A39: 在數值參考頁面按自己特有的村規進行基礎屬性、點數的調整。或加入新職階
A62: 本角色卡是為聖杯戰爭跑團準備的角色卡。
A63: 該聖杯戰爭跑團規則大部分採用了日本現在較流行的男爵聖杯規則作為基底，進行魔改的TRPG規則，在遊戲上簡約了戰鬥部分，以實際扮演為主體的遊戲方式。
A65: 若有疑問可加群424815329查詢
A66: 備用二群 | B66: 310690935

Sheet 角色卡
B2: 阵营 | E2: 外貌描述 | H2: 肖像 | K2: 资源上限 | L2: 特攻列表
B3: =角色經歷!E15 -> 秩序-善 | K3: =12+VLOOKUP(C18,'（调卡用表）'!P3:Q7,2,0) -> 24 | L3: 职业 | N3: =F9 -> 异能者
L4: 子职 | N4: =F10 -> 宝菌传承者
B5: 令咒 | K5: 剩余资源 | L5: 阵营 | N5: =角色經歷!E15 -> 秩序-善
K6: =K3-IF(J19>0,K9,K9-J19/20) -> 5 | L6: 特性 | N6: =F11 -> 人型 | O6: =G11 -> 0
N7: =F12 -> 0 | O7: =G12 -> 0
K8: 花费资源 | L8: 性别 | N8: =角色經歷!C12 -> 男
E9: 主职业 | F9: 异能者 | K9: =J21+AE30+AE37+J49+J58+J67+T21+T30+T39+T49+T58+T67+K12 -> 19 | L9: 体型 | N9: =F13 -> 通常
E10: 子职业 | F10: 宝菌传承者 | L10: 注释
E11: 特性 | F11: 人型 | K11: 扩容 | L11: 特攻列表不会也不能为其他角色所获取。
K12: =H21+AC30+AC37+H49+H58+H67+R21+R30+R39+R49+R58+R67 -> 4
E13: 体型 | F13: 通常 | L13: 学科特性
E14: 学科 | L14: 名称 | O14: 选取条件
B15: 属性 | C15: 等级 | D15: 筋力 | E15: 耐久 | F15: 敏捷 | G15: 魔力 | H15: 幸运 | I15: 回路 | J15: 属性点数
B16: 合计 | C16: =C17+C18+C19 -> 50 | D16: =D17+D18+D19 -> 5 | E16: =E17+E18+E19 -> 10 | F16: =F17+F18+F19 -> 5 | G16: =G17+G18+G19 -> 10 | H16: =H17+H18+H19 -> 40 | I16: =I17+I18+I19 -> 80 | J16: 80 | L16: 效果 | M16: （持有[类型：魔术]技能且存在时钟塔进修经历的单位才可以选择[学科]） （此项为额外规则，通常不开）
B17: 职业 | D17: =VLOOKUP(F9,'（调卡用表）'!B3:H13,2,0) -> 0 | E17: =VLOOKUP(F9,'（调卡用表）'!B3:H13,3,0) -> 0 | F17: =VLOOKUP(F9,'（调卡用表）'!B3:H13,4,0) -> 0 | G17: =VLOOKUP(F9,'（调卡用表）'!B3:H13,5,0) -> 10 | H17: =VLOOKUP(F9,'（调卡用表）'!B3:H13,6,0) -> 30 | I17: =VLOOKUP(F9,'（调卡用表）'!B3:I13,7,0) -> 10 | J17: =D17+E17+F17+G17+H17+I17 -> 50
B18: 分配 | C18: 40 | D18: 5 | E18: 10 | F18: 5 | H18: 10 | I18: 50 | J18: 剩余点数
B19: 补正 | C19: 10 | I19: 20 | J19: =J16-SUM(D18:I18) -> 0
B20: 工房构件 | L20: 额外技能
B21: 模板 | C21: 炼金基盘 | E21: 构件种类 | F21: 基本组件 | G21: 扩容 | I21: 资源 | L21: 模板 | M21: 英雄制作 | O21: 等级 | P21: B | Q21: 扩容 | S21: 资源 | T21: =_xlfn.IFNA(VLOOKUP(P21,'（调卡用表）'!$J$3:$K$33,2,0),0) -> 4
B22: 名称 | E22: 魔力消耗 | G22: 规模 | I22: 稳态 | L22: 名称 | M22: 断覆之羽-为你赐福 | O22: 类型 | P22: 祝福 | R22: 回转 | S22: 3
O23: 发动时机 | P23: 随时 | R23: 魔力消耗 | S23: 0 | T23: =IF(P23="常驻","每日","每次") -> 每次
B24: 效果 | C24: [稳态20/20][规模1/10] 令自阵营在此灵脉上进行的[礼装制作]获得[+25%]的基础成功率补正。 | L24: 效果 | M24: 除此技能的首次发动外，此技能指定的对象必须为自身外持有[王者]的御主单位。 此技能仅能在满足以下任一条件时立即发动并生效，并在发动后移除对应条件： 1、当前灵脉上任一御主单位作为[主力位/辅助位]参与到战斗中时； 2、当前灵脉上任一御主单位作为[主力位/辅助位]参与到战斗中，且获得战斗胜利时； 3、当前灵脉上任一御主单位在战斗中成为敌方战斗位上任意技能或宝具指定的目标时； 4、当前灵脉上任一御主单位受到来自其同阵营以外单位的负面判定，且那个判定成功时； 5、当前灵脉上任一御主单位以魔力[<-20]进行了至少一次魔力结算时； 6、当前灵脉上任一御主单位持有令咒数为[0]时。 给予目标[王者 1]，这之后，给予目标[+5]的等级补正，除[宝具]外全属性[+10]的常驻补正。 若目标[王者]层数因此变为[4]，允许将自身保有的任一技能以对应等级模板赋予目标，以此方 式获取的技能同样视为保有技能； 若目标[王者]层数因此变为[5]，允许将自身保有的任一宝具以对应等级模板赋予目标，并允许目 标获得与其持有宝具等级对应的[宝具]基础属性； 若目标[王者]层数因此变为[6]，目标在判定上同样视为从者单位（无法在圣杯契约中视为从者且 不会产生等级魔耗）。 此技能至多生效[5/4/3]次，且生效[5/4/3]次后，破弃此技能。 此技能作为额外技能重复获取时，先前发动带来的影响不会重置。
B27: 背景 | L27: 背景 | M27: 弟弟，以前我们什么也决定不了...但以后我们就是自由的了... 这片断覆的残羽，将为你照耀前行的道路 在我心中你便是最大的英雄
B30: 模板 | E30: 构件种类 | G30: 扩容 | I30: 资源 | L30: 模板 | O30: 等级 | Q30: 扩容 | R30: 4 | S30: 资源 | T30: =_xlfn.IFNA(VLOOKUP(P30,'（调卡用表）'!$J$3:$K$33,2,0),0) -> 0
B31: 名称 | E31: 魔力消耗 | G31: 规模 | I31: 稳态 | L31: 名称 | O31: 类型 | R31: 回转 | S31: 3
O32: 发动时机 | R32: 魔力消耗 | S32: 20 | T32: =IF(P32="常驻","每日","每次") -> 每次
B33: 效果 | C33: （每个御主持有一个工房构件栏，每个额外工房栏需要消耗1RP购入，写作[扩容]） | L33: 效果
B36: 背景 | L36: 背景
B39: 模板 | E39: 构件种类 | G39: 扩容 | I39: 资源 | L39: 模板 | O39: 等级 | Q39: 扩容 | S39: 资源 | T39: =_xlfn.IFNA(VLOOKUP(P39,'（调卡用表）'!$J$3:$K$33,2,0),0) -> 0
B40: 名称 | E40: 魔力消耗 | G40: 规模 | I40: 稳态 | L40: 名称 | O40: 类型 | R40: 回转
O41: 发动时机 | R41: 魔力消耗 | T41: =IF(P41="常驻","每日","每次") -> 每次
B42: 效果 | L42: 效果
B45: 背景 | L45: 背景
B48: 保有技能 | L48: 礼装
B49: 模板 | C49: 流转之传承 | E49: 等级 | F49: A | G49: 扩容 | I49: 资源 | J49: =_xlfn.IFNA(VLOOKUP(F49,'（调卡用表）'!$J$3:$K$33,2,0),0) -> 5 | L49: 模板 | O49: 等级 | P49: / | Q49: 扩容 | S49: 资源
B50: 名称 | C50: 圣子之心-羽 | E50: 类型 | F50: 天赋 | H50: 回转 | I50: 0 | L50: 名称 | O50: 类型 | R50: 回转
E51: 发动时机 | F51: 常驻 | H51: 魔力消耗 | I51: 0 | J51: =IF(F51="常驻","每日","每次") -> 每日 | O51: 发动时机 | R51: 魔力消耗 | T51: =IF(P51="常驻","每日","每次") -> 每次
B52: 效果 | C52: 建卡时，额外持有一个需要消耗[3]RP扩容的技能栏。 从从者资源库中选择低于此技能等级，且非[类型：职阶]的技能获取，占用此技能带来的技能栏 ；通过此技能获取技能时，视为购入，适用从者的资源购入规则，在发动时正常计算消耗和回转 。获取C级以上且仅有一个等级的技能时，需要额外消耗[1]RP进行扩容。 此技能等级达到EX时，额外消耗[3]RP扩容，允许自身获取A级的技能，若获取的那个技能仅有A 级，则需要额外消耗[1]RP进行扩容。 | L52: 效果 | M52: （每名御主持有一个初始礼装栏，每个额外礼装栏需要消耗1RP购入，写作[扩容]）
B55: 背景 | C55: 这片残缺的羽翼，为避护你而存在 ...弟弟 圣子的身份，我从不在意，我只希望你能够活下去 | L55: 背景
...

Sheet 角色經歷
B2: 最能代表角色的一句话: | L2: 你的角色是为了圣杯而参战的？你投身到圣杯战争中所追求的是什么？
B3: 残缺之羽，也有一天会飞向天空 | L3: 为了寻找原本的自由
B6: 喜好 | D6: 无 | H6: 使魔外观 | I6: 鸦羽
B7: 厌恶 | D7: 无 | H7: 技术 | I7: 无 | L7: 角色之核心人設
B8: 魔术属性 | D8: 无 | H8: 图片（此处为使魔外观） | L8: 弟控x，很纯粹的 老好人，他就是属于狗头型人设
B9: 魔术特性 | D9: 无
B10: 姓名 | C10: 卡斯托尔 | E10: 身份 | F10: 圣子
B11: 职业 | C11: 圣子 | E11: 所属 | F11: ？
B12: 性别 | C12: 男 | E12: 玩家
B13: 年龄 | C13: ？ | E13: 天海
B14: 身高 | C14: ？ | E14: 阵营
B15: 体重 | C15: ？ | E15: 秩序-善
B16: 已知的情报
B17: 被提灯教会收养为圣子，在逃离的过程之中被弟弟所背刺...
B25: 社会关系/[支援伦理规则]: | L25: 在這場聖杯戰爭中，你是否會遵守倫理的規則，不波及無辜？
B26: 关系： | C26: 父女 | E26: 對像： | F26: 远坂时臣 | H26: 态度： | I26: 亲切 | L26: 会
B27: 效果︰ | C27: 无
B29: 交集点/ 关系现状: | C29: 时臣死了。 | L29: 你的愿望是否可以放弃，如果可以，是在什么情况下？
L30: 会，我们想活上去
B32: 关系： | E32: 對像： | H32: 态度： | I32: 友好
B33: 效果︰ | C33: (支援伦理规则用的格子，若果GM没开这规则就不用理会) （作为社会关系栏位时，只需填写关系、态度与交集点/现状） | L33: 你希望拥有怎样的从者？在什么情况下你可能会违背从者的意愿进行行动？
L34: 无论怎么样都行...至少我们想活下去
B35: 交集点/ 关系现状: | C35: (本角色與指定關系人如何相遇、如何相處)
L37: 你愿意相信什么样的人？在什么情况下你可能会将其他参赛者认作盟友？
B38: 关系： | E38: 對像： | H38: 态度： | I38: 友好
B39: 效果︰ | C39: (支援伦理规则用的格子，若果GM没开这规则就不用理会) （作为社会关系栏位时，只需填写关系、态度与交集点/现状）
B41: 交集点/ 关系现状: | C41: (本角色與指定關系人如何相遇、如何相處) | L41: 角色梦境:
L42: (与从者交换梦境用的格子，若果GM没要求就不用理会)
B44: 关系： | E44: 對像： | H44: 态度： | I44: 友好
B45: 效果︰ | C45: (支援伦理规则用的格子，若果GM没开这规则就不用理会) （作为社会关系栏位时，只需填写关系、态度与交集点/现状）
B47: 交集点/ 关系现状: | C47: (本角色與指定關系人如何相遇、如何相處)
B50: 特性： | C50: (例)根源的渴望
B51: 效果： | C51: (是否提供实质加乘，请向GM查询自行决定，基本上无效果)
B52: 描述： | C52: (对自己的愿望有什么程度的执着，会于什么原因下放弃?) (面对其他组别会优先做出什么行动?)(在失去从者的情况下还会不会坚持不退出?)

Sheet （调卡用表）
B3: 职业名称 | C3: 筋力 | D3: 耐久 | E3: 敏捷 | F3: 魔力 | G3: 幸运 | H3: 回路 | J3: 技能等级 | K3: 对应RP | M3: 宝具等级 | N3: 对应RP | P3: 御主等级 | Q3: 对应RP
B4: 魔术师 | C4: 0 | D4: 0 | E4: 0 | F4: 20 | G4: 10 | H4: 20 | J4: E | K4: 1 | M4: E | N4: 1 | P4: 10 | Q4: 0
B5: 体术师 | C5: 20 | D5: 20 | E5: 20 | F5: 0 | G5: 10 | H5: 0 | J5: D | K5: 2 | M5: D | N5: 2 | P5: 20 | Q5: 4
B6: 异能者 | C6: 0 | D6: 0 | E6: 0 | F6: 10 | G6: 30 | H6: 10 | J6: C | K6: 3 | M6: C | N6: 3 | P6: 30 | Q6: 8
B7: 代行者 | C7: 0 | D7: 15 | E7: 0 | F7: 15 | G7: 10 | H7: 10 | J7: B | K7: 4 | M7: B | N7: 4 | P7: 40 | Q7: 12
B8: 退魔师 | C8: 10 | D8: 10 | E8: 10 | F8: 20 | G8: 0 | H8: 0 | J8: A | K8: 5 | M8: A | N8: 5
B9: 执法者 | C9: 15 | D9: 20 | E9: 15 | F9: 0 | G9: 0 | H9: 0 | J9: EX | K9: 7 | M9: EX | N9: 9
J10: -(E) | K10: 1 | M10: -(E) | N10: 1
J11: -(D) | K11: 2 | M11: -(D) | N11: 2
J12: -(C) | K12: 3 | M12: -(C) | N12: 3
J13: -(B) | K13: 4 | M13: -(B) | N13: 4
J14: -(A) | K14: 5 | M14: -(A) | N14: 5
J15: -(EX) | K15: 7 | M15: -(EX) | N15: 9
J16: E+ | K16: 3 | M16: E+ | N16: 3
J17: D+ | K17: 4 | M17: D+ | N17: 4
J18: C+ | K18: 5 | M18: C+ | N18: 5
J19: B+ | K19: 6 | M19: B+ | N19: 6
J20: A+ | K20: 7 | M20: A+ | N20: 7
J21: E++ | K21: 5 | M21: E++ | N21: 5
... J30: A+++ | K30: 11 | M30: A+++ | N30: 11

Sheet 建卡用参考资源
B2: 职业 | D2: 能力
B3: 魔术师 | D3: 就算自身与从者不在同一个场景下，也能对其使用令咒。
D4: 魔力额外获得[+10]的补正，该补正可以突破属性上限。并且基础技能的[类型]必须为[魔术]。
D5: 开局可获得一个任意的基础礼装。
C6: 人偶师 | D6: 就算自身与从者不在同一个场景下，也能对其使用令咒。
D7: 自身的基础技能将会提升一个等级，最高为 A，但必须为[人偶制成]。
B8: 异能者 | D8: 可任意挑选[类别:魔术]以外的基础技能。并将那个技能的等级提高一个等级，最高为 A 级。
D9: 并且额外获得[20]的可任意分配点数。
D10: （若是在等级骰点制的规则下，额外可任意分配点数将可以转化为自身等级骰+1。）
D11: 注 1:这个可任意分配点数，无法使属性突破上限。
D12: 注 2:由于御主默认没有宝具，所以也无法分配到宝具处。
B13: 魔眼使 | D13: 将自身的[基础技能]更替为具有[对他人产生负面效果]的[特殊技能]，该特殊技能的技能等级视为[B]。
D14: 名字：待定 类别：一般 使用时机：初始工序
D15: 效果：对对方战斗位的上一名御主进行一次成功率=[自身任一数值-目标任一数值]的[即死]效果，
D16: 在判定成功的情况下，若不以一枚令咒抵消，则将会视为退场。
D17: 在判定失败的情况下，将会给予对方[同等于即死成功率]的[胜率惩罚]。
B18: 保菌传承者 | D18: 将自身的[基础技能]更替为与自身[魔]相同等级的[对人宝具]。在解放宝具的当下也将会获得同等的[宝]属性。
D19: 10=E 20=D 30=C 40=B 50=A。
D20: 该宝具一天只能释放一次，且将会消耗等同于[魔]属性的魔力。也可以将自身的魔永久[-20]，将宝具类型提升为[固有结界]。
B21: 代行者 | D21: 自身的阵营必须为[秩序]，且参加圣杯战争的目的，必须是以[将圣杯回收至教会]为主，并且为了保证[圣杯]的魔力，不会给他人对[圣杯]许愿的机会。
D22: 可任意挑选基础技能，并将会额外获得一个礼装——[九键]，并且可以对自身使用令咒来加强自身的战斗能力。
D23: 名称：[九键] 类型：常驻礼装 使用时机：常驻
D24: 效果：战斗中，无条件给予自身[+15]的胜率补正。该[胜率补正]不可与其他[九键]复数叠加。
B25: 巫术使 | D25: 该职业可任意挑选基础技能，且将会额外获得两项特殊的回合行动指令。
D26: 诅咒：
D27: 消耗一个行动阶段发动，选择一名被自身详细侦查成功且未被诅咒过的御主全抗性受到[-20]的削减，这个状态将持续三天。
D28: 该行动的优先级高于袭击低于魂食。
D29: 献祭：
D30: 这个职业的御主每当杀死了其他御主的情况下，将可以令与自身契约的一名从者除[宝]以外的属性获得[+5]的[常驻补正]；
D31: 或消耗一个行动阶段发动，令自身的[耐]属性受到[-20]的常驻惩罚]，令与自身契约的一名从者除[宝]以外的属性获得[+5]的[常驻补正]。
B33: 技能资源库
B34: 基础技能 | K34: 特化技能
B35: 一般 | K35: 一般
B36: 名称： | C36: 枪械精通 A B C | E36: 类别： | F36: 一般 | H36: 使用时机： | I36: 初始工序 | K36: 名称： | L36: 八极拳 B | N36: 类别： | O36: 一般 | Q36: 使用时机： | R36: 初始工序
B37: 效果︰ | C37: 在[袭击]或[介入行动]的时候，无条件获得[+20/15/10]的胜率补正。 | K37: 效果︰ | L37: 选择对方战斗位上的一名御主发动，令其进行一次成功率=[自身上三维总和-目标上三维总和]的判定 在判定成功后，将会使目标强制退出战斗位，这个判定受[非精神系弱体耐性]的影响。
B39: 备注： | C39: 御主等级[30/20/10]可分别获得[A/B/C]等级。
B40: 名称： | C40: 情报优势 A B C | E40: 类别： | F40: 一般 | H40: 使用时机： | I40: 游戏第一天开始时
B41: 效果︰ | C41: 随机获得除自己以外最多[3/2/1]名[御主]的[详细侦查资料]以及[所在根据地]。 | K41: 名称： | L41: 投毒 B | N41: 类别： | O41: 一般 | Q41: 使用时机： | R41: 行动阶段
K42: 效果︰ | L42: 该技能在本次圣杯战争中只能使用一次，发动后选择以下其一发动。 ①消耗一个行动阶段，令一个灵脉上的全部[御主]受到一次成功率=[50]的[中毒]判定。 ②回合结束时发动，令自身所在灵脉除自身以外的全部[御主]直接[中毒]。
B43: 备注： | C43: 御主等级[35/25/15]可分别获得[A/B/C]等级。
...

Sheet 数值参考
A1: 御主等级 | B1: 可分配资源 | D1: 特性 | G1: 职业 | H1: 筋力： | I1: 耐力： | J1: 敏捷： | K1: 魔力： | L1: 幸运： | M1: 回路：
A2: 10 | B2: 12 | D2: 秩序-善 | G2: 魔术师 | H2: 0 | I2: 0 | J2: 0 | K2: 10 | L2: 0 | M2: 10
A3: 20 | B3: 16 | D3: 中立-善 | G3: 体术师 | H3: 15 | I3: 15 | J3: 15 | K3: 0 | L3: 0 | M3: 0
A4: 30 | B4: 20 | D4: 混沌-善 | G4: 异能者 | H4: 0 | I4: 0 | J4: 0 | K4: 0 | L4: 30 | M4: 0
A5: 40 | B5: 24 | D5: 秩序-中立 | G5: 代行者 | H5: 0 | I5: 15 | J5: 0 | K5: 15 | L5: 0 | M5: 0
D6: 中立-中庸 | H6: 0 | I6: 0 | J6: 0 | K6: 0 | L6: 0 | M6: 0
D7: 混沌-中立 | H7: 0 | I7: 0 | J7: 0 | K7: 0 | L7: 0 | M7: 0
D8: 秩序-邪 | H8: 0 | I8: 0 | J8: 0 | K8: 0 | L8: 0 | M8: 0
D9: 中立-邪 | H9: 0 | I9: 0 | J9: 0 | K9: 0 | L9: 0 | M9: 0
B10: / | D10: 混沌-邪 | H10: 0 | I10: 0 | J10: 0 | K10: 0 | L10: 0 | M10: 0
B11: / | D11: 秩序-狂 | H11: 0 | I11: 0 | J11: 0 | K11: 0 | L11: 0 | M11: 0
B12: / | D12: 中立-狂 | H12: 0 | I12: 0 | J12: 0 | K12: 0 | L12: 0 | M12: 0
B13: / | D13: 混沌-狂 | H13: 0 | I13: 0 | J13: 0 | K13: 0 | L13: 0 | M13: 0
B14: / | D14: 空 | H14: 0 | I14: 0 | J14: 0 | K14: 0 | L14: 0 | M14: 0
D15: 空 | H15: 0 | I15: 0 | J15: 0 | K15: 0 | L15: 0 | M15: 0
D16: 空 | H16: 0 | I16: 0 | J16: 0 | K16: 0 | L16: 0 | M16: 0
A17: 骰值1D8 | B17: 关系 | C17: 等级 | D17: 空 | H17: 0 | I17: 0 | J17: 0 | K17: 0 | L17: 0 | M17: 0
A18: / | B18: (态度) | C18: / | D18: 空 | H18: 0 | I18: 0 | J18: 0 | K18: 0 | L18: 0 | M18: 0
A19: 1 | B19: 友好 | C19: C | D19: 空 | H19: 0 | I19: 0 | J19: 0 | K19: 0 | L19: 0 | M19: 0
A20: 2 | B20: 亲切 | C20: B | D20: 空
A21: 3 | B21: 依赖 | C21: A | D21: 空
A22: 4 | B22: 独占欲 | C22: A | D22: 空 | G22: 等级转化资源
A23: 5 | B23: 轻蔑 | C23: C | D23: 空 | G23: EX | H23: 10
A24: 6 | B24: 敌视 | C24: B | D24: 空 | G24: A++ | H24: 9
A25: 7 | B25: 仇恨 | C25: A | D25: 空 | G25: A+ | H25: 7
A26: 8 | B26: 支配欲 | C26: A | D26: 空 | G26: A | H26: 5
D27: 空 | G27: B++ | H27: 8
D28: 空 | G28: B+ | H28: 6
D29: 空 | G29: B | H29: 4
D30: 空 | G30: C++ | H30: 7
D31: 空 | G31: C+ | H31: 5
D32: 空 | G32: C | H32: 3
D33: 空 | G33: D++ | H33: 6
D34: 空 | G34: D+ | H34: 4
G35: D | H35: 2
G36: E++ | H36: 5
G37: E+ | H37: 3
G38: E | H38: 1
