Workbook
Name 阵营: 數值參考!$C$3:$C$35

Sheet 说明
A1: 對應規則書︰2.05
A6: 更新记录
A7: 5 | B7: 自动化一部份的属性分配
B8: 加入看上去很酷的属性图
B9: 加入详细的圣遗物介绍
A10: 5.1 | B10: 加入特性(可选规则)用的格子
A11: 5.11 | B11: 只是加了一個職階技能的格子，方便特殊職階車卡。拜託普通職階不要填
A12: 5.2 | B12: 將特性這不會暴露，暴露後易被針對的效果移至角色卡下方，以便GM處理情報
B13: 為特性提供了實驗性質的效果槽，是否啟用自行向GM查詢
A14: 5.22 | B14: Berserker的基礎屬性調整，1.79以下的版本的參加者請注意
A15: 5.31 | B15: 六維圖修了修
B16: 技能效果多加了一行，讓說明有點複雜的技能不用整天拉長行數。但是說明超長的依然要拉長行數
A17: 5.4 | B17: 其實什麼都沒動，但為了對稱所以再發一版~
A18: 5.5 | B18: 這回真的有更動!寶具/技能的名稱格子長了!
B19: 遺物介紹的格子微調了
B20: 特性由原來的範例，改成一些針對性的問題，寫特性時請將這些問題納入考慮
B21: Avenger的基礎屬性確立，2.03以下的版本注意
B22: 雖然很丟人，但之前一直將貼圖鎖了....現在不解除保護也能貼圖了
B23: Lancer的基础属性调整，2.05以下的版本注意
A24: 6.0 | B24: 角色的屬性改成橫的，方便填表時右鍵
B25: 角色頭像可以放更大的了
B26: 陣營的位置改放到「角色經歷」
B27: 調整了一下排版，如無意外角卡可以用A4size印出來了
A28: 6.01 | B28: 有些排版出包了，調整完成。
A29: GM开团前「可」准备的事
A34: 在数值参考页面按自己特有的村规进行基础属性、点数的调整。或加入新职阶
A48: 本角色卡是为圣杯战争跑团准备的战斗计算表。
A49: 该圣杯战争跑团规则大部分采用了日本现在较流行的男爵圣杯规则作为基底，进行魔改的TRPG规则，在游戏上简约了战斗部分，以实际扮演为主体的游戏方式。
A51: 若有疑问可加群424815329查询

Sheet 角色卡 
C1: =C16+C17 -> 70 | D1: =D16+D17 -> 20 | E1: =E16+E17 -> 20 | F1: =F16+F17 -> 20 | G1: =G16+G17 -> 90 | H1: =H16+H17 -> 40 | I1: =I16+I17 -> 50
B2: 阵营 | E2: 外貌描述 | H2: 肖像 | K2: 资源上限 | L2: 特攻列表
B3: =角色經歷!B15 -> 混沌-中庸 | K3: 24 | L3: 职阶 | N3: =F10 -> Caster
L4: 灵基 | N4: =F11 -> 英灵
K5: 剩余资源 | L5: 阵营 | N5: =角色經歷!B15 -> 混沌-中庸
K6: =K3-IF(J18>0,K9,K9-J18/10) -> 0 | L6: 特性 | N6: =F12 -> 人型 | O6: =G12 -> 0
E7: 令咒 | L7: 时代 | N7: 未来
K8: 花费资源 | L8: 隐属 | N8: 人
K9: =J20+J29+J38+J48+J57+J66+T20+T29+T38+T48+T57+T66+K12 -> 24 | L9: 性别 | N9: =角色經歷!C27 -> 男
E10: 职阶 | F10: Caster | L10: 体型 | N10: =F13 -> 通常
E11: 灵基 | F11: 英灵 | K11: 扩容 | L11: 注释
E12: 特性 | F12: 人型 | K12: =H20+H29+H38+H48+H57+H66+R20+R29+R38+R48+R57+R66 -> 4 | L12: 特攻列表不会也不能为其他角色所获取。
E13: 体型 | F13: 通常
C14: 等级 | D14: 筋力 | E14: 耐久 | F14: 敏捷 | G14: 魔力 | H14: 幸运 | I14: 宝具 | J14: 属性点数
B15: 合计 | C15: =C16+C17+C18 -> 70 | D15: =D16+D17+D18 -> 20 | E15: =E16+E17+E18 -> 20 | F15: =F16+F17+F18 -> 20 | G15: =G16+G17+G18 -> 90 | H15: =H16+H17+H18 -> 60 | I15: =I16+I17+I18 -> 50 | J15: =20+C17*2 -> 160 | K15: 修正上限
B16: 职阶 | D16: =INDEX(數值參考!F2:M10,MATCH($F$10,數值參考!F2:F10,0),2) -> 0 | E16: =INDEX(數值參考!F2:M10,MATCH($F$10,數值參考!F2:F10,0),3) -> 0 | F16: =INDEX(數值參考!F2:M10,MATCH($F$10,數值參考!F2:F10,0),4) -> 0 | G16: =INDEX(數值參考!F2:M10,MATCH($F$10,數值參考!F2:F10,0),5) -> 30 | H16: =INDEX(數值參考!F2:M10,MATCH($F$10,數值參考!F2:F10,0),6) -> 0 | J16: =SUM(C16:I16) -> 30 | K16: 0
B17: 分配 | C17: 70 | D17: 20 | E17: 20 | F17: 20 | G17: 60 | H17: 40 | I17: 50 | J17: 剩余点数 | K17: 基础上限
B18: 补正 | H18: 20 | J18: =J15-D17-E17-F17-G17-H17 -> 0 | K18: 60
B19: 职阶技能 | L19: 宝具
B20: 模板 | C20: 阵地制造 | E20: 等级 | F20: E(本职) | G20: 扩容 | I20: 资源 | J20: =_xlfn.IFNA(VLOOKUP(F20,數值參考!$J$23:$K$38,2,FALSE),0) -> 0 | L20: 模板 | M20: 苍天已死，黄天当立 | O20: 等级 | P20: A | Q20: 扩容 | S20: 资源 | T20: =_xlfn.IFNA(VLOOKUP(P20,數值參考!$H$23:$I$38,2,FALSE),0) -> 5
B21: 名称 | E21: 类型 | F21: 职介 | H21: 回转 | I21: 3 | L21: 名称 | M21: 岁在甲子，天下大吉 | O21: 类型 | P21: 对军 | R21: 回转 | S21: 6
E22: 发动时机 | F22: 行动阶段 | H22: 魔力消耗 | I22: 20 | J22: =IF(F22="常驻","每日","每次") -> 每次 | O22: 发动时机 | P22: 战斗开始时 | R22: 魔力消耗 | S22: 60 | T22: =IF(P22="常驻","每日","每次") -> 每次
B23: 效果 | C23: 允许自身进行[阵地]的建设：消耗行动阶段发动，赋予当前灵脉[阵地][结阵 1]。 令[阵地]获得以下效果： 若当前灵脉不具有额外魔力池，则赋予当前灵脉基础上限为[0]的额外魔力池；每[结阵 1]，令此 额外魔力池上限[+20]。 [阵地]会在持有者不处于当前灵脉时摧毁。 自身在赋予[阵地][结阵]后，其层数至多为[结阵 5/4/3/2/1]。 轮次结束时，给予当前灵脉的额外魔力池以[持有者基础[魔力]属性]的魔力供给。 判定上，这个技能也视为[类型：魔术]。 | L23: 效果 | M23: [主力位] 解放后，使当前灵脉上的所有使魔在本场战斗中无效化，并且无效此灵脉外，获取当前灵脉信 息的效果，并给予双方[支援位]单位以[混乱 1]。 每个战斗工序开始时，自身和敌方主力位各可以从[灼伤][冻结][感电]中暗宣言一项。 若自身本场战斗内未暗宣言过这个状态，本工序内，每当敌方战斗位任一单位获得对应状态时 ，根据那个状态的类型执行对应效果： [灼伤]：给予敌方战斗位非支援位]全部单位[筋力][耐久]属性[-15]的属性惩罚，并令其立 即结算一次[灼伤]；战斗胜利时，额外令因此效果结算了灼伤的单位额外结算一次[灼伤]。 [冻结]：给予敌方战斗位非[支援位]全部单位[敏捷][魔力]属性[-15]的属性惩罚，战斗胜利 时，令其获得[抗性下降：-15%]，此抗性下降常时存在。 [感电]：给予敌方战斗位非[支援位]全部单位[幸运][宝具]属性[-15]的属性惩罚，最终工序 时，对受到此属性惩罚的单位造成[激荡]；战斗胜利时，令其立即产生[30]魔力消耗。 敌方主力位进行宣言且宣言状态与自身相同的场合下，本工序内此宝具效果失效。 敌方主力位进行宣言且宣言状态与自身不同的场合下，给予目标自身宣言的状态[3]层。 特别的，此宝具解放时，允许同灵脉其他从者单位支付[-]魔力，令此宝具效果仅在本次 解放效果上升[1]级。
B26: 背景 | C26: 作为以caster职阶降世的张角，其生前具有制造符水等史诗事迹，因此可以正大光明的拥有该项技能 张角的道具作成，本质是扎根于汉末濒死大地的巫仪，是《太平要术》篇章的活体实践，它剥离了传统魔术的优雅逻辑，蜕变为一种“以人愿为薪柴，炼化混沌奇迹”的原始，其产物“符水”，是救赎的圣物，也是灭顶的根源 张角无需魔术工坊，他的“作坊”是流民匍匐的荒野，可能是当时魔术并不流行，也有可能是环境过于恶劣，仅仅只需要寥寥数笔，便能够达到像当前顶级魔术师所绘制的魔术 书写符箓的黄麻纸，需在朔月之夜铺于饿殍横陈的战场，吸收怨为基底；朱砂必混入重病信徒的指尖血，这血液承载着对“黄天太平”的极致渴求，是将人类求生执念提纯为咒力萃取。笔锋游走时，他口诵《太平清领书》残章，九节杖尖震颤共鸣，令符文共鸣，将魔术与自然共鸣。强行运用自然力量为自己所用 一道雷符实为向苍穹劫掠电光的敕令，一纸雨符则是强征河伯泪水的檄文。， 盛载之器非金非玉，而是劈开的粗陶土瓮，所汲必是无根水，屋檐未落的雨滴，或深涧不触淤泥的寒泉，关键仪式在于焚符入水，张角将血书黄符悬于水面，九节杖引动地脉浊气化为幽蓝鬼火，舔舐符纸。火焰焚烧的不仅是纸张，更是信徒寄托其中的生命祈愿与痛苦记忆。灰烬落水瞬间，水面翻腾如沸，灰黄雾霭升腾凝结成模糊人形嘶嚎消散。最终，浑浊的符水沉淀出铁锈般的猩红絮状物，散发腐烂桃木与烈酒混合刺鼻气息。那些创痕也早已被封印于此符纸之中，待到作战之日，便可将其魂归敌军，将这些伤痛一一奉还给敌人 除符纸外，他大抵也会做一些别的魔术道具...只不过时代特殊，那个时候的人民需要什么，他便制造什么！倘若好好发挥自己的技巧，也可以在东汉末年争出一个名头。 只可惜，溯其本源，张角也只是一个不忍民生疾苦而自己又无大力足以一人救苍生之人罢了 | L26: 背景 | M26: ，“苍天已死″ 那并非预言。是浸透九节杖的百万病民之泪，是焚烧三万卷《太平清领书》升腾的符灰之云，是自中原大地上每一具饿殍瞳仁中映出的、对「失道昊天」的共业裁决。当杖头青铜铃舌震碎雒阳观星的玉圭，汉火德之运便随裂痕没入龟甲灼焦的谶纬。 “黄天当立″ 其人所布之道，乃以《太平要术》为枢，将冀州麦田龟裂的地怨、弃婴襁褓中的寒啼、易子而食者喉头的血沫，与对「昏聩苍穹」的万民之诅，凝结为九霄垂落的三十六方青词雷檄。他非僭越者，是代行「黄神」威权的末法祝史。 何事之人？令「祈雨」的祝舞化作引动旱蝗的步罡，使「祷安」的章表咒为焚毁宫观的阴火。当竹简丹书在祭坛爆裂，篆文便成刺入州郡文脉的咒针 他所布阵之处，星官失序。文昌星坠入黄河泛滥的浊流，灵龟卜甲在雷声中绽出「甲子大凶」的阴纹，蓍草散作飘向钜鹿战场的纸钱。地脉中奔涌的不复清流，而是裹挟符灰与尸碱的“黄泉浊流” 若问“苍天″何罪之有？凭谁问？“此苍生又何罪之有呢″ 蔽日蝗群是其行军的玄旗，翅浪翻涌声是撕裂《白虎通》的徵之音；千里赤地是其铺展的祭坛，皲裂的土壳下浮出颠覆州郡界碑的咒蛭。 每一粒飞沙皆拓印着「天下大吉」的镜书反字，随东风卷入未央宫椒壁，将「汉」字蚀成中空的墓志。 其宝具显现之刻—— 苍穹倾覆为蒸煮礼乐的巨甑，层云翻卷似十万张飘荡的度死符。撕裂暮色的紫电非天之怒，乃地肺中淤积的疠气遇劫火而化的赤霄九云 当黄麻符巾漫过长安神明台，以流民肠中的观音土为祭米，以冻毙者眉睫的霜晶为盐卤，焚尽太史令掌中的受命玉牒，终在残烬上塑起蜃楼般的「中黄太乙」坛场。 至此，将那一切的祸患，将那一切的因果，如数奉还至那不顾苍生的「愚代」统治者之上 风雷云起，水火交加，普天象地，万物宗萎 此即大贤良师所求？ 或仅是那根汲尽人间离乱的九节杖，在张角脊骨弯作祭弓后，以黄河决堤的地鸣为阵地，为旧世界献上的罢黜禳业！
B29: 模板 | C29: 道具制作 | E29: 等级 | F29: E(本职) | G29: 扩容 | I29: 资源 | J29: =_xlfn.IFNA(VLOOKUP(F29,數值參考!$J$23:$K$38,2,FALSE),0) -> 0 | L29: 模板 | M29: 神威车轮 | O29: 等级 | P29: B | Q29: 扩容 | R29: 2 | S29: 资源 | T29: =_xlfn.IFNA(VLOOKUP(P29,數值參考!$H$23:$I$38,2,FALSE),0) -> 4
B30: 名称 | E30: 类型 | F30: 职阶 | H30: 回转 | I30: 0 | L30: 名称 | M30: 三公将军·供颂太平之道 | O30: 类型 | P30: 对人 | R30: 回转 | S30: 0
E31: 发动时机 | F31: 常驻 | H31: 魔力消耗 | I31: 0 | J31: =IF(F31="常驻","每日","每次") -> 每日 | O31: 发动时机 | P31: 常驻 | R31: 魔力消耗 | S31: 20 | T31: =IF(P31="常驻","每日","每次") -> 每日
B32: 效果 | C32: 建卡时，从辅助礼装、限定礼装中选择任[-]种礼装记录。 允许持有者进行[礼装制作]，以此方式进行的[礼装制作]仅可制作基础礼装，以及此技能记录的 礼装。 自身每轮次[发动礼装次数上限][+13/11/9/7/5]。 判定上，这个技能也视为[类型：魔术]。 | L32: 效果 | M32: [骑乘] 此宝具无法以特殊等级获取，且仅能在建卡时获取。 自身发动技能或解放宝具时，令受到那个技能或宝具效果影响的全部单位获得[感电 1]。若自身 在战斗中处于[主力位]，则己方所有单位的技能与宝具同样享受上述效果。 此宝具等级达到B时，战斗中，每工序开始时，给予敌方[主力位]单位[感电 1]。此效果在自身发 起成功的[冲锋]判定时，改为给予敌方非[支援位]全部单位[感电 1]。
B35: 背景 | C35: 作为以caster职阶，阵地制作与道具做成一直是双生相伴的，因此极具职阶适配性的张角便能够获得较高等级的阵地制造 太平祈坛，严格遵循早期道教“法天象地”的仪轨。当九节杖轻触大地，杖首二十八枚铜环应和周天星宿之位震响时，一方调和阴阳的临时圣域便悄然展开。 星斗为图，地脉为络 阵地无需破坏地表。张角踏禹步巡游，步伐暗合洛书轨迹，所过之处地面自然浮现银白色光纹，此乃引动地底灵脉透出的“精气显化”。光纹交织成三层圆坛。外坛浮现八卦卦象，对应八风方位，中坛环绕二十八宿星图，星光虚影浮空三寸，内坛中心隆起微光土台，九节杖植立其上如“建木天梯” 整个祭坛笼罩在薄纱般的青金色雾霭中，散发柏叶与冷泉的清气。令人倾心舒适 阵地本质是放大张角沟通天地之力的媒介，坛内风雨温顺，云气随咒文聚散。张角可小范围调节天候，星图光纹能梳理紊乱的地脉精气，平息轻微地动，使草木焕发生机。踏入阵地的伤者会感到疲惫稍减，因大地精气在温和滋养血肉，书写的符箓在坛内自动汲取游离天地精气，威能提升却更趋稳定。一道“清风符”可化柔风托起坠鸟，“甘霖符”能唤来清甜雨露解渴 而当张角与祭坛中心进行作法，书写雷符时。九节杖顶自动汇聚青白色电光。中坛苍龙星图逐一亮起，云层中传来沉闷龙吟般的滚雷声。阵法将地脉精气升腾为“雷种”，引动大气电荷碰撞，最终从杖顶迸射出一道曲折电蛇劈向目标。此非天罚，而是众民所望！ | L35: 背景 | M35: “苍天已死，黄天当立！岁在甲子，天下大吉！” 这撼动东汉根基的呐喊，是百万黄巾的怒吼，更是张角与两位胞弟张宝、张梁以血脉为纽带，以信仰为誓约，共同谱写的太平序曲。张角为“天公将军”，掌天道，定方向，张宝为“地公将军”，安营扎寨，固守根本，张梁为“人公将军”，统御部众，冲锋陷阵。三兄弟各司其职，缺一不可，共同构成了太平道这艘巨舰的“黄天三柱″
B38: 模板 | E38: 等级 | G38: 扩容 | I38: 资源 | J38: =_xlfn.IFNA(VLOOKUP(F38,數值參考!$J$23:$K$38,2,FALSE),0) -> 0 | L38: 模板 | M38: 勇往直前·俱利伽罗岭 | O38: 等级 | P38: C | Q38: 扩容 | R38: 2 | S38: 资源 | T38: =_xlfn.IFNA(VLOOKUP(P38,數值參考!$H$23:$I$38,2,FALSE),0) -> 3
B39: 名称 | E39: 类型 | H39: 回转 | L39: 名称 | M39: 辉煌的旧梦，予那万民之黄天 | O39: 类型 | P39: 对军 | R39: 回转 | S39: 9
E40: 发动时机 | H40: 魔力消耗 | O40: 发动时机 | P40: 战斗开始时 | R40: 魔力消耗 | S40: 60 | T40: =IF(P40="常驻","每日","每次") -> 每次
B41: 效果 | L41: 效果 | M41: [主力位] 赋予当前灵脉[固有结界：俱利伽罗岭]。 [固有结界：俱利伽罗岭 | 灵脉宽度：7 | 魔力量：0 | 人流量：0 | 昼夜规律：永夜] 赋予此固有结界以下效果： 本场战斗中，双方战斗位单位无法在初始工序撤退。 每工序开始时，召唤至多[2]个等级＝[40]，具有除[宝具]外[10]全属性的[召唤物]。此[召唤物] 总是在战斗结束或被敌方技能宝具效果影响时退场。 每工序结束时，允许此宝具持有者宣言指定敌方任一单位，令己方战斗位上由此宝具产生的[召 唤物]对指定目标各发起一次成功率[45%]的负面判定，判定成功时给予目标除[宝具]外 任一属性[-5]属性惩罚以及[灼伤 1]。无论判定是否成功，这之后，发起了判定的[召唤物]将立即 退场。 最终工序时，己方战斗位上每存在一个此宝具产生的[召唤物]，给予敌方战斗位单位[灼伤 1]， 并令此宝具带来的所有[召唤物]退场。 这之后，允许追加宣言一枚令咒，给予敌方战斗位全部单位[筋力][耐久][敏捷]三项属性[-30]属 性惩罚并[爆燃]。若自阵营不持有[令咒]，则此效果无需支付令咒也能生效，但不会造成属性惩 罚。
B44: 背景 | L44: 背景 | M44: 钜鹿人士，姓张单名一个角字。 本也是读书种子，手不释卷，求的是功名仕进。 怎奈世道浑浊，疫气横行 白骨露于野，千里无鸡鸣 一卷《太平经》悄然入手 从此心窍顿开，别见洞天 不再仰望庙堂之高， 转而俯身泥土之深。 施符水，愈沉疴，解厄难， 足迹踏遍冀、青、幽、徐。 虽是布衣之身，却被万千黎庶唤作“大贤良师″ 田间地头，符水化入浑浊的井泉， 驱散病痛，也驱散对“天命”的愚昧敬畏。 市井闾巷，低语如风， “苍天已死”的偈言，在冻僵的耳廓间传递暖意。 夜聚晓散，草鞋踏过霜露浸透的田埂， 三十六方渠帅，眼中映着同一片，黄天的幻影。 那是何等纯粹的旧梦 “老有所终，壮有所用，幼有所长，鳏寡孤独废疾者皆有所养！″ 那朱门里倾倒的馊酒， 足以养活整村饥肠辘辘的孩童； 那豪强圈占的沃土， 原是百姓安身立命的祖产。 那高坐明堂的天子， 眼中何曾有过蝼蚁般的草民？ 其实自己心中雪亮， 这胸中的愤懑不平，早已如地火奔涌。 即便如此。 当那世家豪奴的鞭子， 再一次抽在佝偻老者的背上， 当那催缴赋税的铜锣， 又一次敲碎贫户最后一丝希望， 他站在高台之上，振臂一呼： “苍天已死，黄天当立！” 早已看穿了这王朝的末路。 腐朽如千疮百孔的老树， 根基尽烂，只待一阵狂风。 奉承大道之意， 身负革鼎之命， 聚三十六方，裹黄巾百万， 欲扫清寰宇，再造一个太平人间。 星星之火，可以燎原 其势可追昔日陈胜、吴广之呐喊 何其壮阔的愿景， 必须点燃的烽烟！ 他的一言可令州郡震恐， 他的符水能聚百万雄兵。 乃是纵为官吏、豪强、高高在上的天子， 亦不可等闲视之的燎原野火。 乃是心腹大患。 必须剿灭， 决不能容其星火蔓延。 当那甲子年的日头升起， 当那“岁在甲子，天下大吉”的号角， 由 百万草芥之喉 同声嘶吼， 这旧梦， 便不再是虚妄的泡影 化作焚烧官廨、砸碎枷锁的粗粝拳头， 化作农妇手中缝制的 杏黄大旗， 化作童子递向义军的那碗 混着泥土的清水。 焚尽腐朽的“苍天”， 予那被践踏、被遗忘的万民， 一个 触手可及、煌煌如日的崭新人间！ 其势... 足令巍巍雒阳为之动摇， 足令衮衮诸公魂飞魄散！ 何其壮烈的幻梦， 必须实现的夙愿！ 它的一粒火星可引动山呼海啸， 它的一道符箓能聚起移山填海之伟力。 乃是纵为帝王、将相、食肉吮髓的世家门阀， 亦不可直视、不可阻挡的 民心之怒涛 乃是倾覆乾坤的狂澜。 必须扑灭， 必须将其扼杀于襁褓
B47: 保有技能 | L47: 礼装
B48: 模板 | E48: 等级 | F48: C | G48: 扩容 | I48: 资源 | J48: =_xlfn.IFNA(VLOOKUP(F48,數值參考!$F$23:$G$38,2,FALSE),0) -> 3 | L48: 模板 | O48: 等级 | P48: / | Q48: 扩容 | S48: 资源
B49: 名称 | C49: 太平要术 | E49: 类型 | F49: 兵器 | H49: 回转 | I49: 3 | L49: 名称 | O49: 类型 | R49: 回转
E50: 发动时机 | F50: 随时 | H50: 魔力消耗 | I50: 15 | J50: =IF(F50="常驻","每日","每次") -> 每次 | O50: 发动时机 | R50: 魔力消耗
B51: 效果 | C51: 令目标进行一次成功率=[30%]的[灼伤]判定，成功的场合下给予目标[灼伤 1D5/4/3]。 令目标进行一次成功率=[30%]的[感电]判定，成功的场合下给予目标[感电 1D5/4/3]。 令目标进行一次成功率=[30%]的[冻结]判定，成功的场合下给予目标[冻结 1D5/4/3]。 自身参与的战斗中，[灼伤][感电][冻结]中任一状态首次被给予给战斗位上单位时，此技能立刻获 得 1 回转。 | L51: 效果 | M51: （建卡时，从者无法持有礼装）
B54: 背景 | C54: 《太平经》融合了道家哲学（尤其是黄老思想)、阴阳五行学说、神仙方术、迷信以及一些原始的社会政治理想，其核心思想是追求太平世界，这是一个没有灾异、疾病、战争、剥削，万物和谐共生，君主贤明，人民安居乐业的理想社会状态 而所谓的太平要术，便是张角运用《太平经》之中的内容，所提炼而出自我额外衍生的衍生变体 其理论根基源自《太平经》：“人为恶，灾及草木，咎返己身” 张角通过符咒与步罡，将目标此生累积的“业障”逐渐的渐渐演化为具象的“三才失衡”，层层叠加终致“天道″反噬 《第一印:地符》 张角以九节杖点地画“地裂符”，唤醒脚下地脉中被其践踏的怨念，符纹将引动淤塞的地气缠绕其足踝 ，移动时拖拽可见的浊黄色地煞之气，步伐沉重如陷沼泽 “坤德厚载，然暴虐者失其承天资格”。 《第二印:火符》 张角甩出朱砂书就的“回禄符”贴附其兵器或术式。此符将对方外泄的功击转化为反噬心火效果，受击者伤口浮现灼热赤斑，使体内阳气暴躁体内阳气暴走，进而引发情绪愈狂躁，脏腑灼痛愈烈 “离火本明，然凶戾者引焰焚心”。 《第三印:水符》 当张角脚踏坎位时，可诵《解厄经》 "祸福无门，惟人自召；善恶之报，如影随形″ 九节杖引积雨云笼罩目标。将汇聚恶念降下酸蚀性黑雨，雨水触及皮肤处生成幽蓝色纹路，持续腐蚀身体且破坏目标魔术回路，腐蚀铁器 “玄冥主生，然贪婪者自绝甘露”。 《三才锁咎:雷罚》 当三种印记同时存在，张角将九节杖倒插入地，发动《太平要术》“代天行咎” 天空降下三道昏黄光柱钉住印记， 引土石绊其足，令攻击灼伤己身，将恢复反效为毒 除此之外，三符化一，将引渡天雷，将战场瞬息万变 | L54: 背景
...

Sheet 角色經歷
B2: 最能代表角色的一句话: | L2: 角色之核心人設
B3: “跪天跪地，不跪腐汉！黄巾覆额之日，便是万民站起来之时！” | L3: 张角我觉得他个人应该是一种真正为民发声的一种形象吧，因为在那个乱世三国当中，真正能够抚恤民众的很少 因为无论是魏蜀吴还是后面的晋，都是以自己的理由，就是他们的并不是真正的为了一个群众，而是都有自己的一个欲望，在整个三国时期 我个人认为张角是我一个比较喜欢的人物吧，只可惜这个人物最后的结局是悲哀的 然而在目前三国演义当中，张角一直是偏反派的人物，因为他们起家都是靠打反叛的，小时候不懂 长大了之后才会真的懂张角这个人物的核心内在，就是张角他是一个我个人觉得有点悲剧，但是又不是特别悲剧，他有曾经像陈胜吴广一样的勇气，却只是在这乱世之中，给了百姓希望，却不能给百姓一个好的结果 很喜欢之前那句话就是你平时都饿着的百姓是怎么去打那些精兵良将
B6: 职阶 | C6: 灵基 | D6: 等级 | E6: 筋力 | F6: 耐力 | G6: 敏捷 | H6: 魔力 | I6: 幸运 | J6: 宝具
B7: ='角色卡 '!F10 -> Caster | C7: 英灵 | D7: ='角色卡 '!C15 -> 70 | E7: =_xlfn.IFS('角色卡 '!$D$15<21,"E",'角色卡 '!$D$15<41,"D",'角色卡 '!$D$15<61,"C",'角色卡 '!$D$15<81,"B",'角色卡 '!$D$15<101,"A",'角色卡 '!$D$15<121,"A+",'角色卡 '!$D$15>120,"EX") -> E | F7: =_xlfn.IFS('角色卡 '!$E$15<21,"E",'角色卡 '!$E$15<41,"D",'角色卡 '!$E$15<61,"C",'角色卡 '!$E$15<81,"B",'角色卡 '!$E$15<101,"A",'角色卡 '!$E$15<121,"A+",'角色卡 '!$E$15>120,"EX") -> E | G7: =_xlfn.IFS('角色卡 '!$F$15<21,"E",'角色卡 '!$F$15<41,"D",'角色卡 '!$F$15<61,"C",'角色卡 '!$F$15<81,"B",'角色卡 '!$F$15<101,"A",'角色卡 '!$F$15<121,"A+",'角色卡 '!$F$15>120,"EX") -> E | H7: =_xlfn.IFS('角色卡 '!$G$15<21,"E",'角色卡 '!$G$15<41,"D",'角色卡 '!$G$15<61,"C",'角色卡 '!$G$15<81,"B",'角色卡 '!$G$15<101,"A",'角色卡 '!$G$15<121,"A+",'角色卡 '!$G$15>120,"EX") -> A | I7: =_xlfn.IFS('角色卡 '!$H$15<21,"E",'角色卡 '!$H$15<41,"D",'角色卡 '!$H$15<61,"C",'角色卡 '!$H$15<81,"B",'角色卡 '!$H$15<101,"A",'角色卡 '!$H$15<121,"A+",'角色卡 '!$H$15>120,"EX") -> C | J7: =_xlfn.IFS('角色卡 '!$I$15<11,"E",'角色卡 '!$I$15<21,"D",'角色卡 '!$I$15<31,"C",'角色卡 '!$I$15<41,"B",'角色卡 '!$I$15<51,"A",'角色卡 '!$I$15<56,"A+",'角色卡 '!$I$15>55,"EX") -> A
B8: 性别 | C8: =C27 -> 男 | E8: 样貌特点
B9: 身高 | C9: 170 | E9: 一个普通的黄袍道士
B10: 体重 | C10: 57
B11: 玩家 | E11: 喜好事物
B12: 天海 | E12: 宗教与神秘学
B14: 阵营 | E14: 厌恶事物
B15: 混沌-中庸 | E15: 腐败的统治者，传统的儒家学说，背叛与怀疑
B17: 图片 | E17: 圣遗物评级
E18: Euclid
E19: 名称
E21: 地域
E22: 年代
E23: 外观
E24: 出产地点
B25: 真名 | C25: 张角 | E25: 英灵愿望 | L25: 你希望拥有怎样的御主？在什么情况下你可能会违背御主的命令？
B26: 职业 | C26: 道士 | E26: 为了让天底下百姓能够得到一个太平盛世，倘若现在已经是太平盛世 便可放弃 | L26: 与自己观念一致
B27: 性别 | C27: 男
B28: 国家 | C28: 东汉末年
B29: 信仰 | L29: 你在战斗中会以怎样的姿态面对你的对手？
B30: 典出 | L30: 如同对待当时的
B31: 角色资料
B32: 张角（？—184年），冀州巨鹿（今河北平乡西南）人，[30]是道教领袖[54]，东汉末年太平道首领、“黄巾起义”领导人，自号大贤良师、天公将军。[1][3] 张角出身巨鹿，[30]最初以传授弟子法术和咒语，创立了太平道，后来通过符水治疗病人，结交十常侍为内应[38]，以传道和治病为名，在农民中宣扬教义，进行秘密活动[30]。在青（今山东西北、胶东）、徐（今山东南部、江苏、长江以北）、幽（今河北东部、辽宁）、冀（今河北中部、南部）等八州发展了数十万信徒。[1]随后张角整编信徒，在各地传布口号，预谋起事。[3]中平元年（184年），在渠帅马元义谋划起事被杀后，张角发动“黄巾起义”，号召三十六万部众同日起事。但不久张角便被北中郎将卢植打败，逼得退守广宗（今河北威县东），并于同年秋冬间身亡。[2][3][31] 张角生平主要事迹便是创立太平道和发动“黄巾起义”。[4]他创立的太平道，被视作道教的正式开端，甚至深深影响着后世道教的发展。[5]而“黄巾起义”，则是中国历史上第一次以宗教形式发动的农民起义运动，它沉重打击东汉王朝的统治秩序，造就了东汉末年军阀割据的局面，最终导致了东汉王朝的覆灭。[10]
L33: 你认为友谊是什么？你愿意把后背托付给怎么样的战友？
L34: 友谊便是盟友，便是值得信任的伙伴
L37: 此空白留给GM为了更好理解你扮演的角色而给出询问
B40: 职阶适性
B41: 都道士了，肯定能当c | L41: 此空白留给GM为了更好理解你扮演的角色而给出询问
B44: 英灵原则
B45: 不动平民百姓一分一毫 | L45: 此空白留给GM为了更好理解你扮演的角色而给出询问
B49: 下方的效果将严重影响角色方针，请自行填写描述，由GM决定具体效果
B50: 特性: | C50: （例：无尽的强制）
B51: 效果︰ | C51: （例：执行[机动]的回合内作为袭击方参与战斗时将额外获得[+5%]的胜率补正）
B52: 描述︰ | C52: （例：你的角色无论如何都不会放弃圣杯，将会用尽一切手段攻击其他可能的阻碍者或在战斗中胜出）

Sheet 建卡用参考资源
B1: *仅包含常用资源
B2: 职阶 | D2: 基础属性 | J2: 职阶奖励与特性
B3: Saber | D3: 属性 | E3: 筋力 | F3: 耐久 | G3: 敏捷 | H3: 魔力 | I3: 幸运 | J3: [对魔力]上升一级。
D4: 点数 | E4: 20 | F4: 20 | G4: 20 | H4: 10 | I4: 0
B5: Lancer | D5: 属性 | E5: 筋力 | F5: 耐久 | G5: 敏捷 | H5: 魔力 | I5: 幸运 | J5: [对魔力]上升一级。
D6: 点数 | E6: 15 | F6: 15 | G6: 30 | H6: 0 | I6: 0 | J6: 需要主动释放且[类型：对人宝具]的宝具所消耗的魔力降低10点。
B7: Archer | D7: 属性 | E7: 筋力 | F7: 耐久 | G7: 敏捷 | H7: 魔力 | I7: 幸运 | J7: 从[对魔力]或[单独行动]中，择一项上升一级。
D8: 点数 | E8: 15 | F8: 15 | G8: 20 | H8: 0 | I8: 0
B9: Rider | D9: 属性 | E9: 筋力 | F9: 耐久 | G9: 敏捷 | H9: 魔力 | I9: 幸运 | J9: 从[对魔力]或[骑乘]中，择一项上升一级。
D10: 点数 | E10: 10 | F10: 10 | G10: 10 | H10: 0 | I10: 0
B11: Caster | D11: 属性 | E11: 筋力 | F11: 耐久 | G11: 敏捷 | H11: 魔力 | I11: 幸运 | J11: 从[阵地制作]或[道具制作]中，择一项上升一级。
D12: 点数 | E12: 0 | F12: 0 | G12: 0 | H12: 30 | I12: 0
B13: Assassin | D13: 属性 | E13: 筋力 | F13: 耐久 | G13: 敏捷 | H13: 魔力 | I13: 幸运 | J13: [气息遮蔽]上升一级。
D14: 点数 | E14: 0 | F14: 0 | G14: 30 | H14: 0 | I14: 0
B15: Berserker | D15: 属性 | E15: 筋力 | F15: 耐久 | G15: 敏捷 | H15: 魔力 | I15: 幸运 | J15: [狂化]可选择是否上升或下降一级。
D16: 点数 | E16: 15 | F16: 15 | G16: 0 | H16: 0 | I16: 0 | J16: 除了 EX 级别的狂化外，B 等级以上的狂化解放宝具时，
J17: 需额外消耗一枚令咒才能解放。(该枚令咒将视为胜率补正消耗)。
B19: 技能资源库
B20: 基础技能
B21: 一般 | K21: 一般
B22: 名称： | C22: 枪械精通 A B C | E22: 类别： | F22: 一般 | H22: 使用时机： | I22: 初始工序 | K22: 名称： | L22: 八极拳 B | N22: 类别： | O22: 一般 | Q22: 使用时机： | R22: 初始工序
B23: 效果︰ | C23: 在[袭击]或[介入行动]的时候，无条件获得[+20/15/10]的胜率补正。 | K23: 效果︰ | L23: 选择对方战斗位上的一名御主发动，令其进行一次成功率=[自身上三维总和-目标上三维总和]的判定 在判定成功后，将会使目标强制退出战斗位，这个判定受[非精神系弱体耐性]的影响。
B25: 备注： | C25: 御主等级[30/20/10]可分别获得[A/B/C]等级。
B26: 名称： | C26: 情报优势 A B C | E26: 类别： | F26: 一般 | H26: 使用时机： | I26: 游戏第一天开始时
B27: 效果︰ | C27: 随机获得除自己以外最多[3/2/1]名[御主]的[详细侦查资料]以及[所在根据地]。 | K27: 名称： | L27: 投毒 B | N27: 类别： | O27: 一般 | Q27: 使用时机： | R27: 行动阶段
K28: 效果︰ | L28: 该技能在本次圣杯战争中只能使用一次，发动后选择以下其一发动。 ①消耗一个行动阶段，令一个灵脉上的全部[御主]受到一次成功率=[50]的[中毒]判定。 ②回合结束时发动，令自身所在灵脉除自身以外的全部[御主]直接[中毒]。
B29: 备注： | C29: 御主等级[35/25/15]可分别获得[A/B/C]等级。
B30: 名称： | C30: 武术（剑术） A B C | E30: 类别： | F30: 一般 | H30: 使用时机： | I30: 主要工序
B31: 效果︰ | C31: 给予自身[筋力 [耐久]、[敏捷]其中一项获得[+15/+10/+5]的属性补正。
K32: 魔术
B33: 备注： | C33: 御主上三维属性的总和[70/50/30]可分别获得[A/B/C]等级。 | K33: 名称： | L33: 宝石魔术 B | N33: 类别： | O33: 魔术 | Q33: 使用时机： | R33: 最终工序
B34: 魔术 | K34: 效果︰ | L34: 消耗任意一个礼装后发动，给予对方[-20]的胜率惩罚。
B35: 名称： | C35: 魔术 A B C | E35: 类别： | F35: 魔术 | H35: 使用时机： | I35: 主要工序
B36: 效果︰ | C36: 有使用[魔力]作为战斗属性的场合，给予敌方[-20/15/10]的胜率惩罚。 | K36: 名称： | L36: 死灵魔术 B | N36: 类别： | O36: 魔术 | Q36: 使用时机： | R36: 常驻
K37: 效果︰ | L37: 自身[人偶]的制作方式改变为[杀死一名御主]或[进行一次成功的魂食]，但自身的[人偶]将可以复数存在， 且自身的人偶无论数量多少，都将会在战斗时将所有人偶的属性叠加在一起并视为一个单位。
B38: 备注： | C38: 御主的[魔]达到[35/25/15]可分别获得[A/B/C]等级。
B39: 名称： | C39: 炼金魔术 A B C | E39: 类别： | F39: 魔术 | H39: 使用时机： | I39: 常驻
B40: 效果︰ | C40: 自身在制作礼装时，将会获得[+25/20/15]的[成功率补正]。 并且在制作礼装时，若出目数在[5]以下时，则这一次制作成功的礼装视为[2]份。
K41: 备注： | L41: 利用[魂食]进行[人偶制作]时，在成功时将无法获取相对应的魔力。
B42: 备注： | C42: 御主的[魔]达到[35/25/15]可分别获得[A/B/C]等级。 | K42: 名称： | L42: 妨碍傀儡 A | N42: 类别： | O42: 魔术 | Q42: 使用时机： | R42: 战斗前
...

Sheet 技能&宝具资源库
A1: 技能资源列表 | I1: 宝具资源列表
A2: 模板 | B2: 类型 | C2: 时机 | D2: 等级 | E2: 资源 | F2: 回转 | G2: 魔耗 | H2: 效果 | I2: 模板 | J2: 类型 | K2: 时机 | L2: 等级 | M2: 资源 | N2: 回转 | O2: 魔耗 | P2: 效果
A3: 对魔力 | B3: 职介 | C3: 技能发动时 | D3: E | E3: 1 | F3: 1 | G3: 1 | H3: [反击][支援] 当自身成为此技能等级相同或以下的[类型：魔术]技能的效果对象，或受到其效果影响时可以发动，令那个技能对自身可能生效的效果无效，且不会返还发动消耗。
A4: 对魔力 | B4: 职介 | C4: 技能发动时 | D4: D | E4: 2 | F4: 1 | G4: 1 | H4: [反击][支援] 当自身成为此技能等级相同或以下的[类型：魔术]技能的效果对象，或受到其效果影响时可以发动，令那个技能对自身可能生效的效果无效，且不会返还发动消耗。
A5: 对魔力 | B5: 职介 | C5: 技能发动时 | D5: C | E5: 3 | F5: 1 | G5: 1 | H5: [反击][支援] 当自身成为此技能等级相同或以下的[类型：魔术]技能的效果对象，或受到其效果影响时可以发动，令那个技能对自身可能生效的效果无效，且不会返还发动消耗。
A6: 对魔力 | B6: 职介 | C6: 技能发动时 | D6: B | E6: 4 | F6: 1 | G6: 1 | H6: [反击][支援] 当自身成为此技能等级相同或以下的[类型：魔术]技能的效果对象，或受到其效果影响时可以发动，令那个技能对自身可能生效的效果无效，且不会返还发动消耗。
A7: 对魔力 | B7: 职介 | C7: 技能发动时 | D7: A | E7: 5 | F7: 1 | G7: 1 | H7: [反击][支援] 当自身成为此技能等级相同或以下的[类型：魔术]技能的效果对象，或受到其效果影响时可以发动，令那个技能对自身可能生效的效果无效，且不会返还发动消耗。
A8: 骑乘 | B8: 职介 | C8: 常驻 | D8: E | E8: 1 | F8: 0 | G8: 0 | H8: 自身具有[骑乘]的技能或宝具生效时，给予自身[+10%]的胜率补正。
A9: 骑乘 | B9: 职介 | C9: 常驻 | D9: D | E9: 2 | F9: 0 | G9: 0 | H9: 自身具有[骑乘]的技能或宝具生效时，给予自身[+20%]的胜率补正。
A10: 骑乘 | B10: 职介 | C10: 常驻 | D10: C | E10: 3 | F10: 0 | G10: 0 | H10: 自身具有[骑乘]的技能或宝具生效时，给予自身[+30%]的胜率补正。
A11: 骑乘 | B11: 职介 | C11: 常驻 | D11: B | E11: 4 | F11: 0 | G11: 0 | H11: 自身具有[骑乘]的技能或宝具生效时，给予自身[+40%]的胜率补正。
A12: 骑乘 | B12: 职介 | C12: 常驻 | D12: A | E12: 5 | F12: 0 | G12: 0 | H12: 自身具有[骑乘]的技能或宝具生效时，给予自身[+50%]的胜率补正。
A13: 单独行动 | B13: 职介 | C13: 常驻 | D13: E | E13: 1 | F13: 0 | G13: 0 | H13: 自身进行广泛侦查时，额外获得[+10%]的最终成功率补正。 自身魔力下限改为[-200]，魔力不足惩罚改为每达到[-20]，全属性将受到[-5]的惩罚。 御主死亡或与御主解除[圣杯契约]后仍可以存活[1]天，在此期间将不结算待机耗魔，但亦无法获得来自[灵脉]或[圣杯]的供魔。 魔力不足达到下限或剩余回合数不足时将会消灭。
A14: 单独行动 | B14: 职介 | C14: 常驻 | D14: D | E14: 2 | F14: 0 | G14: 0 | H14: 自身进行广泛侦查时，额外获得[+20%]的最终成功率补正。 自身魔力下限改为[-200]，魔力不足惩罚改为每达到[-20]，全属性将受到[-5]的惩罚。 御主死亡或与御主解除[圣杯契约]后仍可以存活[2]天，在此期间将不结算待机耗魔，但亦无法获得来自[灵脉]或[圣杯]的供魔。 魔力不足达到下限或剩余回合数不足时将会消灭。
... A68: 魔力放出 | B68: 技艺 | C68: 随时 | D68: C | E68: 3 | F68: 1 | G68: 5 | H68: 给予自身的[筋力][耐久][敏捷]当中的任一项属性[+5]的常驻补正与[+10%]的胜率补正。 这个技能带来的常驻补正将会在回合结束时失去。
D69: B | E69: 4 | F69: 1 | G69: 10 | H69: 给予自身的[筋力][耐久][敏捷]当中的任一项属性[+10]的常驻补正与[+10%]的胜率补正。 这个技能带来的常驻补正将会在回合结束时失去。
D70: A | E70: 5 | F70: 1 | G70: 15 | H70: 给予自身的[筋力][耐久][敏捷]当中的任一项属性[+15]的常驻补正与[+10%]的胜率补正。 这个技能带来的常驻补正将会在回合结束时失去。
A71: 军略 | B71: 技艺 | C71: 常驻 | D71: E | E71: 1 | F71: 0 | G71: 0 | H71: [主力位] 自身[战术]未被克制时才能生效。 我方发动[对军宝具]时，给予自身[+5%]的胜率补正。 自身[战术]克制敌方，且在敌方发动[对军宝具]时，给予自身[+5%]的胜率补正。
C72: 常驻 | D72: D | E72: 2 | F72: 0 | G72: 0 | H72: [主力位] 自身[战术]未被克制时才能生效。 我方发动[对军宝具]时，给予自身[+10%]的胜率补正。 自身[战术]克制敌方，且在敌方发动[对军宝具]时，给予自身[+10%]的胜率补正。
C73: 常驻 | D73: C | E73: 3 | F73: 0 | G73: 0 | H73: [主力位] 自身[战术]未被克制时才能生效。 我方发动[对军宝具]时，给予自身[+15%]的胜率补正。 自身[战术]克制敌方，且在敌方发动[对军宝具]时，给予自身[+15%]的胜率补正。
C74: 常驻 | D74: B | E74: 4 | F74: 0 | G74: 0 | H74: [主力位] 自身[战术]未被克制时才能生效。 我方发动[对军宝具]时，给予自身[+20%]的胜率补正。 自身[战术]克制敌方，且在敌方发动[对军宝具]时，给予自身[+20%]的胜率补正。
C75: 常驻 | D75: A | E75: 5 | F75: 0 | G75: 0 | H75: [主力位] 自身[战术]未被克制时才能生效。 我方发动[对军宝具]时，给予自身[+25%]的胜率补正。 自身[战术]克制敌方，且在敌方发动[对军宝具]时，给予自身[+25%]的胜率补正。

Sheet 數值參考
A2: 从者等级 | B2: 分配点数 | C2: 特性 | G2: 筋力： | H2: 耐力： | I2: 敏捷： | J2: 魔力： | K2: 幸运： | L2: 宝具： | M2: 职阶特性
A3: 40 | B3: 100 | C3: 秩序·善 | F3: Saber | G3: 20 | H3: 20 | I3: 20 | J3: 10 | K3: 20 | L3: 0 | M3: 宝具栏数量最大为2，建卡时可以通过放弃【骑乘】来额外获得2的RP用于资源兑换。
A4: 50 | B4: 120 | C4: 中立·善 | F4: Lancer | G4: 10 | H4: 10 | I4: 30 | J4: 10 | K4: 10 | L4: 0 | M4: 自身的其中一项等级最高宝具的魔耗【-20】（最低为0），允许宣言指令【冲锋】。
A5: 60 | B5: 140 | C5: 混沌·善 | F5: Archer | G5: 10 | H5: 10 | I5: 10 | J5: 0 | K5: 20 | L5: 0 | M5: 自身的其中一项等级最高宝具获得【爆发】特性，且建卡时额外拥有2的RP用于在宝具资源上的兑换。
A6: 70 | B6: 160 | C6: 秩序·中立 | F6: Rider | G6: 0 | H6: 30 | I6: 0 | J6: 0 | K6: 20 | L6: 0 | M6: 初始宝具栏数量为2，且自身其中一项宝具获得【骑乘】特性。
A7: 空 | B7: 0 | C7: 中立·中庸 | F7: Caster | G7: 0 | H7: 0 | I7: 0 | J7: 30 | K7: 0 | L7: 0 | M7: 自身的【魔力】属性视为等值的【回路】属性，魔力池额外获得50上限，且自身持有的魔术技能获得【双发】特性。
A8: 空 | B8: 0 | C8: 混沌·中立 | F8: Assassin | G8: 0 | H8: 0 | I8: 20 | J8: 0 | K8: 20 | L8: 0 | M8: 自身发起的负面判定成功率[+20%]调整值。
A9: 空 | B9: 0 | C9: 秩序·恶 | F9: Berserker | G9: 0 | H9: 0 | I9: 0 | J9: 0 | K9: 0 | L9: 0 | M9: 【筋力】【耐久】【敏捷】的分配属性上限修改为80，【魔力】【幸运】的分配属性上限修改为40。
C10: 中立·恶 | F10: Saber(骑乘) | G10: 20 | H10: 30 | I10: 20 | J10: 10 | K10: 20 | L10: 0
C11: 混沌·恶 | F11: Ruler | G11: 0 | H11: 0 | I11: 0 | J11: 0 | K11: 0 | L11: 0
C12: 秩序·狂 | F12: Shielder | G12: 0 | H12: 0 | I12: 0 | J12: 0 | K12: 0 | L12: 0
C13: 中立·狂 | F13: Foreigner | G13: 0 | H13: 0 | I13: 0 | J13: 0 | K13: 0 | L13: 0
C14: 混沌·狂 | F14: Alterego | G14: 0 | H14: 0 | I14: 0 | J14: 0 | K14: 0 | L14: 0
C15: 空 | F15: Moon Cancer | G15: 0 | H15: 0 | I15: 0 | J15: 0 | K15: 0 | L15: 0
C16: 空 | F16: Beast | G16: 0 | H16: 0 | I16: 0 | J16: 0 | K16: 0 | L16: 0
C17: 空 | F17: Avenger | G17: 20 | H17: 0 | I17: 0 | J17: 0 | K17: 0 | L17: 0
C18: 空 | G18: 0 | H18: 0 | I18: 0 | J18: 0 | K18: 0 | L18: 0
C19: 空 | G19: 0 | H19: 0 | I19: 0 | J19: 0 | K19: 0 | L19: 0
C20: 空 | G20: 0 | H20: 0 | I20: 0 | J20: 0 | K20: 0 | L20: 0
C21: 空
C22: 空 | F22: 技能等级转化资源 | H22: 宝具等级转化资源 | J22: 职阶技能等级转化资源
C23: 空 | F23: EX | G23: 7 | H23: EX | I23: 9 | J23: A+(本职) | K23: 6
C24: 空 | F24: A++++ | G24: 5 | J24: A(本职) | K24: 4
C25: 空 | F25: A+ | G25: 7 | H25: A+ | I25: 7 | J25: A+ | K25: 7
C26: 空 | F26: A | G26: 5 | H26: A | I26: 5 | J26: A | K26: 5
C27: 空 | F27: - [视为A级] | G27: 5 | H27: - [视为A级] | I27: 5 | J27: B(本职) | K27: 3
C28: 空 | F28: B+ | G28: 6 | H28: B+ | I28: 6 | J28: B+ | K28: 6
C29: 空 | F29: B | G29: 4 | H29: B | I29: 4 | J29: B | K29: 4
C30: 空 | F30: - [视为B级] | G30: 4 | H30: - [视为B级] | I30: 4 | J30: C(本职) | K30: 2
C31: 空 | F31: C+ | G31: 5 | H31: C+ | I31: 5 | J31: C+ | K31: 5
C32: 空 | F32: C | G32: 3 | H32: C | I32: 3 | J32: C | K32: 3
C33: 空 | F33: - [视为C级] | G33: 3 | H33: - [视为C级] | I33: 3 | J33: D(本职) | K33: 1
C34: 空 | F34: D+ | G34: 4 | H34: D+ | I34: 4 | J34: D+ | K34: 4
C35: 空 | F35: D | G35: 2 | H35: D | I35: 2 | J35: D | K35: 2
J36: E(本职) | K36: 0
F37: E+ | G37: 3 | H37: E+ | I37: 3 | J37: E+ | K37: 3
F38: E | G38: 1 | H38: E | I38: 1 | J38: E | K38: 1
