Workbook
Name 表: 数值参考!#REF!
Name 科技: 数值参考!#REF!
Name 魔术: 数值参考!#REF!
Name 特殊: 数值参考!#REF!
Name 天赋类型: 数值参考!#REF!
Name 武术: 数值参考!#REF!
Name 阵营: '[1]數值參考'!$C$3:$C$35

Sheet 說明
A1: 對應規則書︰2.05
A7: 更新記錄
A8: 5 | B8: 自動化一部份的屬性分配
B9: 加入看上去很酷的屬性圖
B10: 加入簡單背景介紹在第一頁
A11: 5.1 | B11: 加入特性(可選規則)用的格子
A12: 5.2 | B12: 將特性這不會暴露，暴露後易被針對的效果移至角色卡下方，以便GM處理情報
B13: 為特性提供了實驗性質的效果槽，是否啟用自行向GM查詢
A14: 5.3 | B14: 本版本因應2.0規則將魔屬性分配更改了，舊版千萬不要使用此規則
B15: 並且于本版卡的起源覺醒者已正式移出，和加入了結界使、人偶使
A16: 5.31 | B16: 六維圖修了修
B17: 技能效果多加了一行，讓說明有點複雜的技能不用整天拉長行數。但是說明超長的依然要拉長行數
A18: 5.4 | B18: 禦主屬性回檔，魔力分配重新改為/2
B19: 處理了不太好看的格子
A20: 5.5 | B20: 加了倫理規則下，關係用的格子
B21: 特性由原來的範例，改成一些針對性的問題，寫特性時請將這些問題納入考慮
B22: 雖然很丟人，但之前一直將貼圖鎖了....現在不解除保護也能貼圖了
A23: 5.51 | B23: 異能者的特性也改了
B24: 代行者的九鍵數值調成15
A25: 6 | B25: 倫理關係的格子細分了關係背景、對指定關係人的態度
B26: 角色的屬性改成橫的，方便填表時右鍵
B27: 角色頭像可以放更大的了
B28: 禦主名字、陣營的位置改放到「角色經歷」，第一頁改為放代稱
B29: 為了排版美觀，職業特性自己去查規則書。
B30: 另外調整了排版，如無意外角色卡可以用A4size印出來了。不過我還沒嘗試。
A31: 6.01 | B31: 有些排版出包了，調整完成。
B32: 御主可选职业新增了巫术使
A34: GM開團前「可」準備的事
A39: 在數值參考頁面按自己特有的村規進行基礎屬性、點數的調整。或加入新職階
A62: 本角色卡是為聖杯戰爭跑團準備的角色卡。
A63: 該聖杯戰爭跑團規則大部分採用了日本現在較流行的男爵聖杯規則作為基底，進行魔改的TRPG規則，在遊戲上簡約了戰鬥部分，以實際扮演為主體的遊戲方式。
A65: 若有疑問可加群424815329查詢
A66: 備用二群 | B66: 310690935

Sheet 角色卡
B2: 阵营 | E2: 外貌描述 | H2: 肖像 | K2: 资源上限 | L2: 特攻列表 | Q2: 职业特性
B3: =角色經歷!E15 -> 秩序-善 | E3: （简单的外貌描述） | H3: （立绘） | K3: =12+VLOOKUP(C18,'（调卡用表）'!P3:Q7,2,0) -> 24 | L3: 职业 | N3: =F9 -> 体术师 | Q3: =VLOOKUP(F9,'（调卡用表）'!S3:T15,2,0) -> 允许执行[机动][介入]。
L4: 子职 | N4: =F10 -> 结界师
B5: 令咒 | K5: 剩余资源 | L5: 阵营 | N5: =角色經歷!E15 -> 秩序-善
B6: （图片，或者文本描述） | K6: =K3-IF(J19>0,K9,K9-J19/20) -> -2 | L6: 特性 | N6: =F11 -> 人型 | O6: =G11 -> 0
N7: =F12 -> 0 | O7: =G12 -> 0
K8: 花费资源 | L8: 性别 | N8: =角色經歷!C12 -> 女 | Q8: =VLOOKUP(F10,'（调卡用表）'!V3:W15,2,0) -> 自阵营通过[广泛侦查]获悉某一灵脉存在[魔术结界]时，自身将知悉那个[魔术结界]的效果。
E9: 主职业 | F9: 体术师 | K9: =J21+H30+H39+AE30+AE37+J49+J58+J67+T21+T30+T39+T49+T58+T67+K12 -> 17 | L9: 体型 | N9: =F13 -> 通常
E10: 子职业 | F10: 结界师 | L10: 注释
E11: 特性 | F11: 人型 | K11: 扩容 | L11: 特攻列表不会也不能为其他角色所获取。
K12: =H21+AC30+AC37+H49+H58+H67+R21+R30+R39+R49+R58+R67 -> 2
E13: 体型 | F13: 通常 | L13: 学科特性
E14: 学科 | L14: 名称 | O14: 选取条件
B15: 属性 | C15: 等级 | D15: 筋力 | E15: 耐久 | F15: 敏捷 | G15: 魔力 | H15: 幸运 | I15: 回路 | J15: 属性点数
B16: 合计 | C16: =C17+C18+C19 -> 40 | D16: =D17+D18+D19 -> 80 | E16: =E17+E18+E19 -> 80 | F16: =F17+F18+F19 -> 60 | G16: =G17+G18+G19 -> 20 | H16: =H17+H18+H19 -> 40 | I16: =I17+I18+I19 -> 70 | J16: 80 | L16: 效果 | M16: （持有[类型：魔术]技能且存在时钟塔进修经历的单位才可以选择[学科]） （此项为额外规则，通常不开）
B17: 职业 | D17: =VLOOKUP(F9,'（调卡用表）'!B3:H13,2,0) -> 20 | E17: =VLOOKUP(F9,'（调卡用表）'!B3:H13,3,0) -> 20 | F17: =VLOOKUP(F9,'（调卡用表）'!B3:H13,4,0) -> 20 | G17: =VLOOKUP(F9,'（调卡用表）'!B3:H13,5,0) -> 0 | H17: =VLOOKUP(F9,'（调卡用表）'!B3:H13,6,0) -> 10 | I17: =VLOOKUP(F9,'（调卡用表）'!B3:I13,7,0) -> 0 | J17: =D17+E17+F17+G17+H17+I17 -> 70
B18: 分配 | C18: 40 | D18: 60 | E18: 60 | F18: 40 | G18: 20 | H18: 30 | I18: 50 | J18: 剩余点数
B19: 补正 | I19: 20 | J19: =J16-SUM(D18:I18) -> -180
B20: 工房构件 | L20: 保有技能（额外栏位）
B21: 模板 | C21: （构件模板） | E21: 构件种类 | G21: 扩容 | I21: 资源 | L21: 模板 | O21: 等级 | Q21: 扩容 | S21: 资源 | T21: =_xlfn.IFNA(VLOOKUP(P21,'（调卡用表）'!$J$3:$K$33,2,0),0) -> 0
B22: 名称 | C22: （构件名称） | E22: 魔力消耗 | F22: 无 | G22: 规模 | I22: 稳态 | L22: 名称 | O22: 类型 | R22: 回转
O23: 发动时机 | R23: 魔力消耗 | T23: =IF(P23="常驻","每日","每次") -> 每次
B24: 效果 | C24: （通常只有持有[魔术师]职业特性的单位才可以建造[魔术工房]） | L24: 效果 | M24: （每个御主持有三个初始技能栏，每个额外技能栏需要消耗2RP购入，写作[扩容]）
B27: 背景 | L27: 背景
B30: 模板 | E30: 构件种类 | G30: 扩容 | I30: 资源 | L30: 模板 | O30: 等级 | Q30: 扩容 | S30: 资源 | T30: =_xlfn.IFNA(VLOOKUP(P30,'（调卡用表）'!$J$3:$K$33,2,0),0) -> 0
B31: 名称 | E31: 魔力消耗 | G31: 规模 | I31: 稳态 | L31: 名称 | O31: 类型 | R31: 回转
O32: 发动时机 | R32: 魔力消耗 | T32: =IF(P32="常驻","每日","每次") -> 每次
B33: 效果 | C33: （每个御主持有一个工房构件栏，每个额外工房栏需要消耗1RP购入，写作[扩容]） | L33: 效果
B36: 背景 | L36: 背景
B39: 模板 | E39: 构件种类 | G39: 扩容 | I39: 资源 | L39: 模板 | O39: 等级 | Q39: 扩容 | S39: 资源 | T39: =_xlfn.IFNA(VLOOKUP(P39,'（调卡用表）'!$J$3:$K$33,2,0),0) -> 0
B40: 名称 | E40: 魔力消耗 | G40: 规模 | I40: 稳态 | L40: 名称 | O40: 类型 | R40: 回转
O41: 发动时机 | R41: 魔力消耗 | T41: =IF(P41="常驻","每日","每次") -> 每次
B42: 效果 | L42: 效果
B45: 背景 | L45: 背景
B48: 保有技能 | L48: 礼装
B49: 模板 | C49: 魔剑传承 | E49: 等级 | F49: A | G49: 扩容 | H49: 2 | I49: 资源 | J49: =_xlfn.IFNA(VLOOKUP(F49,'（调卡用表）'!$J$3:$K$33,2,0),0) -> 5 | L49: 模板 | M49: 无明三段突 | O49: 等级 | P49: / | Q49: 扩容 | S49: 资源
B50: 名称 | C50: (自定义技能名称) | E50: 类型 | F50: 荣冠 | H50: 回转 | I50: 0 | L50: 名称 | O50: 类型 | P50: 对人魔剑 | R50: 回转 | S50: 3
E51: 发动时机 | F51: 常柱 | H51: 魔力消耗 | I51: 0 | J51: =IF(F51="常驻","每日","每次") -> 每次 | O51: 发动时机 | P51: 随时 | R51: 魔力消耗 | S51: 10 | T51: =IF(P51="常驻","每日","每次") -> 每次
B52: 效果 | C52: 建卡时，额外支付[2]RP点记为扩容，从从者资源库中获取一件[面向：魔剑]的宝具。 以此方式获取的[面向：魔剑]宝具，其不会产生首次解放带来的效果，在判定上视为 A 级的[ 类型：技艺]技能，并移除[主力位]词条。 以此方式获取的[面向：魔剑]宝具，在受到使效果等级下降的效果时，每下降[1]级将令其发 起的判定受到[-20%]的成功率惩罚。 特别的，以此方式获取的[面向：魔剑]宝具，在其他单位作为额外技能获取时，其效果等级 始终下降[2]级。 | L52: 效果 | M52: 令敌方主力位受到三次成功率=[80%]的负面判定（视为[即死]判定），若目标[敏捷]属性不小于 [40]，则这个判定的成功率减半。 每个成功的判定，都将令目标[筋力][耐久][敏捷]三项属性中一项属性受到[-20]的属性惩罚，若 目标对应属性存在补正，则这个属性惩罚减半； 若本次解放中，此宝具判定成功数达到[3]，则额外对目标造成一次[即死]效果，若不消耗一枚令 咒抵消，则立即退场。每场战斗中，此效果仅会在此宝具首次生效时生效。 解放此宝具后，给予自身[迟滞 1]。
B55: 背景 | C55: ， | L55: 背景
...

Sheet 角色經歷
B2: 最能代表角色的一句话: | L2: 你的角色是为了圣杯而参战的？你投身到圣杯战争中所追求的是什么？
B3: “如果你不为了你自己而活的话， 所谓的幸福究竟是什么——根本不会明白！” | L3: （投身杀戮，冒着生命危险参加圣杯战争的原因、愿望） （除非GM允许，否则愿望必须需要通过圣杯许愿实现）
B6: 喜好 | D6: 宝石磨制、捉弄士郎。 | H6: 使魔外观 | I6: 猫、狗、机器、工具人
B7: 厌恶 | D7: 全部的电子仪器、突发事件。 | H7: 技术 | I7: 魔术/科技/人脉? | L7: 角色之核心人設
B8: 魔术属性 | D8: 五大元素使 | H8: 图片（此处为使魔外观） | L8: （专注描写角色的性格、价值观的形成等等） （不便公开的里设，与正常侦查不应该取得的情报都放置于此） （角色简介与核心人设的内容，宜于审卡前与GM进行商确，确定什么内容置于那一面）
B9: 魔术特性 | D9: 转换
B10: 姓名 | C10: 远坂凛 | E10: 身份 | F10: 魔术师/冬木市地脉管理者
B11: 职业 | C11: 穗群原学园学生 | E11: 所属 | F11: 远坂家
B12: 性别 | C12: 女 | E12: 玩家
B13: 年龄 | C13: 17
B14: 身高 | C14: 159 | E14: 阵营
B15: 体重 | C15: 47 | E15: 秩序-善
B16: 已知的情报
B17: （写出角色的简单、可调查取得的情报。像是出身、生平与所属魔术集团中的地位、战斗风格、魔术上的研究定位） （为保证公平性，请与GM商确清楚放置于此处的内容） （本部份将因为详细侦查而暴露，过于核心的内容请不要填写于此处。但也不容许于此处进行严重欺骗、误导）
B25: 社会关系/[支援伦理规则]: | L25: 在這場聖杯戰爭中，你是否會遵守倫理的規則，不波及無辜？
B26: 关系： | C26: 父女 | E26: 對像： | F26: 远坂时臣 | H26: 态度： | I26: 亲切
B27: 效果︰ | C27: 无
B29: 交集点/ 关系现状: | C29: 时臣死了。 | L29: 你的愿望是否可以放弃，如果可以，是在什么情况下？
L30: （除非GM允许，否则愿望无法被放弃）
B32: 关系： | E32: 對像： | H32: 态度： | I32: 友好
B33: 效果︰ | C33: （支援伦理规则用的格子，若果GM没开这规则就不用理会） （作为社会关系栏位时，只需填写关系、态度与交集点/现状） | L33: 你希望拥有怎样的从者？在什么情况下你可能会违背从者的意愿进行行动？
B35: 交集点/ 关系现状: | C35: （本角色與指定關系人如何相遇、如何相處）
L37: 你愿意相信什么样的人？在什么情况下你可能会将其他参赛者认作盟友？
B38: 关系： | E38: 對像： | H38: 态度： | I38: 友好
B39: 效果︰ | C39: （支援伦理规则用的格子，若果GM没开这规则就不用理会） （作为社会关系栏位时，只需填写关系、态度与交集点/现状）
B41: 交集点/ 关系现状: | C41: （本角色與指定關系人如何相遇、如何相處） | L41: 角色梦境:
L42: （与从者交换梦境用的格子，若果GM没要求就不用理会） （梦境的内容，主要是人生态度、遭遇、生平等） （通常御主开启梦境时，目的是用于提升和从者的相性）
B44: 关系： | E44: 對像： | H44: 态度： | I44: 友好
B45: 效果︰ | C45: （支援伦理规则用的格子，若果GM没开这规则就不用理会） （作为社会关系栏位时，只需填写关系、态度与交集点/现状）
B47: 交集点/ 关系现状: | C47: （本角色與指定關系人如何相遇、如何相處）
B50: 特性： | C50: （例：根源的渴望）（此内容是否启用请咨询GM）
B51: 效果： | C51: （是否提供实质加成，请向GM查询自行决定，基本上无效果）
B52: 描述： | C52: （对自己的愿望有什么程度的执着，会于什么原因下放弃?） （面对其他组别会优先做出什么行动?）（在失去从者的情况下还会不会坚持不退出?）

Sheet （调卡用表）
B3: 职业名称 | C3: 筋力 | D3: 耐久 | E3: 敏捷 | F3: 魔力 | G3: 幸运 | H3: 回路 | J3: 技能等级 | K3: 对应RP | M3: 宝具等级 | N3: 对应RP | P3: 御主等级 | Q3: 对应RP | S3: 职业名称 | T3: 职业特性 | V3: 职业名称 | W3: 职业特性
B4: 魔术师 | C4: 0 | D4: 0 | E4: 0 | F4: 20 | G4: 10 | H4: 20 | J4: E | K4: 1 | M4: E | N4: 1 | P4: 10 | Q4: 0 | S4: 魔术师 | T4: 允许执行[礼装制作,可制作基础礼装;允许执行[工房建设]。 | V4: 结界师 | W4: 自阵营通过[广泛侦查]获悉某一灵脉存在[魔术结界]时，自身将知悉那个[魔术结界]的效果。
B5: 体术师 | C5: 20 | D5: 20 | E5: 20 | F5: 0 | G5: 10 | H5: 0 | J5: D | K5: 2 | M5: D | N5: 2 | P5: 20 | Q5: 4 | S5: 体术师 | T5: 允许执行[机动][介入]。 | V5: 咒术师 | W5: 允许自身进行[遮蔽魂食]；自阵营单位杀死其他阵营的御主单位、或进行一次成功的[魂食]时，选择本职业的任一技能，使其获得[生祭]。
B6: 异能者 | C6: 0 | D6: 0 | E6: 0 | F6: 10 | G6: 30 | H6: 10 | J6: C | K6: 3 | M6: C | N6: 3 | P6: 30 | Q6: 8 | S6: 异能者 | T6: 获得[+10]的等级补正,且额外获得4RP;保有[魔性]特性。 | V6: 异能者 | W6: 获得[+10]的等级补正,且额外获得4RP;保有[魔性]特性。
B7: 代行者 | C7: 0 | D7: 15 | E7: 0 | F7: 15 | G7: 10 | H7: 10 | J7: B | K7: 4 | M7: B | N7: 4 | P7: 40 | Q7: 12 | S7: 代行者 | T7: 允许执行[礼装制作],可制作概念武装;获得[抗性上升：+10%]。 | V7: 魔眼使 | W7: 建卡时，获得[1]个额外技能栏位，以此方式获得的技能栏位仅能用于购入[面向：魔眼]的技能。
B8: 退魔师 | C8: 10 | D8: 10 | E8: 10 | F8: 20 | G8: 0 | H8: 0 | J8: A | K8: 5 | M8: A | N8: 5 | S8: 退魔师 | T8: 将基础属性改为 10-10-10-20-0-0，失去[异能者]特性带来的额外RP点，允许将子职业[混血]的技能作为本职业技能获取，允许自身进行[机动][介入]。 | V8: 刽子手 | W8: 若自身在首次参与的战斗中战斗胜利，给予自身标记[行刑者]；若此战斗失败，给予自身标记[解脱者]。
B9: 执法者 | C9: 15 | D9: 20 | E9: 15 | F9: 0 | G9: 0 | H9: 0 | J9: EX | K9: 7 | M9: EX | N9: 9 | S9: 执法者 | T9: 建卡时，获取一件[科技造物]。允许进行[礼装制作]，但以此方式进行的礼装制作判定基础成功率为[50%]，且仅能制作[弹药包]。 | V9: 剑术师 | W9: 战斗开始时，从[剑势：辘轳势/重梅势/长生势]中选择一项获取；战斗结束时，清除自身持有的所有[剑势]。
J10: -(E) | K10: 1 | M10: -(E) | N10: 1 | V10: 死徒 | W10: 允许执行[遮蔽魂食]。
J11: -(D) | K11: 2 | M11: -(D) | N11: 2 | V11: 混血 | W11: 允许将子职业[死徒]除[继理血戒][死亡初拥]外的技能作为本职业技能获取，允许自身进行[遮蔽魂食]。
J12: -(C) | K12: 3 | M12: -(C) | N12: 3 | V12: 驱魔师 | W12: 允许自身消耗行动阶段，赋予当前灵脉[魔术结界：驱魔结界]。 赋予[魔术结界：驱魔结界]以下效果： 当前灵脉发生的战斗开始时，给予灵脉上所有持有[魔性]的单位[混乱 1]。
J13: -(B) | K13: 4 | M13: -(B) | N13: 4 | V13: 权贵 | W13: 特性：建卡时，获得[资金 10]，额外卡面不会获取此效果；每轮次结束时，获得[资金 1]。
J14: -(A) | K14: 5 | M14: -(A) | N14: 5
J15: -(EX) | K15: 7 | M15: -(EX) | N15: 9
J16: E+ | K16: 3 | M16: E+ | N16: 3
J17: D+ | K17: 4 | M17: D+ | N17: 4
J18: C+ | K18: 5 | M18: C+ | N18: 5
J19: B+ | K19: 6 | M19: B+ | N19: 6
J20: A+ | K20: 7 | M20: A+ | N20: 7
J21: E++ | K21: 5 | M21: E++ | N21: 5
J22: D++ | K22: 6 | M22: D++ | N22: 6
J23: C++ | K23: 7 | M23: C++ | N23: 7
J24: B++ | K24: 8 | M24: B++ | N24: 8
J25: A++ | K25: 9 | M25: A++ | N25: 9
... J30: A+++ | K30: 11 | M30: A+++ | N30: 11

Sheet 建卡用参考资源
B2: 职业 | D2: 能力
B3: 魔术师 | D3: 就算自身与从者不在同一个场景下，也能对其使用令咒。
D4: 魔力额外获得[+10]的补正，该补正可以突破属性上限。并且基础技能的[类型]必须为[魔术]。
D5: 开局可获得一个任意的基础礼装。
C6: 人偶师 | D6: 就算自身与从者不在同一个场景下，也能对其使用令咒。
D7: 自身的基础技能将会提升一个等级，最高为 A，但必须为[人偶制成]。
B8: 异能者 | D8: 可任意挑选[类别:魔术]以外的基础技能。并将那个技能的等级提高一个等级，最高为 A 级。
D9: 并且额外获得[20]的可任意分配点数。
D10: （若是在等级骰点制的规则下，额外可任意分配点数将可以转化为自身等级骰+1。）
D11: 注 1:这个可任意分配点数，无法使属性突破上限。
D12: 注 2:由于御主默认没有宝具，所以也无法分配到宝具处。
B13: 魔眼使 | D13: 将自身的[基础技能]更替为具有[对他人产生负面效果]的[特殊技能]，该特殊技能的技能等级视为[B]。
D14: 名字：待定 类别：一般 使用时机：初始工序
D15: 效果：对对方战斗位的上一名御主进行一次成功率=[自身任一数值-目标任一数值]的[即死]效果，
D16: 在判定成功的情况下，若不以一枚令咒抵消，则将会视为退场。
D17: 在判定失败的情况下，将会给予对方[同等于即死成功率]的[胜率惩罚]。
B18: 保菌传承者 | D18: 将自身的[基础技能]更替为与自身[魔]相同等级的[对人宝具]。在解放宝具的当下也将会获得同等的[宝]属性。
D19: 10=E 20=D 30=C 40=B 50=A。
D20: 该宝具一天只能释放一次，且将会消耗等同于[魔]属性的魔力。也可以将自身的魔永久[-20]，将宝具类型提升为[固有结界]。
B21: 代行者 | D21: 自身的阵营必须为[秩序]，且参加圣杯战争的目的，必须是以[将圣杯回收至教会]为主，并且为了保证[圣杯]的魔力，不会给他人对[圣杯]许愿的机会。
D22: 可任意挑选基础技能，并将会额外获得一个礼装——[九键]，并且可以对自身使用令咒来加强自身的战斗能力。
D23: 名称：[九键] 类型：常驻礼装 使用时机：常驻
D24: 效果：战斗中，无条件给予自身[+15]的胜率补正。该[胜率补正]不可与其他[九键]复数叠加。
B25: 巫术使 | D25: 该职业可任意挑选基础技能，且将会额外获得两项特殊的回合行动指令。
D26: 诅咒：
D27: 消耗一个行动阶段发动，选择一名被自身详细侦查成功且未被诅咒过的御主全抗性受到[-20]的削减，这个状态将持续三天。
D28: 该行动的优先级高于袭击低于魂食。
D29: 献祭：
D30: 这个职业的御主每当杀死了其他御主的情况下，将可以令与自身契约的一名从者除[宝]以外的属性获得[+5]的[常驻补正]；
D31: 或消耗一个行动阶段发动，令自身的[耐]属性受到[-20]的常驻惩罚]，令与自身契约的一名从者除[宝]以外的属性获得[+5]的[常驻补正]。
B33: 技能资源库
B34: 基础技能 | K34: 特化技能
B35: 一般 | K35: 一般
B36: 名称： | C36: 枪械精通 A B C | E36: 类别： | F36: 一般 | H36: 使用时机： | I36: 初始工序 | K36: 名称： | L36: 八极拳 B | N36: 类别： | O36: 一般 | Q36: 使用时机： | R36: 初始工序
B37: 效果︰ | C37: 在[袭击]或[介入行动]的时候，无条件获得[+20/15/10]的胜率补正。 | K37: 效果︰ | L37: 选择对方战斗位上的一名御主发动，令其进行一次成功率=[自身上三维总和-目标上三维总和]的判定 在判定成功后，将会使目标强制退出战斗位，这个判定受[非精神系弱体耐性]的影响。
B39: 备注： | C39: 御主等级[30/20/10]可分别获得[A/B/C]等级。
B40: 名称： | C40: 情报优势 A B C | E40: 类别： | F40: 一般 | H40: 使用时机： | I40: 游戏第一天开始时
B41: 效果︰ | C41: 随机获得除自己以外最多[3/2/1]名[御主]的[详细侦查资料]以及[所在根据地]。 | K41: 名称： | L41: 投毒 B | N41: 类别： | O41: 一般 | Q41: 使用时机： | R41: 行动阶段
K42: 效果︰ | L42: 该技能在本次圣杯战争中只能使用一次，发动后选择以下其一发动。 ①消耗一个行动阶段，令一个灵脉上的全部[御主]受到一次成功率=[50]的[中毒]判定。 ②回合结束时发动，令自身所在灵脉除自身以外的全部[御主]直接[中毒]。
B43: 备注： | C43: 御主等级[35/25/15]可分别获得[A/B/C]等级。
...

Sheet 数值参考
A1: 御主等级 | B1: 可分配资源 | D1: 特性 | G1: 职业 | H1: 筋力： | I1: 耐力： | J1: 敏捷： | K1: 魔力： | L1: 幸运： | M1: 回路：
A2: 10 | B2: 12 | D2: 秩序-善 | G2: 魔术师 | H2: 0 | I2: 0 | J2: 0 | K2: 10 | L2: 0 | M2: 10
A3: 20 | B3: 16 | D3: 中立-善 | G3: 体术师 | H3: 15 | I3: 15 | J3: 15 | K3: 0 | L3: 0 | M3: 0
A4: 30 | B4: 20 | D4: 混沌-善 | G4: 异能者 | H4: 0 | I4: 0 | J4: 0 | K4: 0 | L4: 30 | M4: 0
A5: 40 | B5: 24 | D5: 秩序-中立 | G5: 代行者 | H5: 0 | I5: 15 | J5: 0 | K5: 15 | L5: 0 | M5: 0
D6: 中立-中庸 | H6: 0 | I6: 0 | J6: 0 | K6: 0 | L6: 0 | M6: 0
D7: 混沌-中立 | H7: 0 | I7: 0 | J7: 0 | K7: 0 | L7: 0 | M7: 0
D8: 秩序-邪 | H8: 0 | I8: 0 | J8: 0 | K8: 0 | L8: 0 | M8: 0
D9: 中立-邪 | H9: 0 | I9: 0 | J9: 0 | K9: 0 | L9: 0 | M9: 0
B10: / | D10: 混沌-邪 | H10: 0 | I10: 0 | J10: 0 | K10: 0 | L10: 0 | M10: 0
B11: / | D11: 秩序-狂 | H11: 0 | I11: 0 | J11: 0 | K11: 0 | L11: 0 | M11: 0
B12: / | D12: 中立-狂 | H12: 0 | I12: 0 | J12: 0 | K12: 0 | L12: 0 | M12: 0
B13: / | D13: 混沌-狂 | H13: 0 | I13: 0 | J13: 0 | K13: 0 | L13: 0 | M13: 0
B14: / | D14: 空 | H14: 0 | I14: 0 | J14: 0 | K14: 0 | L14: 0 | M14: 0
D15: 空 | H15: 0 | I15: 0 | J15: 0 | K15: 0 | L15: 0 | M15: 0
D16: 空 | H16: 0 | I16: 0 | J16: 0 | K16: 0 | L16: 0 | M16: 0
A17: 骰值1D8 | B17: 关系 | C17: 等级 | D17: 空 | H17: 0 | I17: 0 | J17: 0 | K17: 0 | L17: 0 | M17: 0
A18: / | B18: (态度) | C18: / | D18: 空 | H18: 0 | I18: 0 | J18: 0 | K18: 0 | L18: 0 | M18: 0
A19: 1 | B19: 友好 | C19: C | D19: 空 | H19: 0 | I19: 0 | J19: 0 | K19: 0 | L19: 0 | M19: 0
A20: 2 | B20: 亲切 | C20: B | D20: 空
A21: 3 | B21: 依赖 | C21: A | D21: 空
A22: 4 | B22: 独占欲 | C22: A | D22: 空 | G22: 等级转化资源
A23: 5 | B23: 轻蔑 | C23: C | D23: 空 | G23: EX | H23: 10
A24: 6 | B24: 敌视 | C24: B | D24: 空 | G24: A++ | H24: 9
A25: 7 | B25: 仇恨 | C25: A | D25: 空 | G25: A+ | H25: 7
A26: 8 | B26: 支配欲 | C26: A | D26: 空 | G26: A | H26: 5
D27: 空 | G27: B++ | H27: 8
D28: 空 | G28: B+ | H28: 6
D29: 空 | G29: B | H29: 4
D30: 空 | G30: C++ | H30: 7
D31: 空 | G31: C+ | H31: 5
D32: 空 | G32: C | H32: 3
D33: 空 | G33: D++ | H33: 6
D34: 空 | G34: D+ | H34: 4
G35: D | H35: 2
G36: E++ | H36: 5
G37: E+ | H37: 3
G38: E | H38: 1
